Workbook

Sheet Summaries
A1: Ploughing Summaries | I1: -
A3: ICBC | B3: Total Hours Complete | C3: Families Impacted | D3: Hectares | E3: Status | F3: Payment | G3: Contractor
A4: =Bulunga!B3 -> Bulunga ICBC | B4: =Bulunga!G43 -> 50 | C4: =Bulunga!F44 -> 33 | D4: =1.5*B4 -> 75 | E4: Complete | F4: Paid | G4: Norman's Tractor Services
A5: Hawane | B5: =Hawane!G46 -> 50 | C5: =Hawane!F47 -> 36 | D5: =1.5*B5 -> 75 | E5: Complete | F5: Paid | G5: Hillside Enterprise
A6: =Jubukweni!B3 -> Jubukweni ICBC | B6: =Jubukweni!G42 -> 49 | C6: =Jubukweni!F43 -> 31 | D6: =1.5*B6 -> 73.5 | E6: Complete | F6: Paid | G6: Tiyane Investments
A7: =Kaliba!B3 -> KaLiba ICBC | B7: =Kaliba!G48 -> 50 | C7: =Kaliba!F49 -> 38 | D7: =1.5*B7 -> 75 | E7: Complete | F7: Paid | G7: Dumelitje Farming and Cattle Store
A8: =Gebeni!B3 -> Gebeni ICBC | B8: =Gebeni!G47 -> 50 | C8: =Gebeni!F48 -> 37 | D8: =1.5*B8 -> 75 | E8: Complete | F8: Paid | G8: Thamsanqa Ntshalintshali
A9: =Gundvwini!B3 -> Gundvwini ICBC | B9: =Gundvwini!G39 -> 36 | C9: =Gundvwini!F40 -> 28 | D9: =1.5*B9 -> 54 | E9: Complete | F9: Paid | G9: Vuyisile Mndzebele
A10: Lavumisa | B10: =Lavumisa!H31 -> 3 | C10: =Lavumisa!G32 -> 3 | D10: =1.5*B10 -> 4.5 | E10: Complete | F10: Paid | G10: Sunboy Sithembiso Msibi
A11: Lundzi | B11: =Lundzi!H30 -> 57 | C11: =Lundzi!G31 -> 20 | D11: =1.5*B11 -> 85.5 | E11: Complete | F11: Paid | G11: Ganbarou Investments
A12: =Lushikishini!B3 -> Lushikishini ICBC | B12: =Lushikishini!H31 -> 16 | C12: =Lushikishini!G32 -> 7 | D12: =1.5*B12 -> 24 | E12: Complete | F12: Paid | G12: RDA Tractor
A13: =Lonhlalane!B3 -> Lonhlalane ICBC | B13: =Lonhlalane!G44 -> 50 | C13: =Lonhlalane!F45 -> 34 | D13: =1.5*B13 -> 75 | E13: Complete | F13: Paid | G13: July Mhlanga
A14: Mangcongco ICBC | B14: =Mangcongco!G48 -> 50 | C14: =Mangcongco!F49 -> 35 | D14: =1.5*B14 -> 75 | E14: Complete | F14: Paid | G14: Sum Investments PTY LTD and Umnotfo Farmers Association
A15: Mbowane ICBC | B15: =Mbowane!G43 -> 50 | C15: =Mbowane!F44 -> 33 | D15: =1.5*B15 -> 75 | E15: Complete | F15: Paid | G15: Samkelisiwe Hlophe
A16: =Mcuba!B3 -> Mcuba ICBC | B16: =Mcuba!G53 -> 50 | C16: =Mcuba!F54 -> 43 | D16: =1.5*B16 -> 75 | E16: Complete | F16: Paid | G16: July Mhlanga
A17: =Mlindazwe!B3 -> Mlindazwe ICBC | B17: =Mlindazwe!G41 -> 50 | C17: =Mlindazwe!F42 -> 31 | D17: =1.5*B17 -> 75 | E17: Complete | F17: Paid | G17: Sakhile Mabuza
A18: =Mhlangatane!B3 -> Mhlangatane ICBC | B18: =Mhlangatane!G56 -> 50 | C18: =Mhlangatane!F57 -> 46 | D18: =1.5*B18 -> 75 | E18: Complete | F18: Paid | G18: Mfanukhona Magagula
A19: =Mpuluzi!B3 -> Mpuluzi ICBC | B19: =Mpuluzi!G34 -> 50 | C19: =Mpuluzi!F35 -> 24 | D19: =1.5*B19 -> 75 | E19: Complete | F19: Paid | G19: Sum Investments PTY LTD
A20: =Msahweni!B3 -> Msahweni ICBC | B20: =Msahweni!G51 -> 50 | C20: =Msahweni!F52 -> 41 | D20: =1.5*B20 -> 75 | E20: Complete | F20: Paid | G20: Thulani Fakudze
A21: ='Nyathela '!B3 -> Nyathela ICBC | B21: ='Nyathela '!G42 -> 50 | C21: ='Nyathela '!F43 -> 32 | D21: =1.5*B21 -> 75 | E21: Complete | F21: Paid | G21: Xolani Abel Ndzinisa
A22: =Ngwempisi!B3 -> Ngwempisi ICBC | B22: =Ngwempisi!G35 -> 52 | C22: =Ngwempisi!F36 -> 25 | D22: =1.5*B22 -> 78 | E22: Complete | F22: Paid | G22: Machuzu
A23: =Nsubane!B3 -> Nsubane ICBC | B23: =Nsubane!G36 -> 50 | C23: =Nsubane!F37 -> 26 | D23: =1.5*B23 -> 75 | E23: Complete | F23: Paid | G23: Hezekiel S. Dlamini
A24: Sibovini | B24: =Sibovini!G40 -> 50 | C24: =Sibovini!F41 -> 30 | D24: =1.5*B24 -> 75 | E24: Complete | F24: Paid | G24: Sandile Sibandze
A25: =Sigangeni!B3 -> Sigangeni ICBC | B25: =Sigangeni!G40 -> 50 | C25: =Sigangeni!F41 -> 29 | D25: =1.5*B25 -> 75 | E25: Complete | F25: Paid | G25: Asibambaneni Multi Purpose
A26: =Sigengeni!B3 -> Sigengeni ICBC | B26: =Sigengeni!G42 -> 50 | C26: =Sigengeni!F43 -> 32 | D26: =1.5*B26 -> 75 | E26: Complete | F26: Paid | G26: Nonkhululeko Ngwenya
A27: =Sigombeni!B3 -> Sigombeni ICBC | B27: =Sigombeni!G51 -> 50 | C27: =Sigombeni!F52 -> 41 | D27: =1.5*B27 -> 75 | E27: Complete | F27: Paid | G27: Doctor Banda
A28: =Sigcaweni!B3 -> Esigcaweni ICBC | B28: =Sigcaweni!G49 -> 50 | C28: =Sigcaweni!F50 -> 36 | D28: =1.5*B28 -> 75 | E28: Complete | F28: Paid | G28: Mfanasibili Shongwe
A29: =Zondwako!B3 -> Zondwako ICBC | B29: =Zondwako!G47 -> 50 | C29: =Zondwako!F48 -> 36 | D29: =1.5*B29 -> 75 | E29: Complete | F29: Paid | G29: Sum Investments PTY LTD
A30: Total | B30: =SUM(B4:B29) -> 1213 | C30: =SUM(C4:C29) -> 807 | D30: =1.5*B30 -> 1819.5 | E30: =COUNTIF(E4:Z29,"Complete") -> 26 | F30: =COUNTIF(F4:F29,"Paid") -> 26

Sheet Bulunga
A1: ICBC Ploughing Project
C2: COMPLETE
A3: Name of ICBC: | B3: Bulunga ICBC | E3: Name of Pastor | F3: Ndumiso Gwebu
A4: Contractor's Full Name | B4: Noman Gamedze | E4: ID Number | F4: 8708016100133
A5: Bank | B5: Standard Bank | E5: Account Holder's Name | F5: Noman Gamedze
A6: Branch Code | E6: Account Number | F6: 9110002992984
A9: Community Member’s Name & Surname | B9: Contact details | C9: Date | D9: Start Time (Date & Time) | E9: Completion time (Date & Time) | F9: Number of Hours | G9: Actual Number of Hours | H9: Amount | I9: Location
A10: Pastor Gwebu | B10: 76979572 | C10: 21/10/23 | F10: 1 | G10: 1 | H10: =200*G10 -> 200
A11: Make Ndlovu | B11: 76978028 | C11: 21/10/23 | F11: 2 | G11: 2 | H11: =200*G11 -> 400
A12: Babe Dlamini | B12: 76380224 | C12: 21/10/23 | F12: 2 | G12: 2 | H12: =200*G12 -> 400
A13: Make Mamba | B13: 76142101 | C13: 21/10/23 | F13: 1 | G13: 1 | H13: =200*G13 -> 200
A14: Make Gwebu | B14: 76247135 | C14: 21/10/23 | F14: 2 | G14: 2 | H14: =200*G14 -> 400
A15: Dorah | B15: 76536796 | C15: 27/10/23 | F15: 1 | G15: 1 | H15: =200*G15 -> 200
A16: Make Sikhondze | B16: 76544166 | C16: 27/10/23 | F16: 1 | G16: 1 | H16: =200*G16 -> 200
A17: Make Motsa | B17: 78145259 | C17: 27/10/23 | F17: 2 | G17: 2 | H17: =200*G17 -> 400
A18: Babe Gwebu | B18: 76932942 | C18: 27/10/23 | F18: 1 | G18: 1 | H18: =200*G18 -> 200
A19: Bhekane | B19: 76971553 | C19: 27/10/23 | F19: 1 | G19: 1 | H19: =200*G19 -> 200
A20: Sikhandzabantfu Primary School | B20: 76076266 | C20: 27/10/23 | F20: 1.5 | G20: 1.5 | H20: =200*G20 -> 300
A21: Shongwe | B21: 76747024 | C21: 28/10/23 | D21: 0.70833333 | E21: 0.75 | F21: 1 | G21: 1 | H21: =200*G21 -> 200
A22: Lukhele | B22: 76338758 | C22: 28/10/23 | D22: 0.29166667 | E22: 0.5 | F22: 5 | G22: 5 | H22: =200*G22 -> 1000
A23: Shongwe | B23: No Cellphone | C23: 45027 | D23: 0.29166667 | E23: 0.33333333 | F23: 1 | G23: 1 | H23: =200*G23 -> 200
A24: Mhlabelo | B24: No Cellphone | C24: 45027 | D24: 0.39583333 | E24: 0.020833333 | F24: 3 | G24: 3 | H24: =200*G24 -> 600
A25: mhlanga | B25: No Cellphone | C25: 45027 | D25: 0.54166667 | E25: 0.58333333 | F25: 1 | G25: 1 | H25: =200*G25 -> 200
A26: Make Tiba | B26: No Cellphone | C26: 45027 | D26: 0.70833333 | E26: 0.75 | F26: 1 | G26: 1 | H26: =200*G26 -> 200
A27: Make mngometulu | B27: No Cellphone | C27: 45088 | D27: 0.33333333 | E27: 0.375 | F27: 1 | G27: 1 | H27: =200*G27 -> 200
A28: Babe Shongwe | B28: 764323611 | C28: 45088 | D28: 0.425 | E28: 0.46666667 | F28: 1 | G28: 1 | H28: =200*G28 -> 200
A29: Babe Mamba | B29: 76142101 | C29: 45088 | D29: 0.47916667 | E29: 0.60416667 | F29: 3 | G29: 3 | H29: =200*G29 -> 600
A30: Babe Mamba | B30: No Cellphone | C30: 45088 | D30: 0.75 | E30: 0.79166667 | F30: 1 | G30: 1 | H30: =200*G30 -> 200
A31: Babe Gideon | B31: No Cellphone | C31: 45088 | D31: 0.84166667 | E31: 0.88333333 | F31: 1 | G31: 1 | H31: =200*G31 -> 200
A32: Babe Gwebu | B32: No Cellphone | C32: 45088 | D32: 0.89583333 | E32: 0.9375 | F32: 1 | G32: 1 | H32: =200*G32 -> 200
A33: Pastor Gwebu | B33: No Cellphone | C33: 45088 | D33: 0.95833333 | E33: 0.54166667 | F33: 2 | G33: 2 | H33: =200*G33 -> 400
A34: Thabo | B34: 78219943 | C34: 45149 | D34: 0.25 | E34: 0.875 | F34: 3 | G34: 3 | H34: =200*G34 -> 600
A35: Make LaDladla | B35: 76134614 | C35: 45149 | D35: 0.39583333 | E35: 0.4375 | F35: 1 | G35: 1 | H35: =200*G35 -> 200
A36: Babe Ngwenya | B36: 76875547 | C36: 45149 | D36: 0.45833333 | E36: 0.54166667 | F36: 2 | G36: 2 | H36: =200*G36 -> 400
A37: Mehlaphi | B37: 76380224 | C37: 45149 | D37: 0.625 | E37: 0.66666667 | F37: 1 | G37: 1 | H37: =200*G37 -> 200
A38: Make mngometulu | B38: 76254813 | C38: 45149 | D38: 0.72916667 | E38: 0.77083333 | F38: 1 | G38: 1 | H38: =200*G38 -> 200
A39: Mazayifane | B39: No Cellphone | C39: 45180 | D39: 0.29166667 | E39: 0.33333333 | F39: 1 | G39: 1 | H39: =200*G39 -> 200
A40: Mdupoint | B40: 76058571 | C40: 45180 | D40: 0.35416667 | E40: 0.39583333 | F40: 1 | G40: 1 | H40: =200*G40 -> 200
A41: Mamba | B41: 76033369 | C41: 45180 | D41: 0.41666667 | E41: 0.45833333 | F41: 1 | G41: 1 | H41: =200*G41 -> 200
A42: Make Gamedze | B42: No Cellphone | C42: 45180 | D42: 0.5 | E42: 0.5625 | F42: 1.5 | G42: 1.5 | H42: =200*G42 -> 300
...

Sheet Gebeni
A1: ICBC Ploughing Project
C2: COMPLETE
A3: Name of ICBC: | B3: Gebeni ICBC | E3: Name of Pastor | F3: Sipho Mdluli
A4: Contractor's Full Name | B4: Thamsanqa Ntshalintshali | E4: Contractor's ID Number | F4: 7905016100276
A5: Bank | B5: Building Society | E5: Account Holder's Name | F5: Thamsanqa Ntshalintshali
A6: Branch Code | E6: Account Number | F6: 51001454947
A9: Community Member’s Name & Surname | B9: Contact Details | C9: Date | D9: Start Time (Date & Time) | E9: Completion time (Date & Time) | F9: Number of Hours | G9: Actual Number of Hours | H9: Amount | I9: Location
A10: Machawe Mndzebele | B10: 76532088 | C10: 45210 | F10: 1 | G10: 1 | H10: =G10*200 -> 200
A11: Bongane Mndzebele | B11: 78056179 | C11: 45210 | F11: 2 | G11: 2 | H11: =G11*200 -> 400
A12: Make nkambule | B12: No Cellphone | C12: 45210 | F12: 1 | G12: 1 | H12: =G12*200 -> 200
A13: Mancoba ndlovu | B13: No Cellphone | C13: 45210 | F13: 1 | G13: 1 | H13: =G13*200 -> 200
A14: Mr Titus Dlamini | B14: No Cellphone | C14: 45210 | F14: 2 | G14: 2 | H14: =G14*200 -> 400
A15: Mary Ntshalintshali | B15: No Cellphone | C15: 45210 | F15: 1 | G15: 1 | H15: =G15*200 -> 200
A16: Fundo Dlamini | B16: No Cellphone | C16: 45241 | F16: 1 | G16: 1 | H16: =G16*200 -> 200
A17: Letta mdluli | B17: 76471988 | C17: 45241 | F17: 2 | G17: 2 | H17: =G17*200 -> 400
A18: Scelo Mndzebele | B18: 79689936 | C18: 45241 | F18: 2 | G18: 2 | H18: =G18*200 -> 400
A19: Phindile Dlamini | B19: 76081625 | C19: 45241 | F19: 1 | G19: 1 | H19: =G19*200 -> 200
A20: Nicholas mabuza | B20: 76224315 | C20: 13/11/23 | F20: 2 | G20: 2 | H20: =G20*200 -> 400
A21: Mazwi manyatsi | B21: No Cellphone | C21: 13/11/23 | F21: 1 | G21: 1 | H21: =G21*200 -> 200
A22: Sikelelo manyatsi | B22: No Cellphone | C22: 13/11/23 | F22: 1 | G22: 1 | H22: =G22*200 -> 200
A23: Anna Nhlabatsi | B23: 76085415 | C23: 13/11/23 | F23: 1 | G23: 1 | H23: =G23*200 -> 200
A24: Siphiwe nhlabatsi | B24: No Cellphone | C24: 13/11/23 | F24: 1 | G24: 1 | H24: =G24*200 -> 200
A25: Thulani Dlamini | B25: 76048961 | C25: 15/11/23 | F25: 1 | G25: 1 | H25: =G25*200 -> 200
A26: Mhlonishwa Skhondze | B26: No Cellphone | C26: 15/11/23 | F26: 1 | G26: 1 | H26: =G26*200 -> 200
A27: Mumcy Magagula | B27: 76372193 | C27: 15/11/23 | F27: 4 | G27: 4 | H27: =G27*200 -> 800
A28: Moses Mndzebele | B28: 76138726 | C28: 16/11/23 | F28: 1 | G28: 1 | H28: =G28*200 -> 200
A29: Maphindi Nzima | B29: 78241223 | C29: 16/11/23 | F29: 2 | G29: 2 | H29: =G29*200 -> 400
A30: Mkhey Nzima | B30: No Cellphone | C30: 16/11/23 | F30: 1 | G30: 1 | H30: =G30*200 -> 200
A31: Make shlongonyane | B31: No Cellphone | C31: 16/11/23 | F31: 1 | G31: 1 | H31: =G31*200 -> 200
A32: John ndwandwa | B32: No Cellphone | C32: 16/11/23 | F32: 1 | G32: 1 | H32: =G32*200 -> 200
A33: Nomvula Mndzebele | B33: 76455320 | C33: 16/11/23 | F33: 1 | G33: 1 | H33: =G33*200 -> 200
A34: Bitiwe Mndzebele | B34: 76308501 | C34: 16/11/23 | F34: 1 | G34: 1 | H34: =G34*200 -> 200
A35: Nomvula Mndzebele | B35: No Cellphone | C35: 18/11/23 | F35: 1 | G35: 1 | H35: =G35*200 -> 200
A36: Anastasia mavimbela | B36: 78155350 | C36: 18/11/23 | F36: 2 | G36: 2 | H36: =G36*200 -> 400
A37: Make maziya | B37: No Cellphone | C37: 18/11/23 | F37: 1 | G37: 1 | H37: =G37*200 -> 200
A38: Mduduzi hlophe | B38: No Cellphone | C38: 20/11/23 | F38: 1 | G38: 1 | H38: =G38*200 -> 200
A39: Clc church | B39: 76030650 | C39: 20/11/23 | F39: 1 | G39: 1 | H39: =G39*200 -> 200
A40: Sketi ngwenya | B40: No Cellphone | C40: 20/11/23 | F40: 1 | G40: 1 | H40: =G40*200 -> 200
A41: Titus Dlamini | B41: 76478178 | C41: 20/11/23 | F41: 2 | G41: 2 | H41: =G41*200 -> 400
A42: Sipho mdluli | B42: 76030650 | C42: 20/11/23 | F42: 2 | G42: 2 | H42: =G42*200 -> 400
...

Sheet Gundvwini
A1: ICBC Ploughing Project
C2: COMPLETE
A3: Name of ICBC: | B3: Gundvwini ICBC | E3: Name of Pastor | F3: Dumisani Mdluli
A4: Contractor's Full Name | B4: Vuyisile Mndzebele | E4: Contractor's ID Number | F4: 8004181100045
A5: Bank | B5: Nedbank | E5: Account Holder's Name | F5: Vuyisile Mndzebele
A6: Branch Code | E6: Account Number | F6: 12990684926
A9: Community Member’s Name & Surname | B9: Contact Details | C9: Date | D9: Start Time (Date & Time) | E9: Completion time (Date & Time) | F9: Number of Hours | G9: Actual Number of Hours | H9: Amount | I9: Location
A10: Mphumaphi Dlamini | B10: 76883946 | C10: 23/10/23 | F10: 1 | G10: 1 | H10: =G10*200 -> 200
A11: Vusi Shongwe | B11: 76384871 | C11: 23/10/23 | F11: 1 | G11: 1 | H11: =G11*200 -> 200
A12: Mtetfwa Sifiso | B12: 76056406 | C12: 23/10/23 | F12: 1 | G12: 1 | H12: =G12*200 -> 200
A13: Owen Dlamini | B13: 76279824 | C13: 23/10/23 | F13: 1 | G13: 1 | H13: =G13*200 -> 200
A14: Sphendulo Dlamini | B14: 76363799 | C14: 23/10/23 | F14: 1 | G14: 1 | H14: =G14*200 -> 200
A15: Themba Nhleko | B15: 76129866 | C15: 23/10/23 | F15: 1 | G15: 1 | H15: =G15*200 -> 200
A16: Ndoda Nhleko | B16: 76376831 | C16: 23/10/23 | F16: 1 | G16: 1 | H16: =G16*200 -> 200
A17: Lizzy Shongwe | B17: 76528933 | C17: 23/10/23 | F17: 1 | G17: 1 | H17: =G17*200 -> 200
A18: Sambulo Nxumalo | B18: 76239853 | C18: 25/10/23 | F18: 1 | G18: 1 | H18: =G18*200 -> 200
A19: Losengela Sihlongonyane | B19: 78387550 | C19: 25/10/23 | F19: 1 | G19: 1 | H19: =G19*200 -> 200
A20: Jabulane Nhleko | B20: 76152846 | C20: 25/10/23 | F20: 1 | G20: 1 | H20: =G20*200 -> 200
A21: Tobe Sihlongonyane | B21: 76250181 | C21: 25/10/23 | F21: 1 | G21: 1 | H21: =G21*200 -> 200
... A25: Winile Dlamini | B25: 76273033 | C25: 30/10/23 | F25: 2 | G25: 2 | H25: =G25*200 -> 400
A26: Mduduzi Shongwe | B26: 76259172 | C26: 44937 | F26: 1 | G26: 1 | H26: =G26*200 -> 200
A27: Menzi Gwebu | B27: 76417178 | C27: 44937 | F27: 2 | G27: 2 | H27: =G27*200 -> 400
A28: Winile Dlamini | B28: 76273033 | C28: 44937 | F28: 1 | G28: 1 | H28: =G28*200 -> 200
A29: Sifiso Dlamini | B29: 76079069 | C29: 44937 | F29: 1 | G29: 1 | H29: =G29*200 -> 200
A30: Dada Gwebu | B30: 76771058 | C30: 44937 | F30: 1 | G30: 1 | H30: =G30*200 -> 200
A31: make Gwebu | B31: 76771058 | C31: 14/12/23 | F31: 2 | G31: 2 | H31: =G31*200 -> 400
A32: skhebesi Nxumalo | B32: 79151954 | C32: 14/12/23 | F32: 2 | G32: 2 | H32: =G32*200 -> 400
A33: make Owen | B33: 76279824 | C33: 14/12/23 | F33: 1 | G33: 1 | H33: =G33*200 -> 200
A34: make Khumalo | B34: 76045017 | C34: 14/12/23 | F34: 1 | G34: 1 | H34: =G34*200 -> 200
A35: Linda Nxumalo | B35: 76698808 | C35: 14/12/23 | F35: 2 | G35: 2 | H35: =G35*200 -> 400
A36: Mveli Nxumalo | B36: 78680447 | C36: 14/12/23 | F36: 2 | G36: 2 | H36: =G36*200 -> 400
A37: Make Mndzebele | B37: 76124165 | C37: 14/12/23 | F37: 1 | G37: 1 | H37: =G37*200 -> 200
H38: =G38*200 -> 0
E39: Total | F39: =sum(F10:F38) -> 36 | G39: =SUM(G10:G38) -> 36 | H39: =SUM(H10:H38) -> 7200
E40: Total number of fields ploughed | F40: =COUNT(G10:G38) -> 28
D42: Checked By
D44: Signature
D46: Date

Sheet Hawane
A1: ICBC Ploughing Project
C2: COMPLETE
A3: Name of ICBC: | B3: Hawane ICBC | E3: Name of Pastor | F3: Timothy Makhanya
A4: Contractor's Full Name | B4: Wilton Nkhambule | E4: Contractor's ID Number
A5: Bank | B5: NEDBANK | E5: Account Holder's Name | F5: Wilton Nkhambule
A6: Branch Code | B6: 360164 | E6: Account Number | F6: 200 000 66185
A9: Community Member’s Name & Surname | B9: Contact Details | C9: Date | D9: Start Time (Date & Time) | E9: Completion time (Date & Time) | F9: Number of Hours | G9: Actual Number of Hours | H9: Amount | I9: Location
A10: Make Maziya | B10: 76911205 | F10: 1 | G10: 1 | H10: =G10*200 -> 200
A11: Mbali Lukhuleni | B11: 76956953 | F11: 1 | G11: 1 | H11: =G11*200 -> 200
A12: Make Bill | B12: 76117856 | F12: 1 | G12: 1 | H12: =G12*200 -> 200
A13: Samuel Makhanya | B13: 78728911/79389242 | F13: 1 | G13: 1 | H13: =G13*200 -> 200
A14: Make Dudu Shongwe | B14: No Cellphone | F14: 2 | G14: 2 | H14: =G14*200 -> 400
A15: Jabulile Mlotjwa | B15: 78300499 | F15: 1 | G15: 1 | H15: =G15*200 -> 200
A16: Kufakwakhe Masina | B16: 76816728 | F16: 1 | G16: 1 | H16: =G16*200 -> 200
A17: KaBhembe | B17: No Cellphone | F17: 1 | G17: 1 | H17: =G17*200 -> 200
A18: Make N. Dlamini | B18: No Cellphone | F18: 1 | G18: 1 | H18: =G18*200 -> 200
A19: Babe Nkambule | B19: 76932227 | F19: 1 | G19: 1 | H19: =G19*200 -> 200
A20: Babe Masuku | B20: 76596026 | F20: 1 | G20: 1 | H20: =G20*200 -> 200
A21: Siboniso Ntjangase | B21: No Cellphone | F21: 1 | G21: 1 | H21: =G21*200 -> 200
A22: Sifiso Hlatswako | B22: No Cellphone | F22: 1 | G22: 1 | H22: =G22*200 -> 200
A23: Make G. Mndzebele | B23: No Cellphone | F23: 1 | G23: 1 | H23: =G23*200 -> 200
A24: Portia Mhlanga | B24: No Cellphone | F24: 1 | G24: 1 | H24: =G24*200 -> 200
A25: M. Mkhwanazi | B25: No Cellphone | F25: 2 | G25: 2 | H25: =G25*200 -> 400
A26: Make Sibandze | B26: No Cellphone | F26: 2 | G26: 2 | H26: =G26*200 -> 400
A27: Make Manzini | B27: No Cellphone | F27: 1 | G27: 1 | H27: =G27*200 -> 200
A28: Beauty Hlophe | B28: No Cellphone | F28: 1 | G28: 1 | H28: =G28*200 -> 200
A29: Happy Dlamini | B29: 76962791 | F29: 1 | G29: 1 | H29: =G29*200 -> 200
A30: Make Dlamini | B30: No Cellphone | F30: 1 | G30: 1 | H30: =G30*200 -> 200
A31: Simangele Mabuza | B31: No Cellphone | F31: 2 | G31: 2 | H31: =G31*200 -> 400
A32: Mpendulo Mlotjwa | B32: No Cellphone | F32: 2 | G32: 2 | H32: =G32*200 -> 400
A33: Mcolisi Bhembe | B33: No Cellphone | F33: 2 | G33: 2 | H33: =G33*200 -> 400
A34: Tsela | B34: No Cellphone | F34: 2 | G34: 2 | H34: =G34*200 -> 400
A35: Khuba Dlamini | B35: No Cellphone | F35: 2 | G35: 2 | H35: =G35*200 -> 400
A36: Mangwe | B36: No Cellphone | F36: 2 | G36: 2 | H36: =G36*200 -> 400
A37: Make Mhlanga | B37: No Cellphone | F37: 1 | G37: 1 | H37: =G37*200 -> 200
A38: Make Matsenjwa | B38: No Cellphone | F38: 2 | G38: 2 | H38: =G38*200 -> 400
A39: Kagogo Dladla | B39: No Cellphone | F39: 1 | G39: 1 | H39: =G39*200 -> 200
A40: KaMsibi | B40: No Cellphone | F40: 2 | G40: 2 | H40: =G40*200 -> 400
A41: KaShongwe | B41: No Cellphone | F41: 1 | G41: 1 | H41: =G41*200 -> 200
... A45: KaHlatjwako | B45: No Cellphone | F45: 1 | G45: 1 | H45: =G45*200 -> 200
...

Sheet Jubukweni
A1: ICBC Ploughing Project
C2: COMPLETE
A3: Name of ICBC: | B3: Jubukweni ICBC | E3: Name of Pastor | F3: Sipho Kunene
A4: Contractor's Full Name | B4: Wendy Matsoe Makhubela Tfumbatsa | E4: Contractor's ID Number | F4: 8404251100034
A5: Bank | B5: First National Bank | E5: Account Holder's Name | F5: Wendy Matsoe Makhubela Tfumbatsa
A6: Branch Code | E6: Account Number | F6: 62298487151
A9: Community Member’s Name & Surname | B9: Contact Details | C9: Date | D9: Start Time (Date & Time) | E9: Completion time (Date & Time) | F9: Number of Hours | G9: Actual Number of Hours | H9: Amount | I9: Location
A10: Make Nkhambule (Skhondze) | B10: 78132547 | F10: 4 | G10: 4 | H10: =G10*200 -> 800
A11: Sambulo | B11: 76123907 | F11: 2 | G11: 2 | H11: =G11*200 -> 400
A12: Babe Mbingo | B12: 76151139 | F12: 2 | G12: 2 | H12: =G12*200 -> 400
A13: Sthole | B13: 76906856 | F13: 2 | G13: 2 | H13: =G13*200 -> 400
A14: Make Maziya | B14: 78491962 | F14: 2 | G14: 2 | H14: =G14*200 -> 400
A15: Mandla | B15: 76976247 | F15: 1 | G15: 1 | H15: =G15*200 -> 200
A16: Babe Dlamini | F16: 1 | G16: 1 | H16: =G16*200 -> 200
A17: Mngometulu | B17: 76787874 | F17: 2 | G17: 2 | H17: =G17*200 -> 400
A18: Babe Ngwenya | B18: 76036206 | F18: 2 | G18: 2 | H18: =G18*200 -> 400
A19: Mkhulu Mnisi | B19: 76037243 | F19: 1 | G19: 1 | H19: =G19*200 -> 200
A20: Make Maphalala | B20: No Cellphone | C20: 44937 | F20: 2 | G20: 2 | H20: =G20*200 -> 400
A21: Mabuza | B21: No Cellphone | C21: 44937 | F21: 1 | G21: 1 | H21: =G21*200 -> 200
A22: Make Gumedze | B22: No Cellphone | C22: 44968 | F22: 2 | G22: 2 | H22: =G22*200 -> 400
A23: Babe Gama | B23: No Cellphone | C23: 44968 | F23: 2 | G23: 2 | H23: =G23*200 -> 400
A24: Zakhele Mthembu | B24: No Cellphone | C24: 44968 | F24: 1 | G24: 1 | H24: =G24*200 -> 200
A25: Make Masilela | B25: No Cellphone | C25: 44968 | F25: 1 | G25: 1 | H25: =G25*200 -> 200
A26: Musa Mnisi | B26: No Cellphone | C26: 44968 | F26: 2 | G26: 2 | H26: =G26*200 -> 400
A27: Make Skhondze | B27: 76492038 | F27: 1 | G27: 1 | H27: =G27*200 -> 200
A28: Make Maseko Ka, Sikhinde | B28: 78646249 | C28: 44996 | F28: 3 | G28: 3 | H28: =G28*200 -> 600
A29: Make Zwane | B29: 76355080 | C29: 44996 | F29: 3 | G29: 3 | H29: =G29*200 -> 600
A30: Mkhulu Mabuza | B30: No Phone Numbr | C30: 44996 | F30: 1 | G30: 1 | H30: =G30*200 -> 200
A31: KaMnisi | B31: No Cellphone | C31: 45057 | F31: 1 | G31: 1 | H31: =G31*200 -> 200
A32: KaLaKunene | B32: 76419622 | C32: 45057 | F32: 1 | G32: 1 | H32: =G32*200 -> 200
A33: KaMnisi | B33: 76145091 | F33: 1 | G33: 1 | H33: =G33*200 -> 200
A34: KaMaseko | B34: 76145091 | F34: 1 | G34: 1 | H34: =G34*200 -> 200
A35: KaSithole | B35: No Cellphone | F35: 1 | G35: 1 | H35: =G35*200 -> 200
A36: Mkhulu Mnisi | B36: 76037243 | F36: 1 | G36: 1 | H36: =G36*200 -> 200
A37: Dlamini | B37: No Cellphone | F37: 1 | G37: 1 | H37: =G37*200 -> 200
A38: Mahlalela | B38: 78036057 | F38: 1 | G38: 1 | H38: =G38*200 -> 200
A39: Thabani Mnisi | B39: No Cellphone | F39: 1 | G39: 1 | H39: =G39*200 -> 200
A40: Esontfweni | B40: 76185900 | F40: 1 | G40: 1 | H40: =G40*200 -> 200
A41: Gogo Mnisi | B41: 76037203 | F41: 1 | G41: 1 | H41: =G41*200 -> 200
E42: Total | F42: =SUM(F10:F41) -> 49 | G42: =SUM(G10:G41) -> 49 | H42: =SUM(H2:H41) -> 9800
...

Sheet Kaliba
A1: ICBC Ploughing Project
C2: COMPLETE
A3: Name of ICBC: | B3: KaLiba ICBC | E3: Name of Pastor | F3: Majahonkhe Tsabedze
A4: Contractor's Full Name | B4: Stanford S Dlamini | E4: Contractor's ID Number | F4: 6311136100166
A5: Bank | B5: First National Bank | E5: Account Holder's Name | F5: Stanford S Dlamini
A6: Branch Code | B6: 1779 | E6: Account Number | F6: 62094610758
A9: Community Member’s Name & Surname | B9: Contact Details | C9: Date | D9: Start Time (Date & Time) | E9: Completion time (Date & Time) | F9: Number of Hours | G9: Actual Number of Hours | H9: Amount | I9: Location
A10: Nokulunga Mthembu | B10: 76746433 | C10: 45088 | D10: 0555hrs | E10: 0801hrs | F10: 2 | G10: 2 | H10: =G10*200 -> 400
A11: Mambiwa Dlamini | B11: 78541839 | C11: 45088 | D11: 0807hrs | E11: 1013hrs | F11: 2 | G11: 2 | H11: =G11*200 -> 400
A12: Jabulani Malindzisa | B12: 76052996 | C12: 45088 | D12: 1028hrs | E12: 1131hrs | F12: 1 | G12: 1 | H12: =G12*200 -> 200
A13: Khaya Mabuza | B13: 76804699 | C13: 45088 | D13: 1155hrs | E13: 1258hrs | F13: 1 | G13: 1 | H13: =G13*200 -> 200
A14: Jethro Zungu | B14: 78526604 | C14: 45088 | D14: 1415hrs | E14: 1521hrs | F14: 1 | G14: 1 | H14: =G14*200 -> 200
A15: Rose Mhlanga | B15: 76590417 | C15: 45088 | D15: 1537hrs | E15: 1643hrs | F15: 1 | G15: 1 | H15: =G15*200 -> 200
A16: Ndlaleni Mabuza | B16: 76518082 | C16: 45118 | D16: 0700hrs | E16: 0909hrs | F16: 2 | G16: 2 | H16: =G16*200 -> 400
A17: Lomsombuluko Fakudze | B17: 78261614 | C17: 45118 | D17: 0935hrs | E17: 1033hrs | F17: 1 | G17: 1 | H17: =G17*200 -> 200
A18: Felicia Myeni | B18: 76148718 | C18: 45118 | D18: 1050hrs | E18: 1159hrs | F18: 1 | G18: 1 | H18: =G18*200 -> 200
A19: Ester Malindzisa | B19: 7835517 | C19: 45149 | D19: 1300hrs | E19: 1455hrs | F19: 2 | G19: 2 | H19: =G19*200 -> 400
A20: Norah Fakudze | B20: 766725315 | C20: 45149 | D20: 1515hrs | E20: 1717hrs | F20: 2 | G20: 2 | H20: =G20*200 -> 400
A21: Sambane Fakudze | B21: 76123830 | C21: 45180 | D21: 0607hrs | E21: 0711hrs | F21: 1 | G21: 1 | H21: =G21*200 -> 200
A22: Ndaba Malindzisa | B22: No Cellphone | C22: 45180 | D22: 0749hrs | E22: 0855hrs | F22: 1 | G22: 1 | H22: =G22*200 -> 200
A23: Ezekiel Mabuza | B23: 76148833 | C23: 45180 | D23: 0904hrs | E23: 1002hrs | F23: 1 | G23: 1 | H23: =G23*200 -> 200
A24: Prince Thobile | B24: 78407657 | C24: 45180 | D24: 1013hrs | E24: 1209hrs | F24: 2 | G24: 2 | H24: =G24*200 -> 400
A25: Pauline Dlamini | B25: 76889377 | C25: 45180 | D25: 1226hrs | E25: 1325hrs | F25: 1 | G25: 1 | H25: =G25*200 -> 200
A26: Takhona Malindzisa | B26: 76074075 | C26: 45180 | D26: 1344hrs | E26: 1438hrs | F26: 1 | G26: 1 | H26: =G26*200 -> 200
A27: Gcwalisile Dlamini | B27: 78154421 | C27: 45180 | D27: 1516hrs | E27: 1621hrs | F27: 1 | G27: 1 | H27: =G27*200 -> 200
A28: Gweyevu Fafudze | B28: 76084154 | C28: 45210 | D28: 1025hrs | E28: 1331hrs | F28: 3 | G28: 3 | H28: =G28*200 -> 600
A29: Bheki Fakudze | B29: 7818857 | C29: 45210 | D29: 1340hrs | E29: 1441hrs | F29: 1 | G29: 1 | H29: =G29*200 -> 200
A30: Sifiso Fakudze | B30: 76071011 | C30: 45210 | D30: 1501hrs | E30: 1600hrs | F30: 1 | G30: 1 | H30: =G30*200 -> 200
A31: Pardon Mabuza | B31: 76037008 | C31: 45210 | D31: 1607hrs | E31: 1807hrs | F31: 2 | G31: 2 | H31: =G31*200 -> 400
A32: Mr Simelane | B32: 76437743 | C32: 45241 | D32: 0549hrs | E32: 0755hrs | F32: 2 | G32: 2 | H32: =G32*200 -> 400
A33: Girly Dlamini | B33: 78112019 | C33: 45241 | D33: 0812hrs | E33: 0916hrs | F33: 1 | G33: 1 | H33: =G33*200 -> 200
A34: Lungile Ntjakala | B34: 76587432 | C34: 45241 | D34: 0924hrs | E34: 1031hrs | F34: 1 | G34: 1 | H34: =G34*200 -> 200
A35: Sandile Mkhweli | B35: 76150843 | C35: 45241 | D35: 1147hrs | E35: 1259hrs | F35: 1 | G35: 1 | H35: =G35*200 -> 200
A36: Sendzeleni Fakudze | B36: 76084808 | C36: 16/11/23 | D36: 0511hrs | E36: 0717hrs | F36: 2 | G36: 2 | H36: =G36*200 -> 400
A37: Pardon Mabuza | B37: 76037008 | C37: 16/11/23 | D37: 0731hrs | E37: 0829hrs | F37: 1 | G37: 1 | H37: =G37*200 -> 200
A38: Pastor Mtsetfwa | B38: 78145747 | C38: 16/11/23 | D38: 0847hrs | E38: 0955hrs | F38: 1 | G38: 1 | H38: =G38*200 -> 200
A39: Khulile Mabuza | B39: 78128180 | C39: 16/11/23 | D39: 1011hrs | E39: 1115hrs | F39: 1 | G39: 1 | H39: =G39*200 -> 200
A40: Khosikhona Zwane | B40: No Cellphone | C40: 16/11/23 | D40: 1159hrs | E40: 1308hrs | F40: 1 | G40: 1 | H40: =G40*200 -> 200
A41: Magawu Zwane | B41: 76544107 | C41: 16/11/23 | D41: 1331hrs | E41: 1444hrs | F41: 1 | G41: 1 | H41: =G41*200 -> 200
A42: Gcwali Dlamini | B42: 78154421 | C42: 16/11/23 | D42: 1519hrs | E42: 1628hrs | F42: 1 | G42: 1 | H42: =G42*200 -> 200
...

Sheet Lavumisa
A1: ICBC Ploughing Project
D2: COMPLETE
A3: Name of ICBC: | B3: Lavumisa ICBC | F3: Name of Pastor | G3: Sabelo Gina
A4: Contractor's Full Name | B4: Sunboy Sithembiso Msibi | F4: Contractor's ID Number
A5: Bank | B5: Fist National Bank | F5: Account Holder's Name | G5: Sunboy Sithembiso Msibi
A6: Branch Code | F6: Account Number | G6: E- Wallet 76122450
A9: Community Member’s Name & Surname | B9: Contact Details | C9: ID | D9: Date | E9: Start Time (Date & Time) | F9: Completion time (Date & Time) | G9: Number of Hours | H9: Actual Number of Hours | I9: Amount | J9: Location
A10: Bonisile Makhanya | B10: 76680416 | D10: 45295 | G10: 1 | H10: 1 | I10: =H10*200 -> 200
A11: Lungelo Mngometulu | B11: 76841177 | D11: 45296 | G11: 1 | H11: 1 | I11: =H11*200 -> 200
A12: Sisana Gina | B12: 76554905 | D12: 45297 | G12: 1 | H12: 1 | I12: =H12*200 -> 200
I13: =H13*200 -> 0
I14: =H14*200 -> 0
I15: =H15*200 -> 0
I16: =H16*200 -> 0
I17: =H17*200 -> 0
I18: =H18*200 -> 0
I19: =H19*200 -> 0
I20: =H20*200 -> 0
I21: =H21*200 -> 0
I22: =H22*200 -> 0
I23: =H23*200 -> 0
I24: =H24*200 -> 0
... I30: =H30*200 -> 0
F31: Total | G31: =sum(G10:G30) -> 3 | H31: =SUM(H1:H30) -> 3 | I31: =SUM(I10:I30) -> 600
F32: Total number of fields ploughed | G32: =COUNT(H2:H30) -> 3
E34: Checked By
E35: Signature
E36: Date

Sheet Lundzi
A1: ICBC Ploughing Project
D2: COMPLETE
A3: Name of ICBC: | B3: Lundzi ICBC | F3: Name of Pastor | G3: Bongiswa Ntshali
A4: Contractor's Full Name | B4: Ganbarou Investments Pty Ltd | F4: Contractor's ID Number
A5: Bank | B5: Swazi Bank | F5: Account Holder's Name | G5: Ganbarou Investments Pty Ltd
A6: Branch Code | F6: Account Number | G6: 77401567278
A9: Community Member’s Name & Surname | B9: Contact Details | C9: ID | D9: Date | E9: Start Time (Date & Time) | F9: Completion time (Date & Time) | G9: Number of Hours | H9: Actual Number of Hours | I9: Amount | J9: Location
A10: Nkhambule | B10: 76355070 | G10: 3 | H10: 3 | I10: =H10*200 -> 600
A11: Mdluli | B11: 76893400 | G11: 2 | H11: 2 | I11: =H11*200 -> 400
A12: Masuku | B12: 76802640 | G12: 3 | H12: 3 | I12: =H12*200 -> 600
A13: Zama | B13: 76298599 | G13: 4 | H13: 4 | I13: =H13*200 -> 800
A14: Sibongile | B14: 76419953 | G14: 2 | H14: 2 | I14: =H14*200 -> 400
A15: Mkhonta | B15: 76522170 | G15: 1 | H15: 1 | I15: =H15*200 -> 200
A16: Maseko | B16: 76583349 | G16: 2 | H16: 2 | I16: =H16*200 -> 400
A17: Mtsetfwa | B17: 76746429 | G17: 4 | H17: 4 | I17: =H17*200 -> 800
A18: Gogo Nkhosi | B18: 76640205 | G18: 4 | H18: 4 | I18: =H18*200 -> 800
A19: Shongwe | B19: 76670768 | G19: 2 | H19: 2 | I19: =H19*200 -> 400
A20: Mdolly | B20: 78663303 | G20: 5 | H20: 5 | I20: =H20*200 -> 1000
A21: Njakala | B21: 78125690 | G21: 4 | H21: 4 | I21: =H21*200 -> 800
... A29: Gugu | B29: 76837261 | G29: 2 | H29: 2 | I29: =H29*200 -> 400
F30: Total | G30: =sum(G10:G29) -> 57 | H30: =SUM(H1:H29) -> 57 | I30: =SUM(I10:I29) -> 11400
F31: Total number of fields ploughed | G31: =COUNT(H2:H29) -> 20
E33: Checked By
E34: Signature
E35: Date

Sheet Lonhlalane
A1: ICBC Ploughing Project
C2: COMPLETE
A3: Name of ICBC: | B3: Lonhlalane ICBC | E3: Name of Pastor | F3: Johannes Ndwandwe
A4: Contractor's Full Name | B4: Vusumuzi Mhlanga | E4: Contractor's ID Number | F4: 8007226100235
A5: Bank | B5: Nedbank | E5: Account Holder's Name | F5: July Vusumuzi Mhlanga
A6: Branch Code | E6: Account Number | F6: 12990364255
A9: Community Member’s Name & Surname | B9: Contact Details | C9: Date | D9: Start Time (Date & Time) | E9: Completion time (Date & Time) | F9: Number of Hours | G9: Actual Number of Hours | H9: Amount | I9: Location
A10: Solomon Dlamini | F10: 1 | G10: 1 | H10: =G10*200 -> 200
A11: Veni Vilane | F11: 3 | G11: 3 | H11: =G11*200 -> 600
A12: Nabo Sentani | F12: 1 | G12: 1 | H12: =G12*200 -> 200
A13: Ntfulintfuli | F13: 2 | G13: 2 | H13: =G13*200 -> 400
A14: LaNkhosi Makanana | F14: 1 | G14: 1 | H14: =G14*200 -> 200
A15: LaMatibuko | F15: 1 | G15: 1 | H15: =G15*200 -> 200
A16: Mphatsu Magagula | F16: 1 | G16: 1 | H16: =G16*200 -> 200
A17: LaMabuza Magagula | F17: 1 | G17: 1 | H17: =G17*200 -> 200
A18: Lamakhabane | F18: 1 | G18: 1 | H18: =G18*200 -> 200
A19: Mbonane | F19: 1 | G19: 1 | H19: =G19*200 -> 200
A20: Make Ndzabandzaba | F20: 1 | G20: 1 | H20: =G20*200 -> 200
A21: LaMtutu | F21: 1 | G21: 1 | H21: =G21*200 -> 200
... A43: Siphiwe Tsabedze | F43: 1 | G43: 1 | H43: =G43*200 -> 200
E44: Total | F44: =SUM(F9:F43) -> 50 | G44: =SUM(G1:G43) -> 50 | H44: =SUM(H9:H43) -> 10000
E45: Total number of fields ploughed | F45: =COUNT(F10:F43) -> 34
D47: Checked By
D48: Signature
D49: Date

Sheet Lushikishini
A1: ICBC Ploughing Project
D2: COMPLETE
A3: Name of ICBC: | B3: Lushikishini ICBC | F3: Name of Pastor | G3: Phumzile Dlamini
A4: Contractor's Full Name | B4: Rural Development Agency(RDA) Government | F4: Contractor's ID Number | G4: 8001181100132
A5: Bank | B5: First National Bank | F5: Account Holder's Name | G5: Phumzile Melinda Dlamini
A6: Branch Code | F6: Account Number | G6: 62334485415
A9: Community Member’s Name & Surname | B9: Contact Details | C9: ID | D9: Date | E9: Start Time (Date & Time) | F9: Completion time (Date & Time) | G9: Number of Hours | H9: Actual Number of Hours | I9: Amount | J9: Location
A10: Sibongile Hlophe | B10: 76274234 | C10: 6712021100122 | D10: 44968 | G10: 3 | H10: 3 | I10: =H10*200 -> 600 | J10: 26°46'20.6"S 30°52'53.2"E
A11: Moses Hlophe | B11: 76322552 | C11: 7506206100488 | D11: 44968 | G11: 1 | H11: 1 | I11: =H11*200 -> 200 | J11: 26°46'20.7"S 30°53'00.5"E
A12: Vusi Maseko | B12: 76380090 | C12: 7704046100715 | D12: 45149 | G12: 3 | H12: 3 | I12: =H12*200 -> 600 | J12: 26°47'09.1"S 30°52'19.4"E
A13: Mfanasibili Dlamini | B13: 76076856 | C13: 6804186100391 | D13: 45149 | G13: 2 | H13: 2 | I13: =H13*200 -> 400 | J13: 26°47'05.7"S 30°52'04.4"E
A14: Gladice Mdluli | B14: 76820410 | C14: 5205281100040 | D14: 44968 | G14: 2 | H14: 2 | I14: =H14*200 -> 400 | J14: 26°46'36.0"S 30°52'55.8"E
A15: Vinnah Motsa | B15: 76688244 | C15: 5307291100075 | D15: 44996 | G15: 2 | H15: 2 | I15: =H15*200 -> 400 | J15: 26°46'52.6"S 30°53'10.5"E
A16: Ngingi Motsa | B16: 76287890 | C16: 7212256101050 | D16: 44968 | G16: 3 | H16: 3 | I16: =H16*200 -> 600 | J16: 26°46'41.1"S 30°52'43.4"E
I17: =H17*200 -> 0 | J17: 26°46'41.1"S 30°52'43.4"E
I18: =H18*200 -> 0
I19: =H19*200 -> 0
I20: =H20*200 -> 0
I21: =H21*200 -> 0
I22: =H22*200 -> 0
I23: =H23*200 -> 0
I24: =H24*200 -> 0
I25: =H25*200 -> 0
I26: =H26*200 -> 0
I27: =H27*200 -> 0
I28: =H28*200 -> 0
I29: =H29*200 -> 0
I30: =H30*200 -> 0
F31: Total | G31: =sum(G10:G30) -> 16 | H31: =SUM(H1:H30) -> 16 | I31: =SUM(I10:I30) -> 3200
F32: Total number of fields ploughed | G32: =COUNT(H2:H30) -> 7
E34: Checked By
E35: Signature
E36: Date

Sheet Mangcongco
A1: ICBC Ploughing Project
C2: COMPLETE
A3: Name of ICBC: | B3: Mangcongco ICBC | E3: Name of Pastor | F3: Ndumiso Dlamini
A5: Contractor | B5: Sum Investments | E5: Contractor's ID Number | F5: 5610116100224
A6: Bank | B6: First National Bank | E6: Account Holder's Name | F6: ONE BOY ZIKALALA
A7: Branch Code | B7: Simunye | E7: Account Number | F7: 62103866961
A9: Contractor | B9: Umnotfo Association | E9: Account Holder's Name
A10: Bank | B10: Eswatini Building society | E10: Account Number | F10: 51000510169
A12: Community Member’s Name & Surname | B12: Contact Details | C12: Date | D12: Start Time (Date & Time) | E12: Completion time (Date & Time) | F12: Number of Hours | G12: Actual Number of Hours | H12: Amount | I12: Location
A13: Daniel Zikalala | F13: 1 | G13: 1 | H13: =G13*200 -> 200
A14: Forgive Zikalala | B14: 78178387 | F14: 1 | G14: 1 | H14: =G14*200 -> 200
A15: Hlengiwe Mhlanga | B15: 76281974 | F15: 2 | G15: 2 | H15: =G15*200 -> 400
A16: sifiso kunene | B16: 76674700 | F16: 1 | G16: 1 | H16: =G16*200 -> 200
A17: Glory Hlophe | B17: 76574982 | F17: 1 | G17: 1 | H17: =G17*200 -> 200
A18: Mbutwana Dlamini | F18: 2 | G18: 2 | H18: =G18*200 -> 400
A19: Roy Mbetse | B19: 76225689 | F19: 2 | G19: 2 | H19: =G19*200 -> 400
A20: Mayibongwe Ndlangamandla | B20: 78430977 | F20: 1 | G20: 1 | H20: =G20*200 -> 200
A21: Enoch Dlamini | B21: 78380967 | F21: 2 | G21: 2 | H21: =G21*200 -> 400
A22: Dumsani Dlamini | B22: 76048313 | F22: 1 | G22: 1 | H22: =G22*200 -> 200
A23: maltha Dvuba | B23: 76540688 | F23: 1 | G23: 1 | H23: =G23*200 -> 200
A24: Bethina Dlamini | B24: 768220088 | F24: 1 | G24: 1 | H24: =G24*200 -> 200
A25: mavela Dlamini | B25: 78390315 | F25: 2 | G25: 2 | H25: =G25*200 -> 400
A26: Delsile Dlamini | B26: 76575692 | F26: 1 | G26: 1 | H26: =G26*200 -> 200
A27: Evelyn Dlamini | B27: 78366374 | F27: 1 | G27: 1 | H27: =G27*200 -> 200
A28: lulu maseko | B28: 76468465 | F28: 1 | G28: 1 | H28: =G28*200 -> 200
A29: Elizabeth Dlamini | B29: 78219643 | F29: 1 | G29: 1 | H29: =G29*200 -> 200
A30: Evelyn Shongwe | B30: 78366394 | F30: 2 | G30: 2 | H30: =G30*200 -> 400
... A32: Thembi Dlamini | B32: 76793001 | F32: 2 | G32: 2 | H32: =G32*200 -> 400
A33: Rose Dlamini | F33: 1 | G33: 1 | H33: =G33*200 -> 200
A34: Bongani Sibisi | B34: 78654142 | F34: 1 | G34: 1 | H34: =G34*200 -> 200
A35: Elder zwane | B35: 78054646 | F35: 1 | G35: 1 | H35: =G35*200 -> 200
A36: Sindi Zikalala | B36: 76173476 | F36: 2 | G36: 2 | H36: =G36*200 -> 400
A37: Ntokozo Zikalala | F37: 2 | G37: 2 | H37: =G37*200 -> 400
A38: Ruben Zwane | B38: 76338875 | F38: 2 | G38: 2 | H38: =G38*200 -> 400
A39: Elizabeth Zikalala | B39: 76744242 | F39: 2 | G39: 2 | H39: =G39*200 -> 400
A40: Nkhosinathi zwane | B40: 76447995 | F40: 2 | G40: 2 | H40: =G40*200 -> 400
A41: Jabulane Zikalala | B41: 76958554 | F41: 2 | G41: 2 | H41: =G41*200 -> 400
A42: Ellen mbuli | B42: 76314853 | F42: 2 | G42: 2 | H42: =G42*200 -> 400
A43: Mebra zikalala | F43: 1 | G43: 1 | H43: =G43*200 -> 200
A44: Mphohlo mabuza | B44: 76404190 | F44: 1 | G44: 1 | H44: =G44*200 -> 200
...

Sheet Mbowane
A1: ICBC Ploughing Project
C2: COMPLETE
A3: Name of ICBC: | B3: Mbowane ICBC | E3: Name of Pastor | F3: Bongani Mngometulu
A4: Contractor's Full Name | B4: Samkelisiwe Pertunia Hlophe | E4: Contractor's ID Number | F4: 8010151100022
A5: Bank | B5: Nedbank | E5: Account Holder's Name | F5: Samkelisiwe Pertunia Hlophe
A6: Branch Code | B6: Nhlangano code | E6: Account Number | F6: 60000004866
A9: Community Member’s Name & Surname | B9: Contact Details | C9: Date | D9: Start Time (Date & Time) | E9: Completion time (Date & Time) | F9: Number of Hours | G9: Actual Number of Hours | H9: Amount | I9: Location
A10: Jame Simelane | B10: 76438848 | C10: 25/11/23 | D10: 0.17361111 | E10: 0.25555556 | F10: 2 | G10: 2 | H10: =G10*200 -> 400
A11: Mkhetsile Mkhaliphi | B11: 78681925 | C11: 25/11/23 | D11: 0.26041667 | E11: 0.34444444 | F11: 2 | G11: 2 | H11: =G11*200 -> 400
A12: Josephina Nzima | B12: 78572174 | C12: 25/11/23 | D12: 0.34722222 | E12: 0.38888889 | F12: 1 | G12: 1 | H12: =G12*200 -> 200
A13: Elizabeth Nzima | B13: 76939343 | C13: 25/11/23 | D13: 0.39097222 | E13: 0.43055556 | F13: 1 | G13: 1 | H13: =G13*200 -> 200
A14: Lindiwe Mlotshwa | B14: 76378703 | C14: 25/11/23 | D14: 0.4375 | E14: 0.49930556 | F14: 1 | G14: 1 | H14: =G14*200 -> 200
A15: Khayalethu Nzima | B15: 76809559 | C15: 25/11/23 | D15: 0.50347222 | E15: 0.54583333 | F15: 1 | G15: 1 | H15: =G15*200 -> 200
A16: Bongani Mngometulu | B16: 76785885 | C16: 25/11/23 | D16: 0.54861111 | E16: 0.67361111 | F16: 3 | G16: 3 | H16: =G16*200 -> 600
A17: Sibongile Magagula | B17: 78257988 | C17: 25/11/23 | D17: 0.21527778 | E17: 0.25694444 | F17: 1 | G17: 1 | H17: =G17*200 -> 200
A18: Sipho Simelane | B18: 76673744 | C18: 25/11/23 | D18: 0.26388889 | E18: 0.30555556 | F18: 1 | G18: 1 | H18: =G18*200 -> 200
A19: Senteni Lukhele | B19: 76445265 | C19: 25/11/23 | D19: 0.30694444 | E19: 0.38888889 | F19: 2 | G19: 2 | H19: =G19*200 -> 400
A20: Lomvimbi Nhlengethwa | B20: 76296333 | C20: 25/11/23 | D20: 0.40277778 | E20: 0.48611111 | F20: 2 | G20: 2 | H20: =G20*200 -> 400
A21: Sabelo Nzima | B21: 76675231 | C21: 25/11/23 | D21: 0.48958333 | E21: 0.57291667 | F21: 2 | G21: 2 | H21: =G21*200 -> 400
... A42: Jabulile Mkhwanazi | B42: 76662135 | C42: 29/11/23 | D42: 0.37847222 | E42: 0.45833333 | F42: 2 | G42: 2 | H42: =G42*200 -> 400
E43: Total | F43: =SUM(F9:F42) -> 50 | G43: =SUM(G9:G42) -> 50 | H43: =SUM(H9:H42) -> 10000
E44: Total number of fields ploughed | F44: =COUNT(F10:F42) -> 33
D46: Checked By
D47: Signature
D48: Date

Sheet Mcuba
A1: ICBC Ploughing Project
C2: COMPLETE
A3: Name of ICBC: | B3: Mcuba ICBC | E3: Name of Pastor | F3: Johannes Ndwandwe
A4: Contractor's Full Name | B4: Vusumuzi Mhlanga | E4: Contractor's ID Number | F4: 8007226100235
A5: Bank | B5: Nedbank | E5: Account Holder's Name | F5: July Vusumuzi Mhlanga
A6: Branch Code | E6: Account Number | F6: 12990364255
A9: Community Member’s Name & Surname | B9: Contact Details | C9: Date | D9: Start Time (Date & Time) | E9: Completion time (Date & Time) | F9: Number of Hours | G9: Actual Number of Hours | H9: Amount | I9: Location
A10: Make LaZika | C10: 44968 | F10: 2 | G10: 2 | H10: =G10*200 -> 400
A11: Makwa Sizolwethu | C11: 44968 | F11: 1 | G11: 1 | H11: =G11*200 -> 200
A12: Makwa Sisi | C12: 44968 | F12: 1 | G12: 1 | H12: =G12*200 -> 200
A13: LaTfwala | C13: 44968 | F13: 1 | G13: 1 | H13: =G13*200 -> 200
A14: Bhoyi | C14: 44968 | F14: 1 | G14: 1 | H14: =G14*200 -> 200
A15: Landzimandze | C15: 44968 | F15: 1 | G15: 1 | H15: =G15*200 -> 200
A16: Nigros | C16: 44996 | F16: 1 | G16: 1 | H16: =G16*200 -> 200
A17: Make LaBhembhe | C17: 44996 | F17: 1 | G17: 1 | H17: =G17*200 -> 200
A18: Make LaMasuku | C18: 15/11/23 | F18: 1 | G18: 1 | H18: =G18*200 -> 200
A19: Make LaMatsaba | C19: 44996 | F19: 1 | G19: 1 | H19: =G19*200 -> 200
A20: Erick Tsabedze | C20: 44996 | F20: 1 | G20: 1 | H20: =G20*200 -> 200
A21: Nabo Gcinaphi | C21: 44996 | F21: 1 | G21: 1 | H21: =G21*200 -> 200
A22: Simphiwe Tsabedze | C22: 44996 | F22: 1 | G22: 1 | H22: =G22*200 -> 200
A23: Giny Shongwe | C23: 45027 | F23: 1 | G23: 1 | H23: =G23*200 -> 200
A24: Make LaNdzimandze | C24: 45027 | F24: 1 | G24: 1 | H24: =G24*200 -> 200
A25: Mahamba Kancane | C25: 45027 | F25: 1 | G25: 1 | H25: =G25*200 -> 200
A26: Sizakele | C26: 45027 | F26: 1 | G26: 1 | H26: =G26*200 -> 200
A27: Makwa Lethu | C27: 45027 | F27: 1 | G27: 1 | H27: =G27*200 -> 200
A28: Makwa Melusi | C28: 45057 | F28: 2 | G28: 2 | H28: =G28*200 -> 400
A29: Juu Shabangu | C29: 45057 | F29: 1 | G29: 1 | H29: =G29*200 -> 200
A30: Mlungisi Kunene | C30: 45057 | F30: 1 | G30: 1 | H30: =G30*200 -> 200
... A37: Gogo Mdluli | C37: 45088 | F37: 1 | G37: 1 | H37: =G37*200 -> 200
A38: MaChawe Kunene | C38: 14/11/23 | F38: 1 | G38: 1 | H38: =G38*200 -> 200
A39: Makwa MdaMara | C39: 14/11/23 | F39: 1 | G39: 1 | H39: =G39*200 -> 200
A40: LaMaphanga | C40: 45118 | F40: 1 | G40: 1 | H40: =G40*200 -> 200
A41: Makwa Sibonelo | C41: 45118 | F41: 2 | G41: 2 | H41: =G41*200 -> 400
A42: Makwa Dudla | C42: 45118 | F42: 1 | G42: 1 | H42: =G42*200 -> 200
A43: LaMavuso | C43: 45118 | F43: 1 | G43: 1 | H43: =G43*200 -> 200
A44: Makwa Mthokwane | C44: 45118 | F44: 1 | G44: 1 | H44: =G44*200 -> 200
A45: Makwa Mthokwane | C45: 45149 | F45: 1 | G45: 1 | H45: =G45*200 -> 200
A46: Fanono Shongwe | C46: 45149 | F46: 1 | G46: 1 | H46: =G46*200 -> 200
A47: Mbhekeleni Matsebula | C47: 45149 | F47: 1 | G47: 1 | H47: =G47*200 -> 200
A48: Mlungisi Matsebula | C48: 45149 | F48: 1 | G48: 1 | H48: =G48*200 -> 200
...

Sheet Mlindazwe
A1: ICBC Ploughing Project
C2: COMPLETE
A3: Name of ICBC: | B3: Mlindazwe ICBC | E3: Name of Pastor | F3: Phendulile Mlangeni
A4: Contractor's Full Name | B4: Sakhile Mabuza | E4: Contractor's ID Number | F4: 9008216100135
A5: Bank | B5: First National Bank | E5: Account Holder's Name | F5: Sakhile Mabuza
A6: Branch Code | E6: Account Number | F6: Ewallet: 76576977
A9: Community Member’s Name & Surname | B9: Contact Details | C9: Date | D9: Start Time (Date & Time) | E9: Completion time (Date & Time) | F9: Number of Hours | G9: Actual Number of Hours | H9: Amount | I9: Location
A10: Church Field | B10: 76111660 | C10: 18.10.23 | D10: 1600hrs | E10: 1700hrs | F10: 1 | G10: 1 | H10: =200*G10 -> 200 | I10: 26°29'26.1"S 30°53'29.5"E
A11: Dolane Masuku-Dlamini | B11: No cellphone | C11: 19.10.23 | D11: 0838hrs | E11: 1038hrs | F11: 2 | G11: 2 | H11: =200*G11 -> 400 | I11: 26°29'23.1"S 30°52'14.1"E
A12: Umphakatsi | B12: 76518850 | C12: 19.10.23 | D12: 1142hrs | E12: 1242hrs | F12: 1 | G12: 1 | H12: =200*G12 -> 200 | I12: 26°29'08.2"S 30°53'00.9"E
A13: Zwane Lucky esitolo | B13: No cellphone | C13: 20.10.23 | D13: 0616hrs | E13: 0818hrs | F13: 2 | G13: 2 | H13: =200*G13 -> 400 | I13: 26°29'02.8"S 30°53'45.9"E
A14: Zwane Thobisani | B14: 76179671 | C14: 20.10.23 | D14: 1040hrs | E14: 1140hrs | F14: 1 | G14: 1 | H14: =200*G14 -> 200 | I14: 26°29'55.1"S 30°53'04.7"E
A15: Masuku Ndoda | B15: 76549107 | C15: 20.10.23 | D15: 1256hrs | E15: 1556hrs | F15: 3 | G15: 3 | H15: =200*G15 -> 600 | I15: 26°28'54.0"S 30°53'42.0"E
A16: LaNkhosi kaZwane | B16: 76276078 | C16: 20.10.23 | D16: 1650hrs | E16: 1750hrs | F16: 1 | G16: 1 | H16: =200*G16 -> 200 | I16: 26°29'02.4"S 30°53'48.2"E
A17: Zwane Mgcobela | B17: 78315049 | C17: 21.10.23 | D17: 0926hrs | E17: 1126hrs | F17: 2 | G17: 2 | H17: =200*G17 -> 400 | I17: 26°29'35.6"S 31°01'00.4"E
A18: Zwane Mphumulo | B18: 76663848 | C18: 21.10.23 | D18: 1230hrs | E18: 1530hrs | F18: 3 | G18: 3 | H18: =200*G18 -> 600 | I18: 26°29'02.9"S 30°53'52.4"E
A19: Makhubu Nelly | B19: 76535056 | C19: 21.10.23 | D19: 1650hrs | E19: 1950hrs | F19: 3 | G19: 3 | H19: =200*G19 -> 600
A20: LaMndzebele Ka Zwane | B20: 76516372 | C20: 23.10.23 | D20: 1310hrs | E20: 0931hrs | F20: 2 | G20: 2 | H20: =200*G20 -> 400
A21: Gogo Makhubu | B21: 78663241 | C21: 23.10.23 | D21: 0957hrs | E21: 1057hrs | F21: 1 | G21: 1 | H21: =200*G21 -> 200
A22: Gogo Phakathi | B22: 76179671 | C22: 23.10.23 | D22: 1200hrs | E22: 1300hrs | F22: 1 | G22: 1 | H22: =200*G22 -> 200
A23: Seyama Mfanzile | B23: 76179671 | C23: 23.10.23 | D23: 1330hrs | E23: 1530hrs | F23: 2 | G23: 2 | H23: =200*G23 -> 400
A24: Lokotfwako Khalebusuku | B24: 76616821 | C24: 01.11.23 | D24: 0940hrs | E24: 1040hrs | F24: 1 | G24: 1 | H24: =200*G24 -> 200
A25: Lokotfwako Lomathemba | B25: 76524972 | C25: 01.11.23 | D25: 1106hrs | E25: 1206hrs | F25: 1 | G25: 1 | H25: =200*G25 -> 200
A26: Lokotfwako Khabo Sibahle | B26: 76524972 | C26: 01.01.23 | D26: 1211hrs | E26: 1311hrs | F26: 1 | G26: 1 | H26: =200*G26 -> 200
A27: Nkhambule Majority | B27: No cellphone | C27: 01.11.23 | D27: 1334hrs | E27: 1434hrs | F27: 1 | G27: 1 | H27: =200*G27 -> 200
A28: Shabangu Lucky | B28: 76774470 | C28: 01.11.23 | D28: 1450hrs | E28: 1550hrs | F28: 1 | G28: 1 | H28: =200*G28 -> 200
A29: Shabangu KhaboLucky | B29: No cellphone | C29: 01.11.23 | D29: 1559hrs | E29: 1659hrs | F29: 1 | G29: 1 | H29: =200*G29 -> 200
A30: Zodwa Mahlaba | B30: 76634524 | C30: 01.11.23 | D30: 1704hrs | E30: 1804hrs | F30: 1 | G30: 1 | H30: =200*G30 -> 200
A31: Nkhambule Majority | B31: No cellphone | C31: 01.01.23 | D31: 1820hrs | E31: 1920hrs | F31: 1 | G31: 1 | H31: =200*G31 -> 200
A32: Make Makhanya ka Sacolo | B32: No cellphone | C32: 02.11.23 | D32: 0835hrs | E32: 1035hrs | F32: 2 | G32: 2 | H32: =200*G32 -> 400
A33: Mr Magutjwa | B33: 76403785 | C33: 02.11.23 | D33: 1336hrs | E33: 1337hrs | F33: 1 | G33: 1 | H33: =200*G33 -> 200
A34: Gogo Seyama | B34: No cellphone | C34: 02.11.23 | D34: 1326hrs | E34: 1526hrs | F34: 2 | G34: 2 | H34: =200*G34 -> 400
A35: Peggy Ngwenya | B35: 76232017 | C35: 03.11.23 | D35: 0900hrs | E35: 1100hrs | F35: 2 | G35: 2 | H35: =200*G35 -> 400
A36: Mr Dladla | B36: No cellphone | C36: 04.11.23 | D36: 1040hrs | E36: 1140hrs | F36: 1 | G36: 1 | H36: =200*G36 -> 200
A37: Zwane Gogo Dludlu | B37: 76314337 | C37: 06.11.23 | D37: 0800hrs | E37: 1000hrs | F37: 2 | G37: 2 | H37: =200*G37 -> 400
A38: Zwane LaMkhonta | B38: 76065685 | C38: 09.11.23 | D38: 1030hrs | E38: 1330hrs | F38: 3 | G38: 3 | H38: =200*G38 -> 600
A39: Gogo Zwane kaNgwenya | B39: No cellphone | C39: 10.11.23 | D39: 0825hrs | E39: 0925hrs | F39: 2 | G39: 2 | H39: =200*G39 -> 400
A40: KaDlamini KhaboMumcy | B40: 76264709 | C40: 15.11.23 | D40: 1100hrs | E40: 1200hrs | F40: 2 | G40: 2 | H40: =200*G40 -> 400
E41: Total | F41: =SUM(F10:F40) -> 50 | G41: =SUM(G10:G40) -> 50 | H41: =SUM(H10:H40) -> 10000
E42: Total number of fields ploughed | F42: =COUNT(G10:G40) -> 31
...

Sheet Mhlangatane
A1: ICBC Ploughing Project
C2: COMPLETE
A3: Name of ICBC: | B3: Mhlangatane ICBC | E3: Name of Pastor | F3: Nhlanhla Tfwala
A4: Contractor's Full Name | B4: Sincengile Dlamini | E4: Contractor's ID Number | F4: 8612041100482
A5: Bank | B5: Standard Bank | E5: Account Holder's Name | F5: Sincengile Dlamini
A6: Branch Code | E6: Account Number | F6: 9110000140891
A9: Community Member’s Name & Surname | B9: Contact Details | C9: Date | D9: Start Time (Date & Time) | E9: Completion time (Date & Time) | F9: Number of Hours | G9: Actual Number of Hours | H9: Amount | I9: Location
A10: Make Sibongile Makhabane | B10: 78152660 | C10: 44968 | F10: 1 | G10: 1 | H10: =G9:G10*200 -> 200 | I10: 25°51'19.1"S 31°35'55.8"E
A11: Bhaleni Makhabane | B11: 78344967 | C11: 44968 | F11: 1 | G11: 1 | H11: =G10:G11*200 -> 200 | I11: 25°51'19.1"S 31°35'55.8"E
A12: Make Thembi Makhabane | B12: 76729484 | C12: 45027 | D12: 0.34236111 | E12: 0.38402778 | F12: 1 | G12: 1 | H12: =G11:G12*200 -> 200 | I12: 25°51'35.1"S 31°34'50.5"E
A13: Babe Lusongo Magagula | B13: 76790342 | C13: 45027 | D13: 0.40138889 | E13: 0.44305556 | F13: 1 | G13: 1 | H13: =G12:G13*200 -> 200 | I13: 25°51'35.1"S 31°34'50.5"E
A14: Babe Sibhayane | B14: 76514828 | C14: 45027 | D14: 0.475 | E14: 0.016666667 | F14: 1 | G14: 1 | H14: =G13:G14*200 -> 200 | I14: 25°51'35.1"S 31°34'50.5"E
A15: Babe Bhekithemba Sibule | B15: 76510522 | C15: 45027 | D15: 0.52569444 | E15: 0.56736111 | F15: 1 | G15: 1 | H15: =G14:G15*200 -> 200 | I15: 26°01'00.1"S 31°32'44.7"E
A16: Babe Lusentfo Sibule | B16: 76676653 | C16: 45027 | D16: 0.60694444 | E16: 0.64861111 | F16: 1 | G16: 1 | H16: =G15:G16*200 -> 200 | I16: 26°01'29.2"S 31°37'56.7"E
A17: Babe Ngisane Makhabane | B17: 76142997 | C17: 45027 | D17: 0.66805556 | E17: 0.70972222 | F17: 1 | G17: 1 | H17: =G16:G17*200 -> 200 | I17: 25°51'35.1"S 31°34'50.5"E
A18: Bongiwe Gumedze | B18: 7842686 | C18: 45027 | D18: 0.72013889 | E18: 0.76180556 | F18: 1 | G18: 1 | H18: =G17:G18*200 -> 200 | I18: 25°51'35.1"S 31°34'50.5"E
A19: Sithembiso Ndwandwa | B19: 76691064 | C19: 45118 | D19: 0.27361111 | E19: 0.31527778 | F19: 1 | G19: 1 | H19: =G18:G19*200 -> 200 | I19: 26°01'00.1"S 31°32'44.7"E
A20: Sibusiso Ntjalintjali | B20: 78609381 | C20: 45118 | D20: 0.32708333 | E20: 0.36875 | F20: 1 | G20: 1 | H20: =G19:G20*200 -> 200 | I20: 25°52'03.5"S 31°34'36.4"E
A21: Make Magagula (LaTsabedze) | B21: 76862063 | C21: 45118 | D21: 0.40277778 | E21: 0.48611111 | F21: 2 | G21: 2 | H21: =G20:G21*200 -> 400 | I21: 25°52'43.0"S 31°34'15.9"E
A22: Gogo Sehlephi Magagula | B22: 76232912 | C22: 45118 | D22: 0.48680556 | E22: 0.57013889 | F22: 2 | G22: 2 | H22: =G21:G22*200 -> 400 | I22: 25°52'43.0"S 31°34'15.9"E
A23: Make Magagula | B23: 76859834 | C23: 45118 | D23: 0.57430556 | E23: 0.61597222 | F23: 1 | G23: 1 | H23: =G22:G23*200 -> 200 | I23: 25°48'54.2"S 31°24'51.3"E
... A33: Make Zodwa Gumedze | B33: 76698998 | C33: 45180 | D33: 0.27083333 | E33: 0.32291667 | F33: 1 | G33: 1 | H33: =G32:G33*200 -> 200 | I33: 25°51'11.2"S 31°33'56.6"E
A34: Make Cinisile Magagula | B34: 76288370 | C34: 45210 | D34: 0.35277778 | E34: 0.39444444 | F34: 1 | G34: 1 | H34: =G24:G34*200 -> 200 | I34: 25°51'11.2"S 31°33'56.6"E
A35: Make Siphiwe Kunene | B35: 78058315 | C35: 45210 | D35: 0.39097222 | E35: 0.43263889 | F35: 1 | G35: 1 | H35: =G35*200 -> 200 | I35: 25°51'11.2"S 31°33'56.6"E
A36: Make Nonhlanla Sigudla | B36: 76375418 | C36: 45210 | D36: 0.43888889 | E36: 0.48055556 | F36: 1 | G36: 1 | H36: =G33:G36*200 -> 200 | I36: 25°51'35.1"S 31°34'50.5"E
A37: Babe Dumisa Ndzimandze | B37: 76305235 | C37: 45210 | D37: 0.48333333 | E37: 0.525 | F37: 1 | G37: 1 | H37: =G37*200 -> 200 | I37: 25°51'35.1"S 31°34'50.5"E
A38: Make Khulile Genge | B38: 76319724 | C38: 45210 | D38: 0.52222222 | E38: 0.56388889 | F38: 1 | G38: 1 | H38: =G37:G38*200 -> 200 | I38: 25°51'35.1"S 31°34'50.5"E
A39: Make Delisile Ndzinisa | B39: 78438788 | C39: 15/11/23 | D39: 0.26111111 | E39: 0.30277778 | F39: 1 | G39: 1 | H39: =G38:G39*200 -> 200 | I39: 25°51'35.1"S 31°34'50.5"E
A40: Make Phumzile Manana | B40: 76657937 | C40: 15/11/23 | D40: 0.30902778 | E40: 0.35069444 | F40: 1 | G40: 1 | H40: =G39:G40*200 -> 200 | I40: 25°51'35.1"S 31°34'50.5"E
A41: Babe Ndukwane Matsaba | B41: 76766857 | C41: 15/11/23 | D41: 0.34583333 | E41: 0.3875 | F41: 1 | G41: 1 | H41: =G40:G41*200 -> 200 | I41: 25°51'35.1"S 31°34'50.5"E
A42: Babe Mpumelelo Mlambo | B42: 76555761 | C42: 15/11/23 | D42: 0.37638889 | E42: 0.41805556 | F42: 1 | G42: 1 | H42: =G41:G42*200 -> 200 | I42: 25°50'59.8"S 31°34'09.4"E
A43: Make Miriam Masuku | B43: 76963176 | C43: 15/11/23 | D43: 0.42013889 | E43: 0.46180556 | F43: 1 | G43: 1 | H43: =G42:G43*200 -> 200 | I43: 25°52'02.6"S 31°34'35.1"E
A44: Make Zodwa Dlamini | B44: 76967881 | C44: 15/11/23 | D44: 0.44444444 | E44: 0.48611111 | F44: 1 | G44: 1 | H44: =G43:G44*200 -> 200 | I44: 25°52'02.6"S 31°34'35.1"E
A45: Make Dumsile Mahlalela | B45: 76047714 | C45: 15/11/23 | D45: 0.47361111 | E45: 0.51527778 | F45: 1 | G45: 1 | H45: =G44:G45*200 -> 200 | I45: 25°52'49.0"S 31°34'15.9"E
A46: Babe Sidumo Luhlanga | B46: 76321604 | C46: 15/11/23 | D46: 0.62152778 | E46: 0.66319444 | F46: 1 | G46: 1 | H46: =G45:G46*200 -> 200 | I46: 25°52'02.6"S 31°34'35.1"E
A47: Make Lindiwe Mahlalela | B47: 76156728 | C47: 15/11/23 | D47: 0.60833333 | E47: 0.65 | F47: 1 | G47: 1 | H47: =G46:G47*200 -> 200 | I47: 25°52'02.6"S 31°34'35.1"E
A48: Gogo Phatsane Shongwe | B48: 78282326 | C48: 15/11/23 | D48: 0.64097222 | E48: 0.68263889 | F48: 1 | G48: 1 | H48: =G47:G48*200 -> 200 | I48: 25°52'02.6"S 31°34'35.1"E
A49: Babe Samson Solombo | B49: No Cellphone | C49: 15/11/23 | D49: 0.67708333 | E49: 0.76041667 | F49: 2 | G49: 2 | H49: =G48:G49*200 -> 400 | I49: 25°51'59.2"S 31°34'49.2"E
A50: Make Nelisiwe Methula | B50: 76159436 | C50: 15/11/23 | D50: 0.74305556 | E50: 0.78472222 | F50: 1 | G50: 1 | H50: =G49:G50*200 -> 200 | I50: 25°52'02.6"S 31°34'35.1"E
A51: Make Nelisiwe Methula | B51: 76159436 | C51: 15/11/23 | D51: 0.74305556 | E51: 0.78472222 | F51: 1 | G51: 1 | H51: =G50:G51*200 -> 200 | I51: 25°52'02.6"S 31°34'35.1"E
...

Sheet Mpuluzi
A1: ICBC Ploughing Project
C2: COMPLETE
A3: Name of ICBC: | B3: Mpuluzi ICBC | E3: Name of Pastor | F3: Sibusiso Ndlangamandla
A4: Contractor's Full Name | B4: Sum Investments PTY LTD | E4: Contractor's ID Number | F4: 5610116100224
A5: Bank | B5: First National Bank | E5: Account Holder's Name | F5: ONE BOY ZIKALALA
A6: Branch Code | E6: Account Number | F6: 62103866961
A9: Community Member’s Name & Surname | B9: Contact Details | C9: Date | D9: Start Time (Date & Time) | E9: Completion time (Date & Time) | F9: Number of Hours | G9: Actual Number of Hours | H9: Amount | I9: Location
A10: Mr Jan Dube | B10: 76435389 | C10: 14/11/23 | D10: 0.45833333 | E10: 16:00PM | F10: 5 | G10: 5 | H10: =G10*200 -> 1000
A11: Gogo Simelane | B11: 76702399 | C11: 15/11/23 | D11: 0.25 | E11: 0.29166667 | F11: 1 | G11: 1 | H11: =G11*200 -> 200
A12: Make Dlamini laMkhonta | B12: 76524575 | C12: 15/11/23 | F12: 2 | G12: 2 | H12: =G12*200 -> 400
A13: Make Zwane laSimelane | B13: 76849658 | C13: 15/11/23 | F13: 1 | G13: 1 | H13: =G13*200 -> 200
A14: Make Nhlengetfwa | B14: 76040651 | C14: 15/11/23 | F14: 1 | G14: 1 | H14: =G14*200 -> 200
A15: Make Magongo | B15: 76642263 | C15: 15/11/23 | F15: 2 | G15: 2 | H15: =G15*200 -> 400
A16: Babe Mkhonta | B16: 78500225 | C16: 15/11/23 | F16: 3 | G16: 3 | H16: =G16*200 -> 600
A17: Make Zwane | B17: 76360778 | C17: 15/11/23 | F17: 2 | G17: 2 | H17: =G17*200 -> 400
A18: Babe Mnisi | B18: 76360778 | C18: 16/11/23 | F18: 2 | G18: 2 | H18: =G18*200 -> 400
A19: Make Dlamini | B19: 76507787 | C19: 16/11/23 | F19: 3 | G19: 3 | H19: =G19*200 -> 600
A20: Make Dludlu | B20: 76719593 | C20: 16/11/23 | F20: 6 | G20: 6 | H20: =G20*200 -> 1200
A21: Babe Dlamini | B21: 76947301 | C21: 16/11/23 | F21: 2 | G21: 2 | H21: =G21*200 -> 400
A22: Babe Nhlengetfwa | B22: 76680025 | C22: 16/11/23 | F22: 1 | G22: 1 | H22: =G22*200 -> 200
A23: Make Dlamini | B23: 78266833 | C23: 17/11/23 | F23: 2 | G23: 2 | H23: =G23*200 -> 400
... A32: Babe Mhlongo | B32: 76064208 | C32: 23/11/23 | F32: 1 | G32: 1 | H32: =G32*200 -> 200
A33: Babe Maseko | C33: 23/11/23 | F33: 1 | G33: 1 | H33: =G33*200 -> 200
E34: Total | F34: =SUM(F9:F33) -> 50 | G34: =SUM(G1:G33) -> 50 | H34: =SUM(H9:H33) -> 10000
E35: Total number of fields ploughed | F35: =COUNT(F10:F33) -> 24
D37: Checked By
D38: Signature
D39: Date

Sheet Msahweni
A1: ICBC Ploughing Project
C2: COMPLETE
A3: Name of ICBC: | B3: Msahweni ICBC | E3: Name of Pastor | F3: Themba Shabangu
A4: Contractor's Full Name | B4: Thulani Fakudze | E4: Contractor's ID Number | F4: 7012256101369
A5: Bank | B5: Standard Bank | E5: Account Holder's Name | F5: Thulani Fakudze
A6: Branch Code | E6: Account Number | F6: 9110005355063
A9: Community Member’s Name & Surname | B9: Contact Details | C9: Date | D9: Start Time (Date & Time) | E9: Completion time (Date & Time) | F9: Number of Hours | G9: Actual Number of Hours | H9: Amount | I9: Location
A10: CHC mission field | B10: 78673636 | C10: 45088 | D10: 0.29166667 | E10: 0.33402778 | F10: 1 | G10: 1 | H10: =G10*200 -> 200 | I10: 25°49'57.3"S 31°23'33.7"E
A11: Mrs Gumedze | B11: 76737415 | C11: 45088 | D11: 0.33680556 | E11: 0.37847222 | F11: 1 | G11: 1 | H11: =G11*200 -> 200 | I11: 25°49'57.3"S 31°23'33.7"E
A12: Mbongiseni Tfwala | B12: 78250927 | C12: 45088 | D12: 0.38402778 | E12: 0.42569444 | F12: 1 | G12: 1 | H12: =G12*200 -> 200 | I12: 25°48'54.2"S 31°24'51.3"E
A13: Zwelithini Tfwala | B13: 78039281 | C13: 45088 | D13: 0.71875 | E13: 0.76041667 | F13: 1 | G13: 1 | H13: =G13*200 -> 200
A14: Happy Mavuso | B14: 78538219 | C14: 45088 | D14: 0.79861111 | E14: 0.84027778 | F14: 1 | G14: 1 | H14: =G14*200 -> 200
A15: Make Ndwandwe | B15: 76686676 | C15: 45088 | D15: 0.85416667 | E15: 0.89791667 | F15: 1 | G15: 1 | H15: =G15*200 -> 200
A16: Zakhele Madonsela | B16: 76614196 | C16: 45088 | D16: 0.90972222 | E16: 0.99305556 | F16: 3 | G16: 3 | H16: =G16*200 -> 600 | I16: 25°48'54.5"S 31°24'50.7"E
A17: Mancoba Gwebu | B17: 76073877 | C17: 45118 | D17: 0.97222222 | E17: 0.015972222 | F17: 1 | G17: 1 | H17: =G17*200 -> 200 | I17: 25°48'54.1"S 31°24'51.3"E
A18: Gogo Shongwe | B18: 76811647 | C18: 45118 | D18: 0.45833333 | E18: 0.50069444 | F18: 1 | G18: 1 | H18: =G18*200 -> 200 | I18: 25°48'54.2"S 31°24'51.3"E
A19: Gogo Ndlela | B19: 76600492 | C19: 45118 | D19: 0.50347222 | E19: 0.54513889 | F19: 1 | G19: 1 | H19: =G19*200 -> 200 | I19: 25°48'54.2"S 31°24'51.3"E
A20: Johaness Dzimba | B20: 76263751 | C20: 45118 | D20: 13:25 PM | E20: 14: 30PM | F20: 1 | G20: 1 | H20: =G20*200 -> 200 | I20: 25°48'22.8"S 31°28'31.1"E
A21: Gogo LaFofo | B21: No cellphone | C21: 45118 | D21: 14:50 PM | E21: 15:51 PM | F21: 1 | G21: 1 | H21: =G21*200 -> 200 | I21: 25°48'28.9"S 31°28'33.5"E
A22: Mzwandile Kunene | B22: 76274237 | C22: 45118 | D22: 19:40 PM | E22: 20:50 PM | F22: 1 | G22: 1 | H22: =G22*200 -> 200 | I22: 25°50'26.8"S 31°23'38.2"E
A23: Make Malambe | B23: 76834985 | C23: 45149 | D23: 0.23958333 | E23: 0.28263889 | F23: 1 | G23: 1 | H23: =G23*200 -> 200 | I23: 25°48'33.1"S 31°28'33.3"E
A24: Make Kunene | B24: 76739195 | C24: 45149 | D24: 0.41666667 | E24: 0.45833333 | F24: 1 | G24: 1 | H24: =G24*200 -> 200 | I24: 25°48'33.0"S 31°28'33.3"E
A25: Wandile Mdluli | B25: 76407809 | C25: 45149 | D25: 0.52083333 | E25: 0.5625 | F25: 1 | G25: 1 | H25: =G25*200 -> 200 | I25: 25°49'53.8"S 31°23'35.3"E
A26: Mandla Mdluli | B26: 76278557 | C26: 45149 | D26: 0.59722222 | E26: 0.63888889 | F26: 1 | G26: 1 | H26: =G26*200 -> 200 | I26: 25°49'53.8"S 31°23'35.3"E
A27: Joseph Dube | B27: 76118820 | C27: 45149 | D27: 0.74652778 | E27: 0.78819444 | F27: 1 | G27: 1 | H27: =G27*200 -> 200 | I27: 25°49'36.4"S 31°23'44.9"E
A28: Gogo Khelina | B28: 78475928 | C28: 45149 | D28: 0.79513889 | E28: 0.83680556 | F28: 1 | G28: 1 | H28: =G28*200 -> 200 | I28: 25°49'36.4"S 31°23'44.9"E
A29: Gogo Gwadze | B29: 76725577 | C29: 45149 | D29: 0.86805556 | E29: 0.90972222 | F29: 1 | G29: 1 | H29: =G29*200 -> 200 | I29: 25°50'12.4"S 31°23'43.8"E
A30: Gogo Luhlanga | B30: 76361848 | C30: 45180 | D30: 0.22916667 | E30: 0.27083333 | F30: 1 | G30: 1 | H30: =G30*200 -> 200 | I30: 25°48'36.6"S 31°25'27.4"E
A31: Elliot Mamba | B31: 76605964 | C31: 45180 | D31: 0.34722222 | E31: 0.38888889 | F31: 1 | G31: 1 | H31: =G31*200 -> 200 | I31: 25°46'09.2"S 31°35'13.6"E
A32: Joyce Gwebu | B32: 78144908 | C32: 45180 | D32: 0.28472222 | E32: 0.32638889 | F32: 1 | G32: 1 | H32: =G32*200 -> 200 | I32: 25°46'09.2"S 31°35'13.6"E
A33: Simangele Shongwe | B33: 76921927 | C33: 45180 | D33: 0.4375 | E33: 0.47916667 | F33: 1 | G33: 1 | H33: =G33*200 -> 200 | I33: 25°48'54.2"S 31°24'51.3"E
A34: Thandi Dlamini | B34: 78137897 | C34: 45180 | D34: 0.52083333 | E34: 0.5625 | F34: 1 | G34: 1 | H34: =G34*200 -> 200 | I34: 25°50'12.3"S 31°23'43.6"E
