Workbook

Sheet SUMMARIES
A1: 2025 ICBC MAIZE SUSTAINABILITY PROJECT
A2: ICBC SITES | B2: Kilograms(kG) | C2: Tonnes | D2: Amount | E2: Pastor | F2: Pastor's Commission
A3: NGWENYA | B3: =NGWENYA!F18 -> 779.5 | C3: =NGWENYA!G18 -> 0.7795 | D3: =NGWENYA!H18 -> 3897.5 | E3: Mcolisi Dlamini | F3: =NGWENYA!I18 -> 389.75
A4: ZONDWAKO | B4: =ZONDWAKO!F22+ZONDWAKO!F48 -> 11405 | C4: =ZONDWAKO!G48+ZONDWAKO!G22 -> 11.405 | D4: =ZONDWAKO!H24+ZONDWAKO!H50 -> 62727.5 | E4: Jan Dube | F4: =ZONDWAKO!I48+ZONDWAKO!I22 -> 5702.5
A5: SIGOMBENI | B5: =SIGOMBENI!F26 -> 5297.2 | C5: =SIGOMBENI!G26 -> 5.2972 | D5: =SIGOMBENI!H28 -> 29134.6 | E5: Sabelo Molefe | F5: =SIGOMBENI!I26 -> 2648.6
A6: MABHUKWINI | B6: =MABHUKWINI!F20 -> 4108.9 | C6: =MABHUKWINI!G20 -> 4.1089 | D6: =MABHUKWINI!H20 -> 20544.5 | E6: Dumisani Enerst Dlamini | F6: =MABHUKWINI!I30+MABHUKWINI!I20 -> 2223.7
A7: SIGANGENI | B7: =SIGANGENI!F32+SIGANGENI!F48 -> 13209 | C7: =SIGANGENI!G32+SIGANGENI!G48 -> 13.209 | D7: =SIGANGENI!H34+SIGANGENI!H50 -> 71461.5 | E7: Bongani Masombuka | F7: =SIGANGENI!I32+SIGANGENI!I48 -> 6496.5
A11: Total | B11: =SUM(B3:B10) -> 34799.6 | C11: =SUM(C3:C10) -> 34.7996 | D11: =SUM(D3:D10) -> 187765.6

Sheet SIGOMBENI
A1: ICBC MAIZE SUSTAINABILITY PROJECT
H2: COMPLETED
A3: Name of ICBC: | B3: Sigombeni ICBC | E3: Name of Pastor | F3: Sabelo Molefe
A4: Agent's Full Name | B4: Sabelo Molefe | E4: ID Number
A5: Bank | B5: First National Bank | E5: Account Holder's Name | F5: Sabelo Molefe
A6: Branch Code | E6: Account Number | F6: 62415516410
A8: Community Member’s Name & Surname | B8: Contact details | C8: Date | D8: Rate: E/kG | E8: Bags | F8: Kilograms(kG) | G8: Tonnes | H8: Amount | I8: Commission To Pastor
A9: Mlambo Machawe | B9: 76600127 | C9: 45884 | E9: 5 | F9: 187 | G9: =F9*0.001 -> 0.187 | H9: =F9*5 -> 935 | I9: =F9*0.5 -> 93.5
A10: Dlamini Sicelo | B10: 76613841 | C10: 45884 | E10: 4 | F10: 216 | G10: =F10*0.001 -> 0.216 | H10: =F10*5 -> 1080 | I10: =F10*0.5 -> 108
A11: Dlamini Mbhaceka | B11: 76126901 | C11: 45884 | E11: 5 | F11: 191.5 | G11: =F11*0.001 -> 0.1915 | H11: =F11*5 -> 957.5 | I11: =F11*0.5 -> 95.75
A12: Dlamini Sizwe | B12: 76279330 | C12: 45884 | E12: 11 | F12: 578 | G12: =F12*0.001 -> 0.578 | H12: =F12*5 -> 2890 | I12: =F12*0.5 -> 289
A13: Dlamini Salebona | B13: 76323760 | C13: 45884 | E13: 20 | F13: 1353 | G13: =F13*0.001 -> 1.353 | H13: =F13*5 -> 6765 | I13: =F13*0.5 -> 676.5
A14: Simelane Fana | B14: 76329227 | C14: 45884 | E14: 1 | F14: 87 | G14: =F14*0.001 -> 0.087 | H14: =F14*5 -> 435 | I14: =F14*0.5 -> 43.5
A15: Dingane Mtekwa | B15: 76936010 | C15: 45884 | E15: 2 | F15: 128 | G15: =F15*0.001 -> 0.128 | H15: =F15*5 -> 640 | I15: =F15*0.5 -> 64
A16: Zondwa Maseko | B16: 76608964 | C16: 45884 | E16: 4 | F16: 181.5 | G16: =F16*0.001 -> 0.1815 | H16: =F16*5 -> 907.5 | I16: =F16*0.5 -> 90.75
A17: Make Tsabedze | B17: 76600127 | C17: 45884 | E17: 8 | F17: 448 | G17: =F17*0.001 -> 0.448 | H17: =F17*5 -> 2240 | I17: =F17*0.5 -> 224
A18: Busi Jele | B18: 76777751 | C18: 45884 | E18: 8 | F18: 384 | G18: =F18*0.001 -> 0.384 | H18: =F18*5 -> 1920 | I18: =F18*0.5 -> 192
A19: Bonisile Mavuso | B19: 76048734 | C19: 45884 | E19: 10 | F19: 492.5 | G19: =F19*0.001 -> 0.4925 | H19: =F19*5 -> 2462.5 | I19: =F19*0.5 -> 246.25
A20: Delisile Nkwanyane | B20: 78345343 | C20: 45884 | E20: 6 | F20: 370.5 | G20: =F20*0.001 -> 0.3705 | H20: =F20*5 -> 1852.5 | I20: =F20*0.5 -> 185.25
A21: Siphesihle Khumalo | B21: 78701389 | C21: 45884 | E21: 21 | F21: 680.2 | G21: =F21*0.001 -> 0.6802 | H21: =F21*5 -> 3401 | I21: =F21*0.5 -> 340.1
D26: Total | E26: =SUM(E9:E25) -> 105 | F26: =SUM(F9:F25) -> 5297.2 | G26: =SUM(G9:G25) -> 5.2972 | H26: =SUM(H9:H25) -> 26486 | I26: =SUM(I9:I25) -> 2648.6
G28: Total Amount | H28: =H26+I26 -> 29134.6

Sheet NGWENYA
A1: ICBC MAIZE SUSTAINABILITY PROJECT
H2: COMPLETED
A3: Name of ICBC: | B3: Ngwenya ICBC | E3: Name of Pastor | F3: Mcolisi Dlamini
A4: Agent's Full Name | E4: ID Number
A5: Bank | B5: FNB | E5: Account Holder's Name | F5: NGWENYA CHRISTIAN LIFE C
A6: Branch Code | B6: CORPORATE PLACE BRANCH 281264 | E6: Account Number | F6: 63165335811
A8: Community Member’s Name & Surname | B8: Contact details | C8: Date | D8: Rate: E/kG | E8: Bags(20kG ea) | F8: Kilograms(kG) | G8: Tonnes | H8: Amount | I8: Pastors Commission
A9: Jane Hlatshwako | B9: 76450513 | C9: 45894 | E9: 13 | F9: 779.5 | G9: =F9*0.001 -> 0.7795 | H9: =F9*5 -> 3897.5 | I9: =F9*0.5 -> 389.75
G10: =F10*0.001 -> 0 | H10: =F10*5 -> 0 | I10: =H10/5*0.005 -> 0
G11: =F11*0.001 -> 0 | H11: =F11*5 -> 0 | I11: =H11/5*0.005 -> 0
D18: Total | E18: =SUM(E9:E11) -> 13 | F18: =SUM(F9:F11) -> 779.5 | G18: =SUM(G9:G11) -> 0.7795 | H18: =SUM(H9:H11) -> 3897.5 | I18: =SUM(I9:I11) -> 389.75
G20: Total Amount | H20: =H18+I18 -> 4287.25

Sheet ZONDWAKO
A1: ICBC MAIZE SUSTAINABILITY PROJECT
H2: COMPLETED
A3: Name of ICBC: | B3: Zondwako ICBC | E3: Name of Pastor | F3: Jan Dube
A4: Agent's Full Name | E4: ID Number
A5: Bank | B5: FNB | E5: Account Holder's Name | F5: WALK BY FAITH BIBLE MINISTRIES
A6: Branch Code | B6: CORPORATE PLACE BRANCH 281264 | E6: Account Number | F6: 63166073535
A8: Community Member’s Name & Surname | B8: Contact details | C8: Date | D8: Rate: E/kG | E8: Bags(20kG ea) | F8: Kilograms(kG) | G8: Tonnes | H8: Amount | I8: Commission
A9: Sibongile Dlamini | B9: 76600852 | C9: 45897 | E9: 30 | F9: 1567.5 | G9: =F9*0.001 -> 1.5675 | H9: =F9*5 -> 7837.5 | I9: =F9*0.5 -> 783.75
A10: Nkululeko Dlamini | B10: 76557417 | C10: 45897 | E10: 2 | F10: 76.5 | G10: =F10*0.001 -> 0.0765 | H10: =F10*5 -> 382.5 | I10: =F10*0.5 -> 38.25
A11: Siphesihle Dlamini | B11: 76911326 | C11: 45897 | E11: 3 | F11: 134.5 | G11: =F11*0.001 -> 0.1345 | H11: =F11*5 -> 672.5 | I11: =F11*0.5 -> 67.25
A12: Siwela Dlamini | B12: 76185935 | C12: 45897 | E12: 2 | F12: 97 | G12: =F12*0.001 -> 0.097 | H12: =F12*5 -> 485 | I12: =F12*0.5 -> 48.5
A13: Jan Dube | B13: 76435589 | C13: 45897 | E13: 152 | F13: 557.5 | G13: =F13*0.001 -> 0.5575 | H13: =F13*5 -> 2787.5 | I13: =F13*0.5 -> 278.75
A14: Sibusiso Msibi | B14: 76882058 | C14: 45897 | E14: 4 | F14: 184 | G14: =F14*0.001 -> 0.184 | H14: =F14*5 -> 920 | I14: =F14*0.5 -> 92
A15: Thokozani Dlamini | B15: 76180917 | C15: 45897 | E15: 13 | F15: 954 | G15: =F15*0.001 -> 0.954 | H15: =F15*5 -> 4770 | I15: =F15*0.5 -> 477
A16: Trypinah Khumalo | B16: 76350206 | C16: 45897 | E16: 40 | F16: 2450 | G16: =F16*0.001 -> 2.45 | H16: =F16*5 -> 12250 | I16: =F16*0.5 -> 1225
A17: Leonard Mdluli | B17: 76991227 | C17: 45897 | E17: 20 | F17: 1229 | G17: =F17*0.001 -> 1.229 | H17: =F17*5 -> 6145 | I17: =F17*0.5 -> 614.5
A18: Lungile Ntshangase | B18: 76583989 | C18: 45897 | E18: 10 | F18: 607.5 | G18: =F18*0.001 -> 0.6075 | H18: =F18*5 -> 3037.5 | I18: =F18*0.5 -> 303.75
A19: Hloniphile Zwane | B19: 76360462 | C19: 45897 | E19: 8 | F19: 570.5 | G19: =F19*0.001 -> 0.5705 | H19: =F19*5 -> 2852.5 | I19: =F19*0.5 -> 285.25
D22: Total | E22: =SUM(E9:E19) -> 284 | F22: =SUM(F9:F19) -> 8428 | G22: =SUM(G9:G19) -> 8.428 | H22: =SUM(H9:H19) -> 42140 | I22: =SUM(I9:I19) -> 4214
G24: Total Amount | H24: =H22+I22 -> 46354
A25: ICBC MAIZE SUSTAINABILITY PROJECT
H26: COMPLETED
A27: Name of ICBC: | B27: Zondwako ICBC | E27: Name of Pastor | F27: Jan Dube
A28: Agent's Full Name | B28: Jan Dube | E28: ID Number
A29: Bank | B29: FNB | E29: Account Holder's Name | F29: WALK BY FAITH BIBLE MINISTRIES
A30: Branch Code | B30: CORPORATE PLACE BRANCH 281264 | E30: Account Number | F30: 63166073535
A32: Community Member’s Name & Surname | B32: Contact details | C32: Date | D32: Rate: E/kG | E32: Bags(20kG ea) | F32: Kilograms(kG) | G32: Tonnes | H32: Amount | I32: Pastor's Commission
A33: Minenhle Bhembe | B33: 76459955 | C33: 45959 | D33: 5 | F33: 333 | G33: =F33*0.001 -> 0.333 | H33: =F33*5 -> 1665 | I33: =F33*0.5 -> 166.5
A34: Zodwa Nkambule | B34: 76970198 | C34: 45959 | D34: 5 | F34: 80 | G34: =F34*0.001 -> 0.08 | H34: =F34*5 -> 400 | I34: =F34*0.5 -> 40
A35: Hloniphile Khumalo | B35: 76245737 | C35: 45959 | D35: 5 | F35: 256.5 | G35: =F35*0.001 -> 0.2565 | H35: =F35*5 -> 1282.5 | I35: =F35*0.5 -> 128.25
A36: Aron Shabangu | B36: 76766464 | C36: 45959 | D36: 5 | F36: 83.5 | G36: =F36*0.001 -> 0.0835 | H36: =F36*5 -> 417.5 | I36: =F36*0.5 -> 41.75
A37: Lindiwe Shabangu | B37: 76326615 | C37: 45959 | D37: 5 | F37: 88 | G37: =F37*0.001 -> 0.088 | H37: =F37*5 -> 440 | I37: =F37*0.5 -> 44
A38: Wawa Dlamini | B38: 76112198 | C38: 45959 | D38: 5 | F38: 42 | G38: =F38*0.001 -> 0.042 | H38: =F38*5 -> 210 | I38: =F38*0.5 -> 21
A39: Ntombikayise Gogo Mtsetfwa | B39: 76878407 | C39: 45959 | D39: 5 | F39: =105+40 -> 145 | G39: =F39*0.001 -> 0.145 | H39: =F39*5 -> 725 | I39: =F39*0.5 -> 72.5
A40: Simon Dlamini | B40: 76653897/76552363 | C40: 45959 | D40: 5 | F40: 265 | G40: =F40*0.001 -> 0.265 | H40: =F40*5 -> 1325 | I40: =F40*0.5 -> 132.5
A41: Kwanele Makhanya | B41: 76296744 | C41: 45959 | D41: 5 | F41: 270 | G41: =F41*0.001 -> 0.27 | H41: =F41*5 -> 1350 | I41: =F41*0.5 -> 135
A42: Christina Makhanya | B42: 76544000 | C42: 45959 | D42: 5 | F42: 294 | G42: =F42*0.001 -> 0.294 | H42: =F42*5 -> 1470 | I42: =F42*0.5 -> 147
A43: Nontsetselelo Nhlabatsi | B43: 7688406 | C43: 45959 | D43: 5 | F43: 200 | G43: =F43*0.001 -> 0.2 | H43: =F43*5 -> 1000 | I43: =F43*0.5 -> 100
A44: Khabonina Bhembe | B44: 76544947 | C44: 45959 | D44: 5 | F44: 540 | G44: =F44*0.001 -> 0.54 | H44: =F44*5 -> 2700 | I44: =F44*0.5 -> 270
A45: Zodwa Dlamini | B45: 76376171 | C45: 45959 | D45: 5 | F45: 200 | G45: =F45*0.001 -> 0.2 | H45: =F45*5 -> 1000 | I45: =F45*0.5 -> 100
...

Sheet SIGANGENI
A1: ICBC MAIZE BUYBACK PROJECT
H2: COMPLETED
A3: Name of ICBC: | B3: SIGANGENI ICBC | E3: Name of Pastor | F3: BONGANI MASOMBUKA
A4: Agent's Full Name | E4: ID Number
A5: Bank | B5: FNB | E5: Account Holder's Name | F5: WALK BY FAITH BIBLE MINISTRIES
A6: Branch Code | B6: CORPORATE PLACE BRANCH 281264 | E6: Account Number | F6: 63166073535
A8: Community Member’s Name & Surname | B8: Contact details | C8: Date | D8: Rate: E/kG | E8: Bags(20kG ea) | F8: Kilograms(kG) | G8: Tonnes | H8: Amount | I8: Pastor'sCommission
A9: Bonginkosi Dlamini | B9: 76178004 | C9: 29.08.25 | E9: 24 | F9: 1447 | G9: =F9*0.001 -> 1.447 | H9: =F9*5 -> 7235 | I9: =F9*0.5 -> 723.5
A10: Betty Tsabedze | B10: 76608974 | C10: 29.08.25 | E10: 22 | F10: 1431.5 | G10: =F10*0.001 -> 1.4315 | H10: =F10*5 -> 7157.5 | I10: =F10*0.5 -> 715.75
A11: Make Bhembe | B11: 76415917 | C11: 29.08.25 | E11: 5 | F11: 315 | G11: =F11*0.001 -> 0.315 | H11: =F11*5 -> 1575 | I11: =F11*0.5 -> 157.5
A12: Joyce Shongwe | B12: 76622874 | C12: 29.08.25 | E12: 4 | F12: 169 | G12: =F12*0.001 -> 0.169 | H12: =F12*5 -> 845 | I12: =F12*0.5 -> 84.5
A13: Sibongile Shongwe | B13: 76588605 | C13: 29.08.25 | E13: 8 | F13: 505 | G13: =F13*0.001 -> 0.505 | H13: =F13*5 -> 2525 | I13: =F13*0.5 -> 252.5
A14: Calvin Shongwe | B14: 76223389 | C14: 29.08.25 | E14: 5 | F14: 223 | G14: =F14*0.001 -> 0.223 | H14: =F14*5 -> 1115 | I14: =F14*0.5 -> 111.5
A15: Samkelo Mazibuko | B15: 76899443 | C15: 29.08.25 | E15: 7 | F15: 419 | G15: =F15*0.001 -> 0.419 | H15: =F15*5 -> 2095 | I15: =F15*0.5 -> 209.5
A16: Nkosinamandla Shongwe | B16: 76686198 | C16: 29.08.25 | E16: 11 | F16: 617 | G16: =F16*0.001 -> 0.617 | H16: =F16*5 -> 3085 | I16: =F16*0.5 -> 308.5
A17: Phelile Mamba | B17: 76393926 | C17: 29.08.25 | E17: 3 | F17: 130.5 | G17: =F17*0.001 -> 0.1305 | H17: =F17*5 -> 652.5 | I17: =F17*0.5 -> 65.25
A18: Jabulile Masuku | B18: 76358035 | C18: 29.08.25 | E18: 2 | F18: 93.5 | G18: =F18*0.001 -> 0.0935 | H18: =F18*5 -> 467.5 | I18: =F18*0.5 -> 46.75
A19: Xolile Ngwenya | B19: 76120786 | C19: 29.08.25 | E19: 2 | F19: 113.5 | G19: =F19*0.001 -> 0.1135 | H19: =F19*5 -> 567.5 | I19: =F19*0.5 -> 56.75
A20: Jabulile Mamba | B20: 76772817 | C20: 29.08.25 | E20: 2 | F20: 120 | G20: =F20*0.001 -> 0.12 | H20: =F20*5 -> 600 | I20: =F20*0.5 -> 60
... A30: Bhembe Ntombikayise | B30: 76826548 | C30: 29.08.25 | E30: 4 | F30: 216 | G30: =F30*0.001 -> 0.216 | H30: =F30*5 -> 1080 | I30: =F30*0.5 -> 108
D32: Total | E32: =SUM(E9:E30) -> 181 | F32: =SUM(F9:F30) -> 10409 | G32: =SUM(G9:G30) -> 10.409 | H32: =SUM(H9:H29) -> 50965 | I32: =SUM(I9:I29) -> 5096.5
F34: Total Amount | H34: =H32+I32 -> 56061.5
A37: ICBC MAIZE SUSTAINABILITY PROJECT
H38: COMPLETED
A39: Name of ICBC: | B39: SIGANGENI ICBC | E39: Name of Pastor | F39: BONGANI MASOMBUKA
A40: Agent's Full Name | E40: ID Number
A41: Bank | B41: FNB | E41: Account Holder's Name | F41: WALK BY FAITH BIBLE MINISTRIES
A42: Branch Code | B42: CORPORATE PLACE BRANCH 281264 | E42: Account Number | F42: 63166073535
A44: Community Member’s Name & Surname | B44: Contact details | C44: Date | D44: Rate: E/kG | E44: Bags(20kG ea) | F44: Kilograms(kG) | G44: Tonnes | H44: Amount | I44: Pastor'sCommission
A45: Jabulile Dlamini | B45: 76261853 | C45: 45960 | D45: 5 | E45: 60 | F45: 1200 | G45: =F45*0.001 -> 1.2 | H45: =F45*5 -> 6000 | I45: =F45*0.5 -> 600
A46: Joseph Mbhuyisa | B46: 76680176 | C46: 45960 | D46: 5 | E46: 80 | F46: 1600 | G46: =F46*0.001 -> 1.6 | H46: =F46*5 -> 8000 | I46: =F46*0.5 -> 800
D48: Total | E48: =SUM(E45:E46) -> 140 | F48: =SUM(F45:F46) -> 2800 | G48: =SUM(G45:G46) -> 2.8 | H48: =SUM(H45:H46) -> 14000 | I48: =SUM(I45:I46) -> 1400
F50: Total Amount | H50: =H48+I48 -> 15400

Sheet MABHUKWINI
A1: ICBC MAIZE SUSTAINABILITY PROJECT
H2: COMPLETED
A3: Name of ICBC: | B3: Mabhukwini | E3: Name of Pastor | F3: Dumisani Enerst Dlamini
A4: Agent's Full Name | B4: Dumisani Earnest Dlamini | E4: ID Number
A5: Bank | B5: FNB | E5: Account Holder's Name | F5: MABHUKWINI WALK BY FAITH BIBLE MINISTRIES
A6: Branch Code | B6: 281764 | E6: Account Number | F6: 63167087121
A8: Community Member’s Name & Surname | B8: Contact details | C8: Date | E8: Bags(20kg ea) | F8: Kilograms(Kg) | G8: Tons | H8: Amount | I8: Pastor's Commission
A9: Fenis Dlamini | B9: 78356535 | C9: 45896 | E9: 12 | F9: 691.4 | G9: =F9*0.001 -> 0.6914 | H9: =F9*5 -> 3457 | I9: =F9*0.5 -> 345.7
A10: Irene S Mtjali | B10: 76694104 / 76594104 | C10: 45896 | E10: 15 | F10: 981 | G10: =F10*0.001 -> 0.981 | H10: =F10*5 -> 4905 | I10: =F10*0.5 -> 490.5
A11: Victor Vilakati | B11: 76499671 | C11: 45896 | E11: 6 | F11: 292.5 | G11: =F11*0.001 -> 0.2925 | H11: =F11*5 -> 1462.5 | I11: =F11*0.5 -> 146.25
A12: Henry Shabangu | B12: 76176833 | C12: 45896 | E12: 12 | F12: 769 | G12: =F12*0.001 -> 0.769 | H12: =F12*5 -> 3845 | I12: =F12*0.5 -> 384.5
A13: Mbeni Dlamini | B13: 78361597 | C13: 45896 | E13: 4 | F13: 185.5 | G13: =F13*0.001 -> 0.1855 | H13: =F13*5 -> 927.5 | I13: =F13*0.5 -> 92.75
A14: Lungile Ngwenya | B14: 76393233 | C14: 45896 | E14: 13 | F14: 712 | G14: =F14*0.001 -> 0.712 | H14: =F14*5 -> 3560 | I14: =F14*0.5 -> 356
A15: Simangele Dlamini | B15: 76258171 | C15: 45896 | E15: 2 | F15: 139 | G15: =F15*0.001 -> 0.139 | H15: =F15*5 -> 695 | I15: =F15*0.5 -> 69.5
A16: Ntokozo Sikhosana | B16: 768357129 | C16: 45896 | E16: 6 | F16: 338.5 | G16: =F16*0.001 -> 0.3385 | H16: =F16*5 -> 1692.5 | I16: =F16*0.5 -> 169.25
F17: =E17*20 -> 0 | G17: =F17*0.001 -> 0 | H17: =F17*5 -> 0 | I17: =F17*0.5 -> 0
F18: =E18*20 -> 0 | G18: =F18*0.001 -> 0 | H18: =F18*5 -> 0 | I18: =F18*0.5 -> 0
F19: =E19*20 -> 0 | G19: =F19*0.001 -> 0 | H19: =F19*5 -> 0 | I19: =F19*0.5 -> 0
D20: Total | E20: =SUM(E10:E15) -> 52 | F20: =SUM(F9:F17) -> 4108.9 | G20: =SUM(G9:G19) -> 4.1089 | H20: =SUM(H9:H18) -> 20544.5 | I20: =SUM(I9:I19) -> 2054.45
G22: Total Amount | H22: =H20+I20 -> 22598.95
A25: Community Member’s Name & Surname | B25: Contact details | C25: Date | E25: Bags(20kg ea) | F25: Kilograms(Kg) | G25: Tons | H25: Amount | I25: Pastor's Commission
A26: Ntokozo Sikhosana | B26: 768357129 | C26: 45896 | E26: 6 | F26: 338.5 | G26: =F26*0.001 -> 0.3385 | H26: =F26*5 -> 1692.5 | I26: =F26*0.5 -> 169.25
F27: =E27*20 -> 0 | G27: =F27*0.001 -> 0 | H27: =F27*5 -> 0 | I27: =F27*0.5 -> 0
F28: =E28*20 -> 0 | G28: =F28*0.001 -> 0 | H28: =F28*5 -> 0 | I28: =F28*0.5 -> 0
F29: =E29*20 -> 0 | G29: =F29*0.001 -> 0 | H29: =F29*5 -> 0 | I29: =F29*0.5 -> 0
D30: Total | E30: =SUM(E26:E28) -> 6 | F30: =SUM(F26:F27) -> 338.5 | G30: =SUM(G26:G29) -> 0.3385 | H30: =SUM(H26:H28) -> 1692.5 | I30: =SUM(I26:I29) -> 169.25
G32: Total Amount | H32: =H30+I30 -> 1861.75
