Workbook

Sheet Summaries
A1: Ploughing Summaries
A3: ICBC | B3: Total Hours Complete | C3: Families Impacted | D3: Hectares | E3: Status | F3: Payment | G3: Contractor | I3: ICBC Ploughing Project 2024
A4: =Bulunga!B3 -> Bulunga ICBC | B4: =Bulunga!G44 -> 50 | C4: =Bulunga!F45 -> 34 | D4: =1.5*B4 -> 75 | E4: =Bulunga!B2 -> Completed | F4: Paid | I4: =B3 -> Total Hours Complete | J4: =B45 -> 1856.6
A5: =Engcamini!B3 -> Engcamini ICBC | B5: =Engcamini!G43 -> 50 | C5: =Engcamini!F44 -> 33 | D5: =1.5*B5 -> 75 | E5: =Engcamini!B2 -> Completed | F5: Paid | I5: =C3 -> Families Impacted | J5: =C45 -> 1236
A6: =Hawane!B3 -> Hawane ICBC | B6: =Hawane!G52 -> 50 | C6: =Hawane!F53 -> 42 | D6: =1.5*B6 -> 75 | E6: =Hawane!B2 -> Completed | F6: Paid | I6: =D3 -> Hectares | J6: =D45 -> 2784.9
A7: =Jubukweni!B3 -> Jubukweni ICBC | B7: =Jubukweni!G42 -> 50 | C7: =Jubukweni!F43 -> 22 | D7: =1.5*B7 -> 75 | E7: =Jubukweni!B2 -> Completed | F7: Paid
A8: =Kaliba!B3 -> KaLiba ICBC | B8: =Kaliba!G49 -> 50 | C8: =Kaliba!F50 -> 32 | D8: =1.5*B8 -> 75 | E8: =Kaliba!B2 -> Completed | F8: Paid
A9: KaNcesi | B9: =KaNcesi!G48 -> 0 | C9: =KaNcesi!F49 -> 0 | D9: =1.5*B9 -> 0 | E9: =KaNcesi!B2 -> Not Started | F9: None
A10: =Gebeni!B3 -> Gebeni ICBC | B10: =Gebeni!G49 -> 51 | C10: =Gebeni!F50 -> 36 | D10: =1.5*B10 -> 76.5 | E10: =Gebeni!B2 -> Completed | F10: Paid
A11: =Gundvwini!B3 -> Gundvwini ICBC | B11: =Gundvwini!G45 -> 50 | C11: =Gundvwini!F46 -> 33 | D11: =1.5*B11 -> 75 | E11: =Gundvwini!B2 -> Completed | F11: Paid
A12: =Lundzi!B3 -> Lundzi ICBC | B12: =Lundzi!G37 -> 50 | C12: =Lundzi!F38 -> 26 | D12: =1.5*B12 -> 75 | E12: =Lundzi!B2 -> In Progress | F12: Paid
A13: =Lushikishini!B3 -> Lushikishini ICBC | B13: =Lushikishini!G31 -> 33 | C13: =Lushikishini!F32 -> 21 | D13: =1.5*B13 -> 49.5 | E13: =Lushikishini!B2 -> COMPLETE - NMC | F13: Paid
A14: =Lonhlalane!B3 -> Lonhlalane ICBC | B14: =Lonhlalane!G64 -> 50 | C14: =Lonhlalane!F65 -> 50 | D14: =1.5*B14 -> 75 | E14: =Lonhlalane!B2 -> Completed | F14: Paid
A15: Mabhukwini ICBC | B15: =Mabhukwini!G48 -> 55 | C15: =Mabhukwini!F49 -> 34 | D15: =1.5*B15 -> 82.5 | E15: =Mabhukwini!B2 -> Completed | F15: Paid
A16: Mabhukwini Community Fields | B16: 11 | D16: =1.5*B16 -> 16.5 | E16: Completed | F16: None
A17: Makhungutja | B17: =Makhungutja!G48 -> 50 | C17: =Makhungutja!F49 -> 27 | D17: =1.5*B17 -> 75 | E17: =Makhungutja!B2 -> Completed | F17: Paid
A18: Mangcongco ICBC | B18: =Mangcongco!G51 -> 50.7 | C18: =Mangcongco!F52 -> 32 | D18: =1.5*B18 -> 76.05 | E18: =Mangcongco!B2 -> Completed | F18: Paid
A19: Mbowane ICBC | B19: =Mbowane!H46 -> 0 | C19: =Mbowane!G47 -> 0 | D19: =1.5*B19 -> 0 | E19: =Mbowane!B2 -> Not Started | F19: None
A20: =Mcuba!B3 -> Mcuba ICBC | B20: =Mcuba!G60 -> 50 | C20: =Mcuba!F61 -> 34 | D20: =1.5*B20 -> 75 | E20: =Mcuba!B2 -> Completed | F20: Paid
A21: =Mlindazwe!B3 -> Mlindazwe ICBC | B21: =Mlindazwe!G44 -> 50 | C21: =Mlindazwe!F45 -> 33 | D21: =1.5*B21 -> 75 | E21: =Mlindazwe!B2 -> Completed | F21: Paid
A22: =Mhlangatane!B3 -> Mhlangatane ICBC | B22: =Mhlangatane!G61 -> 50 | C22: =Mhlangatane!F62 -> 50 | D22: =1.5*B22 -> 75 | E22: =Mhlangatane!B2 -> Completed | F22: Paid
A23: Njakeni ICBC | B23: =Njakeni!G51 -> 50 | C23: =Njakeni!F52 -> 40 | D23: =1.5*B23 -> 75 | E23: =Njakeni!B2 -> Completed | F23: Paid
A24: Mantabeni ICBC | B24: =Mantabeni!G70 -> 70 | C24: =Mantabeni!F71 -> 58 | D24: =1.5*B24 -> 105 | E24: =Mantabeni!B2 -> Completed | F24: Paid
A25: =Msahweni!B3 -> Msahweni ICBC | B25: =Msahweni!G58 -> 51 | C25: =Msahweni!F59 -> 47 | D25: =1.5*B25 -> 76.5 | E25: =Msahweni!B2 -> Completed | F25: Paid
A26: =Ntondozi!B3 -> Ntondozi ICBC | B26: =Ntondozi!G48 -> 50.9 | C26: =Ntondozi!F49 -> 37 | D26: =1.5*B26 -> 76.35 | E26: =Ntondozi!B2 -> Completed | F26: Paid
A27: Nyakeni | B27: =Nyakeni!G34 -> 27 | C27: =Nyakeni!F35 -> 23 | D27: =1.5*B27 -> 40.5 | E27: =Nyakeni!B2 -> Completed | F27: Paid
A28: ='Nyathela '!B3 -> Nyathela ICBC | B28: ='Nyathela '!G46 -> 50 | C28: ='Nyathela '!F47 -> 26 | D28: =1.5*B28 -> 75 | E28: ='Nyathela '!B2 -> Completed | F28: Paid | I28: Progress Report on ICBC Sites
A29: Nyamane ICBC | B29: =Nyamane!G58 -> 46 | C29: =Nyamane!F59 -> 42 | D29: =1.5*B29 -> 69 | E29: =Nyamane!B2 -> Completed | F29: Paid
A30: =Ngwenya!B3 -> Ngwenya ICBC | B30: =Ngwenya!G47 -> 50 | C30: =Ngwenya!F48 -> 34 | D30: =1.5*B30 -> 75 | E30: Completed | F30: Paid
A31: =Ngwempisi!B3 -> Ngwempisi ICBC | B31: =Ngwempisi!G42 -> 50 | C31: =Ngwempisi!F43 -> 31 | D31: =1.5*B31 -> 75 | E31: =Ngwempisi!B2 -> Completed | F31: Paid | I31: Completed Ploughing | J31: =COUNTIF(E4:E44, "Completed") -> 35
A32: =Nsingweni!B3 -> Nsingweni ICBC | B32: =Nsingweni!G34 -> 22 | C32: =Nsingweni!F35 -> 18 | D32: =1.5*B32 -> 33 | E32: =Nsingweni!B2 -> In Progress | F32: To be Paid
A33: =Nsubane!B3 -> Nsubane ICBC | B33: =Nsubane!G54 -> 35 | C33: =Nsubane!F55 -> 15 | D33: =1.5*B33 -> 52.5 | E33: =Nsubane!B2 -> Completed | F33: Paid
A34: Phonjwane ICBC | B34: =Phonjwane!G45 -> 51 | C34: =Phonjwane!F46 -> 34 | D34: =1.5*B34 -> 76.5 | E34: =Phonjwane!B2 -> Completed | F34: Paid
A35: Sibovini | B35: =Sibovini!G41 -> 51 | C35: =Sibovini!F42 -> 29 | D35: =1.5*B35 -> 76.5 | E35: =Sibovini!B2 -> Completed | F35: Paid
A36: =Sigangeni!B3 -> Sigangeni ICBC | B36: =Sigangeni!G48 -> 52 | C36: =Sigangeni!F49 -> 22 | D36: =1.5*B36 -> 78 | E36: =Sigangeni!B2 -> Completed | F36: Paid
A37: =Sigengeni!B3 -> Sigengeni ICBC | B37: =Sigengeni!G45 -> 50 | C37: =Sigengeni!F46 -> 25 | D37: =1.5*B37 -> 75 | E37: =Sigengeni!B2 -> Completed | F37: Paid
A38: =Sigombeni!B3 -> Sigombeni ICBC | B38: =Sigombeni!G51 -> 50 | C38: =Sigombeni!F52 -> 40 | D38: =1.5*B38 -> 75 | E38: =Sigombeni!B2 -> Completed | F38: Paid
A39: Tibane | B39: =Tibane!G30 -> 50 | C39: =Tibane!F31 -> 18 | D39: =1.5*B39 -> 75 | E39: =Tibane!B2 -> Completed | F39: Paid
A40: =Sigcaweni!B3 -> Esigcaweni ICBC | B40: =Sigcaweni!G49 -> 50 | C40: =Sigcaweni!F50 -> 32 | D40: =1.5*B40 -> 75 | E40: =Sigcaweni!B2 -> Completed | F40: Paid
A41: Mhlabubovu ICBC | B41: =Mhlabubovu!G61 -> 50 | C41: =Mhlabubovu!F62 -> 31 | D41: =1.5*B41 -> 75 | E41: =Mhlabubovu!B2 -> In Progress - NMC | F41: Paid
...

Sheet Engcamini
A1: ICBC Ploughing Project
B2: Completed
A3: Name of ICBC: | B3: Engcamini ICBC | E3: Name of Pastor | F3: Mongie Dlamini
A4: Contractor's Full Name | B4: Themba Maziya | E4: Contact Number | F4: 76222599
A5: Bank | B5: Starndard Bank | E5: Account Holder's Name | F5: Themba Maziya
A6: Branch Code | B6: Manzini - 660564 | E6: Account Number | F6: 9110001178051
A9: Community Member’s Name & Surname | B9: Contact details | C9: Date | D9: Start Time (Date & Time) | E9: Completion time (Date & Time) | F9: Number of Hours | G9: Actual Number of Hours | H9: Amount | I9: Location
A10: Make Bhembe | B10: 76347859 | G10: 2 | H10: =200*G10 -> 400
A11: Make Tfwala | B11: 76953049 | G11: 2 | H11: =200*G11 -> 400
A12: Make Nxumalo | B12: 76277268 | G12: 1 | H12: =200*G12 -> 200
A13: Make Manyatsi | B13: 76188072 | G13: 2 | H13: =200*G13 -> 400
A14: Zodwa Tsabedze | B14: 76835998 | G14: 2 | H14: =200*G14 -> 400
A15: Thandeka Tsabedze | B15: 76445191 | G15: 2 | H15: =200*G15 -> 400
A16: Wandile Lukhele | B16: 76773475 | G16: 1 | H16: =200*G16 -> 200
A17: Lisa Khoza | B17: 76177042 | G17: 2 | H17: =200*G17 -> 400
A18: Gogo Shongwe | B18: 78707745 | G18: 2 | H18: =200*G18 -> 400
A19: Babe Bhembe | B19: 76128185 | G19: 2 | H19: =200*G19 -> 400
A20: Make Gamedze | B20: 76449613 | G20: 1 | H20: =200*G20 -> 200
A21: Mhlanti (Gogo Skhondze) | B21: 76059524 | G21: 1 | H21: =200*G21 -> 200
... A42: Nomcebo Masina | B42: 78104961 | G42: 2 | H42: =200*G42 -> 400
E43: Total | F43: =SUM(F10:F42) -> 0 | G43: =SUM(G10:G42) -> 50 | H43: =SUM(H10:H42) -> 10000
E44: Total number of fields ploughed | F44: =COUNT(G10:G42) -> 33
D46: Checked By
D47: Signature
D48: Date

Sheet Bulunga
A1: ICBC Ploughing Project
B2: Completed
A3: Name of ICBC: | B3: Bulunga ICBC | E3: Name of Pastor | F3: Ndumiso Gwebu
A4: Contractor's Full Name | B4: Musa Masilela | E4: Contractor's Number | F4: 76063646
A5: Bank | B5: Standard Bank | E5: Account Holder's Name | F5: Musa Masilela
A6: Branch Code | B6: Manzini | E6: Account Number | F6: 9110001185341
A8: Community Member’s Name & Surname | B8: Contact details | C8: Date | D8: Start Time (Date & Time) | E8: Completion time (Date & Time) | F8: Number of Hours | G8: Actual Number of Hours | H8: Amount | I8: Location
A9: Ndumiso Gwebu | B9: 76979572 | C9: 45698 | G9: 2 | H9: =200*G9 -> 400
A10: Sicelo Lukhele | B10: 76338758 | C10: 45698 | G10: 3 | H10: =200*G10 -> 600
A11: Masaba Lukhele | B11: 79177763 | C11: 45698 | G11: 1 | H11: =200*G11 -> 200
A12: Make Ladladla | B12: 76134614 | C12: 45698 | G12: 1 | H12: =200*G12 -> 200
A13: Sthembile Gwebu | B13: 76260166 | C13: 45698 | G13: 2 | H13: =200*G13 -> 400
A14: Zanele Mamba | B14: 76786670 | C14: 45726 | G14: 1 | H14: =200*G14 -> 200
A15: Babe Dlamini | B15: 78615263 | C15: 45726 | G15: 4 | H15: =200*G15 -> 800
A16: Njabulo Khumalo | C16: 45726 | G16: 1 | H16: =200*G16 -> 200
A17: Magadze Shongwe | B17: 76323611 | C17: 45726 | G17: 2 | H17: =200*G17 -> 400
A18: Mshiyeni Ngwenya | B18: 76875547 | C18: 45726 | G18: 2 | H18: =200*G18 -> 400
A19: Jabulane Lukhele | B19: 76269031 | C19: 45757 | G19: 2 | H19: =200*G19 -> 400
A20: Thoko Mlambo | B20: 76445985 | C20: 45757 | G20: 2 | H20: =200*G20 -> 400
A21: Thokozile Shongwe | B21: 78425976 | C21: 45757 | G21: 1 | H21: =200*G21 -> 200
A22: Thabo Dlamini | B22: 78219943 | C22: 45757 | G22: 1 | H22: =200*G22 -> 200
A23: Mthunzi Dlamini | B23: 76217105 | C23: 45757 | G23: 1 | H23: =200*G23 -> 200
A24: Magwaza Dlamini | B24: 76400420 | C24: 45757 | G24: 1 | H24: =200*G24 -> 200
A25: Make Masuku | B25: 78169312 | C25: 45757 | G25: 1 | H25: =200*G25 -> 200
A26: Mpendulo Lukhele | B26: 76776566 | C26: 45940 | G26: 1 | H26: =200*G26 -> 200
A27: babe shongwe | C27: 45940 | G27: 2 | H27: =200*G27 -> 400
A28: Make Magagula | C28: 25/10/25 | G28: 1 | H28: =200*G28 -> 200
A29: Mbongiseni Shongwe | C29: 45971 | G29: 2 | H29: =200*G29 -> 400
A30: Mehlabo Dlamini | C30: 46001 | G30: 2 | H30: =200*G30 -> 400
A31: Make Ndlovu | C31: 46001 | G31: 1 | H31: =200*G31 -> 200
A32: Dumsane | C32: 45941 | G32: 1 | H32: =200*G32 -> 200
A33: Make LaGwebu | B33: 76525177 | C33: 45941 | G33: 1 | H33: =200*G33 -> 200
A34: Magrett Dlamini | B34: 76571364 | C34: 45941 | G34: 1 | H34: =200*G34 -> 200
A35: Make Dlamini | B35: 76317342 | C35: 45972 | G35: 1.5 | H35: =200*G35 -> 300
A36: Babe Magwaza | B36: 76400420 | C36: 45972 | G36: 1 | H36: =200*G36 -> 200
A37: LaGwebu | C37: 45972 | G37: 1.5 | H37: =200*G37 -> 300
A38: Make Lahlophe | B38: 76872328 | C38: 45972 | G38: 2 | H38: =200*G38 -> 400
A39: Babe Skhondze | C39: 45941 | G39: 1 | H39: =200*G39 -> 200
A40: Thandiwe Blula | C40: 45941 | G40: 1 | H40: =200*G40 -> 200
A41: LaLukhele | C41: 45941 | G41: 1 | H41: =200*G41 -> 200
...

Sheet Gebeni
A1: ICBC Ploughing Project
B2: Completed
A3: Name of ICBC: | B3: Gebeni ICBC | E3: Name of Pastor | F3: Sipho Mdluli
A4: Contractor's Full Name | B4: SZ Investment (Sithabiso Zwane) | E4: Contractor's ID Number
A5: Bank | B5: First National Bank | E5: Account Holder's Name | F5: Sithabiso Zwane
A6: Branch Code | B6: 281864 | E6: Account Number | F6: 62853630533
A9: Community Member’s Name & Surname | B9: Contact Details | C9: Date | D9: Start Time (Date & Time) | E9: Completion time (Date & Time) | F9: Number of Hours | G9: Actual Number of Hours | H9: Amount | I9: Location
A10: Mr Robert Vilakati | B10: 78180538 | C10: 45963 | F10: 2 | G10: 1 | H10: =200*G10 -> 200
A11: Titus Dlamini | B11: 76478178 | C11: 45962 | F11: 2 | G11: 1 | H11: =200*G11 -> 200
A12: Mr Seluleko Vilakati | B12: 76919069 | C12: 45965 | F12: 1 | G12: 1 | H12: =200*G12 -> 200
A13: Mr Mxolisi Vilakati | B13: 76034480 | C13: 45963 | F13: 1 | G13: 1 | H13: =200*G13 -> 200
A14: Gogo V | B14: 76085415 | C14: 45963 | F14: 2 | G14: 1 | H14: =200*G14 -> 200
A15: Mr France Mndzebele | B15: 76180442 | C15: 45965 | F15: 2 | G15: 2 | H15: =200*G15 -> 400
A16: Make Masangane | B16: 79397236 | C16: 45969 | F16: 1 | G16: 1 | H16: =200*G16 -> 200
A17: Mr Nicholas Mabuza | B17: 76224315 | C17: 45965 | D17: 11/1/25 (2 Hours) | E17: 11/4/25 (2 Hours) | F17: 4 | G17: 4 | H17: =200*G17 -> 800
A18: Mr Nelson Mdluli | B18: 79080259 | C18: 45971 | F18: 3 | G18: 3 | H18: =200*G18 -> 600
A19: Mr Boniface Mdluli | B19: 79397236 | C19: 45965 | F19: 1 | G19: 1 | H19: =200*G19 -> 200
A20: KaMavimbela (Anastacia) | B20: 78155350 | C20: 45962 | F20: 2 | G20: 2 | H20: =200*G20 -> 400
A21: Melani Dlamini | B21: 79828919/76153240 | C21: 45971 | F21: 2 | G21: 1 | H21: =200*G21 -> 200
A22: Mr Mpostoli Mazibuko | B22: 79395067 | C22: 45965 | F22: 1 | G22: 1 | H22: =200*G22 -> 200
A23: Mr Thulane Dlamini | B23: 76048961 | C23: 45962 | F23: 2 | G23: 1 | H23: =200*G23 -> 200
A24: Mr Lucky Dlamini | B24: 76258468 | C24: 45962 | F24: 2 | G24: 2 | H24: =200*G24 -> 400
A25: Takangwane Ndwande | B25: 79383804 | C25: 45966 | F25: 2 | G25: 2 | H25: =200*G25 -> 400
A26: Mumcy Dlamini | B26: 76372196 | C26: 45969 | F26: 2 | G26: 2 | H26: =200*G26 -> 400
A27: David Mabuza (from Muzwabo) | B27: 79491067 | C27: 45967 | F27: 2 | G27: 2 | H27: =200*G27 -> 400
A28: Maheshe Mndzebele | B28: 76712562 | C28: 45966 | F28: 2 | G28: 2 | H28: =200*G28 -> 400
A29: Mr Mfanaleni Mndzebele | B29: 79258007 | C29: 45963 | F29: 1 | G29: 1 | H29: =200*G29 -> 200
A30: Gogo Malinga (replacing Maxwell) | B30: 76473419 | C30: 45966 | F30: 2 | G30: 2 | H30: =200*G30 -> 400
A31: Nonhle Mtsetfwa | B31: 79652950 | C31: 45966 | F31: 2 | G31: 1 | H31: =200*G31 -> 200
A32: Tula Ndlovu | B32: 79556383 | C32: 45966 | F32: 2 | G32: 1 | H32: =200*G32 -> 200
A33: Gogo Zwane | C33: 45962 | F33: 1 | G33: 1 | H33: =200*G33 -> 200
A34: Make Msibi | B34: 76836819 | C34: 45965 | F34: 1 | G34: 1 | H34: =200*G34 -> 200
A35: Gogo Mabuza (Hour from Tula) | C35: 45966 | G35: 1 | H35: =200*G35 -> 200
A36: Phindile Dlamini | C36: 45967 | G36: 1 | H36: =200*G36 -> 200
A37: Gogo Nkhonde | C37: 45967 | G37: 1 | H37: =200*G37 -> 200
A38: Mr Shilesh Mabuza | C38: 45967 | G38: 2 | H38: =200*G38 -> 400
A39: Make Khumalo | C39: 45967 | G39: 2 | H39: =200*G39 -> 400
A40: Sipho Mdluli | C40: 45969 | G40: 1 | H40: =200*G40 -> 200
A41: Sicelo Mndzebele | C41: 45969 | G41: 1 | H41: =200*G41 -> 200
A42: LaGadlela Ndwandwa | C42: 45969 | G42: 1 | H42: =200*G42 -> 200
...

Sheet Gundvwini
A1: ICBC Ploughing Project
B2: Completed
A3: Name of ICBC: | B3: Gundvwini ICBC | E3: Name of Pastor | F3: Dumisani Mdluli
A4: Contractor's Full Name | B4: SZ Investment (Sithabiso Zwane) | E4: Contractor's ID Number
A5: Bank | B5: First National Bank | E5: Account Holder's Name | F5: Sithabiso Zwane
A6: Branch Code | B6: 281864 | E6: Account Number | F6: 62853630533
A9: Community Member’s Name & Surname | B9: Contact Details | C9: Date | D9: Start Time (Date & Time) | E9: Completion time (Date & Time) | F9: Number of Hours | G9: Actual Number of Hours | H9: Amount | I9: Location
A10: Ntambama Gwebu | B10: 76114031 | C10: 45981 | G10: 2 | H10: =200*G10 -> 400
A11: Mthandeni Dlamini | B11: 76805639 | C11: 45981 | G11: 2 | H11: =200*G11 -> 400
A12: Bongiwe Dludlu | B12: 79924433 | C12: 45981 | G12: 1 | H12: =200*G12 -> 200
A13: Gogo Motsa | B13: 76222292 | C13: 45981 | G13: 1 | H13: =200*G13 -> 200
A14: Make Hlophe | B14: 76185157 | C14: 45981 | G14: 2 | H14: =200*G14 -> 400
A15: Vimbela Dlamini | B15: 76079069 | C15: 45981 | G15: 1 | H15: =200*G15 -> 200
A16: Senzo Shongwe | B16: 76609495 | C16: 45981 | G16: 1 | H16: =200*G16 -> 200
A17: Bons'sile Gwebu | B17: 76627118 | C17: 45981 | G17: 2 | H17: =200*G17 -> 400
A18: Mendzi Gwebu | B18: 76417678 | C18: 45981 | G18: 2 | H18: =200*G18 -> 400
A19: Majahonkhe Gwebu | B19: 76802987 | C19: 45981 | G19: 1 | H19: =200*G19 -> 200
A20: Make Dlamini | B20: 76743511 | C20: 45981 | G20: 2 | H20: =200*G20 -> 400
A21: Babe Maseko | B21: 76812896 | C21: 45981 | G21: 2 | H21: =200*G21 -> 400
... A41: Robert Vilakati | B41: 78180538 | C41: 45990 | G41: 1 | H41: =200*G41 -> 200
A42: Moses Mndzebele | C42: 45990 | G42: 1 | H42: =200*G42 -> 200
H43: =200*G43 -> 0
H44: =200*G44 -> 0
E45: Total | F45: =SUM(F10:F44) -> 0 | G45: =SUM(G10:G44) -> 50 | H45: =SUM(H10:H44) -> 10000
E46: Total number of fields ploughed | F46: =COUNT(G10:G44) -> 33
D48: Checked By
D50: Signature
D52: Date

Sheet Hawane
A1: ICBC Ploughing Project | L1: ICBC Ploughing Project
B2: Completed | M2: Completed
A3: Name of ICBC: | B3: Hawane ICBC | E3: Name of Pastor | F3: Timothy Makhanya | L3: Name of ICBC: | M3: Hawane ICBC | P3: Name of Pastor | Q3: Timothy Makhanya
A4: Contractor's Full Name | B4: FNB Mbabane | E4: Contractor's ID Number | L4: Contractor's Full Name | M4: CMS | P4: Contractor's ID Number
A5: Bank | E5: Account Holder's Name | F5: Themba Hleta | L5: Bank | P5: Account Holder's Name | Q5: Wilton Nkhambule
A6: Branch Code | E6: Account Number | F6: 62232811861 | L6: Branch Code | P6: Account Number | Q6: 200 000 66185
A9: Community Member’s Name & Surname | B9: Contact Details | C9: Date | D9: Start Time (Date & Time) | E9: Completion time (Date & Time) | F9: Number of Hours | G9: Actual Number of Hours | H9: Amount | I9: Location | L9: Community Member’s Name & Surname | M9: Contact Details | N9: Date | O9: Start Time (Date & Time) | P9: Completion time (Date & Time) | Q9: Number of Hours | R9: Actual Number of Hours | S9: Amount | T9: Location
A10: Mkhonta Next to Hawane Primary | B10: 78633443 | C10: 45957 | G10: 1 | H10: =200*G10 -> 200 | L10: Ps Timothy Makhanya | N10: 20/11/24 | Q10: 1.5 | R10: 1.5 | S10: =300*R10 -> 450
A11: Sithole Next to Hawane Primary | B11: 76476536 | C11: 45957 | G11: 1 | H11: =200*G11 -> 200 | L11: Ps Timothy Makhanya | N11: 20/11/24 | Q11: 1.2 | R11: 1.2 | S11: =300*R11 -> 360
A12: Joyce Lukhele | B12: 76771194 | C12: 45957 | G12: 2 | H12: =200*G12 -> 400 | L12: Ps Timothy Makhanya | N12: 21/11/24 | Q12: 1.2 | R12: 1.2 | S12: =300*R12 -> 360
A13: Gogo Matsebula | B13: 79879732 | C13: 45957 | G13: 1 | H13: =200*G13 -> 200 | S13: =300*R13 -> 0
A14: Mbuso Ndlela | B14: 76323489 | C14: 45758 | G14: 1 | H14: =200*G14 -> 200 | I14: 26° 12' 33.2003" S 31° 5' 41.5219" E | S14: =300*R14 -> 0
A15: Jabu Mlotshwa | B15: 78300499 | C15: 45758 | G15: 1 | H15: =200*G15 -> 200 | I15: 26° 12' 34.4938" S 31° 5' 6.2732" E | S15: =300*R15 -> 0
A16: Siboniso Ntjalintjali | B16: 76656417 | C16: 45758 | G16: 2 | H16: =200*G16 -> 400 | S16: =300*R16 -> 0
A17: Peter Mabuza by the dam | B17: 76933155 | C17: 45758 | G17: 2 | H17: =200*G17 -> 400 | I17: 26° 13' 6.2476" S 31° 5' 15.5807" E | S17: =300*R17 -> 0
A18: Gogo Magongo ngase FEA | B18: 76596114 | C18: 45758 | G18: 2 | H18: =200*G18 -> 400 | S18: =300*R18 -> 0
A19: Make Nombulelo | B19: 7624 9886 | C19: 45758 | G19: 1 | H19: =200*G19 -> 200 | I19: 26° 10' 11.3369" S 31° 6' 24.9376" E | S19: =300*R19 -> 0
A20: Maduna | B20: 78262620 | C20: 45788 | G20: 1 | H20: =200*G20 -> 200 | I20: 26° 10' 13.1639" S 31° 6' 25.0132" E | S20: =300*R20 -> 0
A21: KaDube eMhlosheni | B21: 76034792 | C21: 45788 | G21: 1 | H21: =200*G21 -> 200 | S21: =300*R21 -> 0
A22: Roman Nxumalo | C22: 45788 | G22: 1 | H22: =200*G22 -> 200 | S22: =300*R22 -> 0
A23: Babe waLusanda Nxumalo | B23: 7605 7085 | C23: 45788 | G23: 1 | H23: =200*G23 -> 200 | S23: =300*R23 -> 0
A24: Make Dlamini | B24: 79258179 | C24: 45819 | G24: 1 | H24: =200*G24 -> 200 | I24: 26° 9' 53.964" S 31° 6' 21.4016" E | S24: =300*R24 -> 0
A25: Make Manzini | B25: 76062704 | C25: 45819 | G25: 2 | H25: =200*G25 -> 400 | I25: 26° 9' 58.622" S 31° 6' 25.7324" E | S25: =300*R25 -> 0
A26: Makhanya | B26: 7665 8129 | C26: 45819 | G26: 1 | H26: =200*G26 -> 200 | I26: 26° 10' 2.1342" S 31° 6' 12.4693" E | S26: =300*R26 -> 0
A27: KaMhlanga (Winile) | B27: 76137999 | C27: 45819 | G27: 1 | H27: =200*G27 -> 200 | I27: 26° 11' 39.1913" S 31° 3' 22.8506" E | S27: =300*R27 -> 0
A28: Ndlangamandla next to dam | B28: 78065362 | C28: 45819 | G28: 1 | H28: =200*G28 -> 200 | I28: 26° 13' 21.7582" S 31° 4' 39.0385" E | S28: =300*R28 -> 0
A29: Themba & Beauty Hlophe | B29: 76416779 | C29: 45819 | G29: 2 | H29: =200*G29 -> 400 | S29: =300*R29 -> 0
A30: Siniketiwe Dlamini | B30: 76277422 | C30: 45849 | G30: 1 | H30: =G30*200 -> 200 | I30: 26° 13' 3.2614" S 31° 2' 45.0838" E
A31: Bhembe by Hawane dam | B31: 76754494 | C31: 45971 | G31: 1 | H31: =200*G31 -> 200 | I31: 26° 13' 0.4912" S 31° 5' 16.1416" E | S31: =300*R31 -> 0
A32: Mkhwanazi | B32: 79739380 | C32: 45971 | G32: 1 | H32: =200*G32 -> 200 | I32: ]' | S32: =300*R32 -> 0
A33: Nkambule | B33: 76857177 | C33: 45971 | G33: 1 | H33: =200*G33 -> 200 | I33: 26° 12' 51.1844" S 31° 5' 17.0563" E | S33: =300*R33 -> 0
A34: Kunene by Hawane dam | B34: 76857177 | C34: 45971 | G34: 1 | H34: =200*G34 -> 200 | I34: 26° 13' 0.953" S 31° 5' 23.4287" E | S34: =300*R34 -> 0
A35: Mncina Mkhwanazi | B35: 79982552 | C35: 45971 | G35: 1 | H35: =200*G35 -> 200 | I35: 26° 12' 42.6492" S 31° 5' 22.7479" E | S35: =300*R35 -> 0
A36: Sibandze | B36: 76023881 | G36: 1 | H36: =200*G36 -> 200 | S36: =300*R36 -> 0
A37: Bill | B37: 76117865 | G37: 1 | H37: =200*G37 -> 200 | S37: =300*R37 -> 0
A38: Star Mlotshwa | B38: 79816197 | G38: 1 | H38: =200*G38 -> 200 | S38: =300*R38 -> 0
A39: Nkambule (White City) | B39: 76932227 | G39: 2 | H39: =200*G39 -> 400 | S39: =300*R39 -> 0
A40: Dlamini | B40: 79241618 | G40: 1 | H40: =200*G40 -> 200 | S40: =300*R40 -> 0
A41: Shabangu | B41: 78126414 | G41: 1 | H41: =200*G41 -> 200
A42: Mbuso Masina | B42: 76115346 | G42: 1 | H42: =200*G42 -> 200 | S42: =300*R42 -> 0
...

Sheet Jubukweni
A1: ICBC Ploughing Project
B2: Completed
A3: Name of ICBC: | B3: Jubukweni ICBC | E3: Name of Pastor | F3: Sipho Kunene
A4: Contractor's Full Name | B4: MR MXOLISI M C GUMEDE | E4: Contractor's ID Number
A5: Bank | B5: FNB | E5: Account Holder's Name | F5: MR MXOLISI M C GUMEDE
A6: Branch Code | B6: 661164 PIGGS PEAK | E6: Account Number | F6: 62449004928
A9: Community Member’s Name & Surname | B9: Contact Details | C9: Date | D9: Start Time (Date & Time) | E9: Completion time (Date & Time) | F9: Number of Hours | G9: Actual Number of Hours | H9: Amount | I9: Location
A10: Make Masilela | B10: 76606658 | C10: 45936 | D10: 1330 | E10: 1730 | F10: 4 | G10: 4 | H10: =G10*200 -> 800
A11: Gogo Mnisi | B11: 76419622 | C11: 45938 | D11: 0530 | E11: 1030 | F11: 5 | G11: 5 | H11: =G11*200 -> 1000
A12: Make Skhondze | B12: 79653860 | C12: 45936 | D12: 0600 | E12: 1000 | F12: 4 | G12: 4 | H12: =G12*200 -> 800
A13: Mumcy Magongo | B13: 76346047 | C13: 45932 | D13: 0700 | E13: 1000 | F13: 3 | G13: 3 | H13: =G13*200 -> 600
A14: Make Nhlabatsi | B14: 76191645 | C14: 45937 | D14: 1015 | E14: 1215 | F14: 2 | G14: 2 | H14: =G14*200 -> 400
A15: Babe Khumalo | B15: 76123023 | C15: 45938 | D15: 1345 | E15: 1545 | F15: 2 | G15: 2 | H15: =G15*200 -> 400
A16: Make Mnisi | B16: 76234210 | C16: 44837 | D16: 0620 | E16: 0820 | F16: 2 | G16: 2 | H16: =G16*200 -> 400
A17: Emphakatsini | B17: 76146854 | C17: 45933 | D17: 1015 | E17: 1315 | F17: 3 | G17: 3 | H17: =G17*200 -> 600
A18: Ndvuna Mabuza | B18: 78515805 | C18: 45938 | D18: 1100 | E18: 1300 | F18: 2 | G18: 2 | H18: =G18*200 -> 400
A19: Make Masilela | B19: 76326608 | C19: 45932 | D19: 0930 | E19: 1130 | F19: 2 | G19: 2 | H19: =G19*200 -> 400
A20: Babe Ngwenya | B20: 76053506 | C20: 45935 | D20: 0710 | E20: 0940 | F20: 2.5 | G20: 2.5 | H20: =G20*200 -> 500
A21: Babe Gama R. | B21: 78251422 | C21: 45936 | D21: 1030 | E21: 1230 | F21: 2 | G21: 2 | H21: =G21*200 -> 400
A22: Thembinkosi Gama | B22: 763309243 | C22: 45940 | D22: 1030 | F22: 4 | G22: 4 | H22: =G22*200 -> 800
A23: KaMaphalala | B23: 79590877 | F23: 2 | G23: 2 | H23: =G23*200 -> 400
A24: Make Mamba | F24: 1 | G24: 1 | H24: =G24*200 -> 200
A25: Mkhulu Mnisi | B25: 79786881 | F25: 2 | G25: 2 | H25: =G25*200 -> 400
A26: Make Nkambule | B26: 78132547 | F26: 1 | G26: 1 | H26: =G26*200 -> 200
A27: Thobile Dlamini | B27: 76226713 | F27: 2 | G27: 2 | H27: =G27*200 -> 400
A28: Make Zwane | B28: 76355080 | F28: 1.5 | G28: 1.5 | H28: =G28*200 -> 300
A29: Gogo Skhondze | B29: 78646249 | F29: 1 | G29: 1 | H29: =G29*200 -> 200
A30: Games Mnisi | B30: 76146854 | F30: 1 | G30: 1 | H30: =G30*200 -> 200
A31: Esontfweni | B31: 76172351 | F31: 1 | G31: 1 | H31: =G31*200 -> 200
H32: =G32*200 -> 0
H33: =G33*200 -> 0
H34: =G34*200 -> 0
H35: =G35*200 -> 0
H36: =G36*200 -> 0
H37: =G37*200 -> 0
H38: =G38*200 -> 0
H39: =G39*200 -> 0
H40: =G40*200 -> 0
H41: =G41*200 -> 0
E42: Total | F42: =SUM(F10:F41) -> 50 | G42: =SUM(G10:G41) -> 50 | H42: =SUM(H2:H41) -> 10000
...

Sheet Kaliba
A1: ICBC Ploughing Project
B2: Completed
A3: Name of ICBC: | B3: KaLiba ICBC | E3: Name of Pastor | F3: Majahonkhe Tsabedze
A4: Contractor's Full Name | E4: Contractor's ID Number
A5: Bank | E5: Account Holder's Name
A6: Branch Code | E6: Account Number
A9: Community Member’s Name & Surname | B9: Contact Details | C9: Date | D9: Start Time (Date & Time) | E9: Completion time (Date & Time) | F9: Number of Hours | G9: Actual Number of Hours | H9: Amount | I9: Location
A10: Samkelo Myeni | B10: 7614 8718 | C10: 45972 | G10: 3 | H10: =200*G10 -> 600
A11: Sambane Fakudze | B11: 7612 3830 | C11: 45972 | G11: 1 | H11: =200*G11 -> 200
A12: Takhona Malindzisa | B12: 76607815 | C12: 45972 | G12: 1 | H12: =200*G12 -> 200
A13: Loheshe Dlamini | B13: 7835 6640 | C13: 45972 | G13: 1 | H13: =200*G13 -> 200
A14: Nokulunga Hlophe | B14: 7813 9964 | C14: 45972 | G14: 1 | H14: =200*G14 -> 200
A15: Lomsombuluko Malindzisa | B15: 78261614 | C15: 46002 | G15: 2 | H15: =200*G15 -> 400
A16: Ndlaleni Mabuza | B16: 76518082 | C16: 46002 | G16: 2 | H16: =200*G16 -> 400
A17: Khaya Mabuza | B17: 78165052 | C17: 46002 | G17: 2 | H17: =200*G17 -> 400
A18: Mbhasobhi Zungu | B18: 7807 6200 | C18: 46002 | G18: 1 | H18: =200*G18 -> 200
A19: Ezekiel Mabuza | B19: 7614 8833 | C19: 46002 | G19: 1 | H19: =200*G19 -> 200
A20: Nomzamo Malindzisa | B20: 7673 7996 | C20: 46002 | G20: 1 | H20: =200*G20 -> 200
A21: Sipho Fakudze | B21: 78075156 | C21: 13/11/25 | G21: 3 | H21: =200*G21 -> 600
A22: Dumisa Fakudze | B22: 76803606 | C22: 13/11/25 | G22: 1 | H22: =200*G22 -> 200
A23: Thulani Sithole | B23: 7660 8129 | C23: 13/11/25 | G23: 1 | H23: =200*G23 -> 200
A24: Scelo Mkhweli | B24: 7834 8129 | C24: 13/11/25 | G24: 2 | H24: =200*G24 -> 400
A25: Ntfombiyenkhosi Dlamini | B25: 7694 5178 | C25: 14/11/25 | G25: 2 | H25: =200*G25 -> 400
A26: Philile Simelane | B26: 7801 4305 | C26: 14/11/25 | G26: 1 | H26: =200*G26 -> 200
A27: Lubhokobhoko Dlamini | B27: 76437743 | C27: 14/11/25 | G27: 2 | H27: =200*G27 -> 400
A28: Mncobi Mndzebele | B28: 7676 5345 | C28: 14/11/25 | G28: 2 | H28: =200*G28 -> 400
A29: Jabulani Mamba | B29: 76592621 | C29: 26/11/25 | G29: 1 | H29: =200*G29 -> 200
A30: Lonah Dlamini | B30: 76774833 | C30: 26/11/25 | G30: 1 | H30: =200*G30 -> 200
A31: Eric Dlamini | B31: 76894912 | C31: 26/11/25 | G31: 2 | H31: =200*G31 -> 400
A32: Mdumseni Shlongonyane | B32: 76389677 | C32: 26/11/25 | G32: 1 | H32: =200*G32 -> 200
A33: LaMangwe Shlongonyane | B33: 79209968 | C33: 26/11/25 | G33: 2 | H33: =200*G33 -> 400
A34: Nokwanda Jele | B34: 78707159 | C34: 26/11/25 | G34: 1 | H34: =200*G34 -> 200
A35: Mnikwa Dlamini | B35: 76967645 | C35: 24/11/25 | G35: 2 | H35: =200*G35 -> 400
A36: Sagila Malindzisa | B36: 76721035 | C36: 24/11/25 | G36: 1 | H36: =200*G36 -> 200
A37: Gogo Makhubu | B37: 76746433 | C37: 24/11/25 | G37: 1 | H37: =200*G37 -> 200
A38: Sphelele Dlamini | B38: 78890323 | C38: 24/11/25 | G38: 2 | H38: =200*G38 -> 400
A39: Nonduduzo Malindzisa | B39: 78408431 | C39: 24/11/25 | G39: 1 | H39: =200*G39 -> 200
A40: Majahonkhe Tsabedze | B40: 76603443 | C40: 27/11/25 | G40: 2 | H40: =200*G40 -> 400
A41: Smanga Dlamini | B41: 78033847 | C41: 27/11/25 | G41: 3 | H41: =200*G41 -> 600
H42: =200*G42 -> 0
...

Sheet KaNcesi
A1: ICBC Ploughing Project
B2: Not Started
A3: Name of ICBC: | B3: KaNcesi ICBC | E3: Name of Pastor | F3: Joel Tsela
A4: Contractor's Full Name | E4: Contractor's ID Number
A5: Bank | E5: Account Holder's Name
A6: Branch Code | E6: Account Number
A9: Community Member’s Name & Surname | B9: Contact Details | C9: Date | D9: Start Time (Date & Time) | E9: Completion time (Date & Time) | F9: Number of Hours | G9: Actual Number of Hours | H9: Amount | I9: Location
H10: =200*G10 -> 0
H11: =200*G11 -> 0
H12: =200*G12 -> 0
H13: =200*G13 -> 0
H14: =200*G14 -> 0
H15: =200*G15 -> 0
H16: =200*G16 -> 0
H17: =200*G17 -> 0
H18: =200*G18 -> 0
H19: =200*G19 -> 0
H20: =200*G20 -> 0
H21: =200*G21 -> 0
... H47: =200*G47 -> 0
E48: Total | F48: =SUM(F9:F47) -> 0 | G48: =SUM(G1:G47) -> 0 | H48: =SUM(H9:H47) -> 0
E49: Total number of fields ploughed | F49: =COUNT(G10:G47) -> 0
D51: Checked By
D52: Signature
D53: Date

Sheet Lavumisa
A1: ICBC Ploughing Project
B2: Did Not Plough
A3: Name of ICBC: | B3: Lavumisa ICBC | E3: Name of Pastor | F3: Sabelo Gina
A4: Contractor's Full Name | B4: Sunboy Sithembiso Msibi | E4: Contractor's ID Number
A5: Bank | B5: Fist National Bank | E5: Account Holder's Name | F5: Sunboy Sithembiso Msibi
A6: Branch Code | E6: Account Number | F6: E- Wallet 76122450
A9: Community Member’s Name & Surname | B9: Contact Details | C9: Date | D9: Start Time (Date & Time) | E9: Completion time (Date & Time) | F9: Number of Hours | G9: Actual Number of Hours | H9: Amount | I9: Location
E31: Total | F31: =SUM(F10:F30) -> 0 | G31: =SUM(G1:G30) -> 0 | H31: =SUM(H10:H30) -> 0
E32: Total number of fields ploughed | F32: =COUNT(G2:G30) -> 0
D34: Checked By
D35: Signature
D36: Date

Sheet Lundzi
A1: ICBC Ploughing Project
B2: In Progress
A3: Name of ICBC: | B3: Lundzi ICBC | E3: Name of Pastor | F3: Bongiswa Ntshalintshali
A4: Contractor's Full Name | B4: Dlamini Enock Siboniso | E4: Contractor's ID Number
A5: Bank | B5: Nedbank | E5: Account Holder's Name | F5: Dlamini Enock Siboniso
A6: Branch Code | B6: Mbabane | E6: Account Number | F6: 20000040817
A9: Community Member’s Name & Surname | B9: Contact Details | C9: Date | D9: Start Time (Date & Time) | E9: Completion time (Date & Time) | F9: Number of Hours | G9: Actual Number of Hours | H9: Amount | I9: Location
A10: Babe Shongwe | B10: 76670768 | C10: 45964 | D10: 0.29166667 | E10: 0.33333333 | G10: 1 | H10: =200*G10 -> 200
A11: Gogo E | B11: 76039069 | C11: 45964 | D11: 0.39583333 | E11: 0.48958333 | G11: 2 | H11: =200*G11 -> 400
A12: Make Kunene | B12: 76903917 | C12: 45964 | D12: 0.54166667 | E12: 0.59375 | G12: 1 | H12: =200*G12 -> 200
A13: Boy Dlamini | B13: 76909991 | C13: 45966 | D13: 0.20833333 | E13: 0.25694444 | G13: 1 | H13: =200*G13 -> 200
A14: Make Ginindza | B14: 76287146 | C14: 45966 | D14: 0.49305556 | E14: 0.54861111 | G14: 1 | H14: =200*G14 -> 200
A15: Babe Mdluli | B15: 76518751 | C15: 45968 | D15: 0.54166667 | E15: 0.63888889 | G15: 2 | H15: =200*G15 -> 400
A16: Make Nkhambule | B16: 76446827 | C16: 45971 | D16: 0.20833333 | E16: 0.25694444 | G16: 1 | H16: =200*G16 -> 200
A17: Make Mkhonta | B17: 76522170 | C17: 45971 | D17: 0.36458333 | E17: 0.40972222 | G17: 1 | H17: =200*G17 -> 200
A18: Make Zwane | B18: 79162424 | C18: 45971 | D18: 0.42361111 | E18: 0.47916667 | G18: 1 | H18: =200*G18 -> 200
A19: Make Mayisela | B19: 76417505 | C19: 45971 | D19: 0.50347222 | E19: 0.54861111 | G19: 1 | H19: =200*G19 -> 200
A20: Mduduzi Shongwe | B20: 76676768 | C20: 45971 | D20: 13::30 | E20: 0.61805556 | G20: 1 | H20: =200*G20 -> 200
A21: Ntokozo Masuku | B21: 76127398 | C21: 45971 | D21: 0.625 | E21: 0.72916667 | G21: 2 | H21: =200*G21 -> 400
A22: Gogo Masuku | B22: 76127398 | C22: 45972 | D22: 0.67361111 | E22: 0.72916667 | G22: 1 | H22: =200*G22 -> 200
A23: Siboniso Dlamini | B23: 76042547 | C23: 45972 | D23: 11/11/2025, 17h50 - 20h50 | E23: 12/05/2025, 06h00 - 13h30 | G23: 10 | H23: =200*G23 -> 2000
A24: Sipho Dlamini | B24: 76042547 | C24: 45972 | D24: 0.20833333 | E24: 0.35416667 | G24: 3 | H24: =200*G24 -> 600
A25: Topolo Dlamini | B25: 78144707 | C25: 45972 | D25: 0.41666667 | E25: 0.46527778 | G25: 1 | H25: =200*G25 -> 200
A26: Babe Ngwenya | B26: 76230687 | C26: 45972 | D26: 0.52083333 | E26: 0.56944444 | G26: 2 | H26: =200*G26 -> 400
A27: Babe Mahlalela | B27: 76298599 | C27: 45972 | D27: 0.66666667 | E27: 0.72222222 | G27: 1 | H27: =200*G27 -> 200
A28: LaGinindza | B28: 7677866- | C28: 45973 | D28: 0.25694444 | E28: 0.3125 | G28: 3 | H28: =200*G28 -> 600
A29: LaNkhosi | B29: 76661662 | C29: 45973 | D29: 0.41666667 | E29: 0.55555556 | G29: 3 | H29: =200*G29 -> 600
A30: Make Tsabedze | B30: 76708727 | C30: 45973 | D30: 0.57638889 | E30: 0.66666667 | G30: 2 | H30: =200*G30 -> 400
A31: Babe Lukhele | B31: 76142411 | C31: 45973 | D31: 0.70833333 | E31: 0.75347222 | G31: 1 | H31: =200*G31 -> 200
A32: Jeff Ginindza | B32: 76792194 | C32: 45986 | D32: 0.41666667 | E32: 0.46527778 | G32: 1 | H32: =200*G32 -> 200
A33: Make Nxumalo | B33: 78275548 | C33: 45986 | D33: 0.5 | E33: 0.55208333 | G33: 1 | H33: =200*G33 -> 200
A34: Make Ndwandwa | B34: 76417505 | C34: 45986 | D34: 0.5625 | E34: 0.61111111 | G34: 1 | H34: =200*G34 -> 200
A35: Bongiswa Ntshalintshali | B35: 76051596 | C35: 45996 | D35: 0.58333333 | E35: 0.8125 | G35: 5 | H35: =200*G35 -> 1000
H36: =200*G36 -> 0
E37: Total | F37: =SUM(F10:F36) -> 0 | G37: =SUM(G10:G36) -> 50 | H37: =SUM(H10:H36) -> 10000
E38: Total number of fields ploughed | F38: =COUNT(G2:G36) -> 26
D40: Checked By
D41: Signature
D42: Date

Sheet Lonhlalane
A1: ICBC Ploughing Project
B2: Completed
A3: Name of ICBC: | B3: Lonhlalane ICBC | E3: Name of Pastor | F3: Johannes Ndwandwe
A4: Contractor's Full Name | B4: Vusumuzi Mhlanga | E4: Contractor's Number
A5: Bank | B5: Eswatini Bank | E5: Account Holder's Name | F5: Vulamehlo Zinyane
A6: Branch Code | B6: 770000 | E6: Account Number | F6: 77400342329
A9: Community Member’s Name & Surname | B9: Contact Details | C9: Date | D9: Start Time (Date & Time) | E9: Completion time (Date & Time) | F9: Number of Hours | G9: Actual Number of Hours | H9: Amount | I9: Location
A10: Solom Magagula | B10: 76428819 | C10: 45965 | D10: 7h15 | E10: 8h15 | G10: 1 | H10: =G10*200 -> 200
A11: Nkomo Nelson | B11: 78179944 | C11: 45965 | D11: 8h40 | E11: 9h40 | G11: 1 | H11: =G11*200 -> 200
A12: Nkomo Lindiwe | B12: 76898410 | C12: 45965 | D12: 10h00 | E12: 11h00 | G12: 1 | H12: =G12*200 -> 200
A13: Lucky Gumedze | B13: 76860207 | C13: 45965 | D13: 11h15 | E13: 12h15 | G13: 1 | H13: =G13*200 -> 200
A14: Nozipho Luhlanga | B14: 78052181 | C14: 45965 | D14: 13h30 | E14: 14h30 | G14: 1 | H14: =G14*200 -> 200
A15: Gumedze Tfobhi | B15: 76733059 | C15: 45965 | D15: 15h30 | E15: 16h30 | G15: 1 | H15: =G15*200 -> 200
A16: Malambe Thabile | B16: 79957449 | C16: 45967 | D16: 6h10 | E16: 7h10 | G16: 1 | H16: =G16*200 -> 200
A17: Dlamini Ncamsile | B17: 78544328 | C17: 45967 | D17: 8h00 | E17: 9h00 | G17: 1 | H17: =G17*200 -> 200
A18: Mhlanga Tapede | B18: 76707757 | C18: 45967 | D18: 9h15 | E18: 10h15 | G18: 1 | H18: =G18*200 -> 200
A19: Mgabhi Mhlengi | B19: 76510530 | C19: 45967 | D19: 11h40 | E19: 12h40 | G19: 1 | H19: =G19*200 -> 200
A20: Mvubu Cebile | B20: 78285149 | C20: 45967 | D20: 13h35 | E20: 14h35 | G20: 1 | H20: =G20*200 -> 200
A21: Mvubu Sikelela | B21: 76146460 | C21: 45967 | D21: 16h10 | E21: 5h10 | G21: 1 | H21: =G21*200 -> 200
... A24: Dlamini Lindiwe | B24: 78116403 | C24: 45968 | D24: 9h40 | E24: 10h40 | G24: 1 | H24: =G24*200 -> 200
A25: Mahlalela Amose | C25: 45968 | D25: 11h10 | E25: 12h10 | G25: 1 | H25: =G25*200 -> 200
A26: Mahlalela Velaphi | C26: 45968 | D26: 14h00 | E26: 15h00 | G26: 1 | H26: =G26*200 -> 200
A27: Gumede Sabelo | C27: 45970 | D27: 8h00 | E27: 9h00 | G27: 1 | H27: =G27*200 -> 200
A28: Nkomo Moses | C28: 45970 | D28: 9h30 | E28: 10h30 | G28: 1 | H28: =G28*200 -> 200
A29: Mhlanga Sikhulile | B29: 76814493 | C29: 45970 | D29: 11h15 | E29: 12h15 | G29: 1 | H29: =G29*200 -> 200
A30: Magagula Nomfundo | B30: 76117266 | C30: 45970 | D30: 14h00 | E30: 15h00 | G30: 1 | H30: =G30*200 -> 200
A31: Sifundza Winile | B31: 78462122 | C31: 45970 | D31: 16h20 | E31: 17h20 | G31: 1 | H31: =G31*200 -> 200
A32: Mhlanga Majahonkhe | B32: 76952483 | C32: 45970 | D32: 17h30 | E32: 18h30 | G32: 1 | H32: =G32*200 -> 200
A33: Mngometulu Noxolo | C33: 45970 | D33: 6h40 | E33: 19h40 | G33: 1 | H33: =G33*200 -> 200
A34: Matsebula Ntombi | B34: 78469406 | C34: 45975 | D34: 10h00 | E34: 11h00 | G34: 1 | H34: =G34*200 -> 200
A35: Gumedze Sibonanga | B35: 76745159 | C35: 45975 | D35: 12h00 | E35: 13h00 | G35: 1 | H35: =G35*200 -> 200
A36: Magagula Mandla | B36: 78726329 | C36: 45975 | D36: 15h15 | E36: 16h00 | G36: 1 | H36: =G36*200 -> 200
A37: Mvubu Samkelisiwe | B37: 76317289 | C37: 45975 | D37: 17h09 | E37: 18h09 | G37: 1 | H37: =G37*200 -> 200
A38: Gumedze Mhawu | B38: 76470323 | C38: 45976 | D38: 7h30 | E38: 8h30 | G38: 1 | H38: =G38*200 -> 200
A39: Mhlanga Zodwa | B39: 76259686 | C39: 45976 | D39: 11h45 | E39: 12h40 | G39: 1 | H39: =G39*200 -> 200
A40: Gumedze Shushomba | B40: 78262359 | C40: 45983 | D40: 11h00 | E40: 12h00 | G40: 1 | H40: =G40*200 -> 200
A41: Zodwa Lubhedze | C41: 45983 | D41: 14h15 | E41: 15h10 | G41: 1 | H41: =G41*200 -> 200
A42: Gcebile Hlatjwako | B42: 76859261 | C42: 45983 | D42: 16h00 | E42: 17h00 | G42: 1 | H42: =G42*200 -> 200
A43: Malambe Khombisile | B43: 78874674 | C43: 45986 | D43: 13h00 | E43: 14h00 | G43: 1 | H43: =G43*200 -> 200
A44: Lencane Mdambe | B44: 76995162 | C44: 45986 | D44: 14h15 | E44: 15h00 | G44: 1 | H44: =G44*200 -> 200
...

Sheet Lushikishini
A1: ICBC Ploughing Project
B2: COMPLETE - NMC
A3: Name of ICBC: | B3: Lushikishini ICBC | E3: Name of Pastor | F3: Phumzile Dlamini
A4: Contractor's Full Name | B4: National Maize Corporation | E4: Contractor's ID Number
A5: Bank | E5: Account Holder's Name
A6: Branch Code | E6: Account Number
A9: Community Member’s Name & Surname | B9: Contact Details | C9: Date | D9: Start Time (Date & Time) | E9: Completion time (Date & Time) | F9: Number of Hours | G9: Actual Number of Hours | H9: Amount | I9: Location
A10: Mazibuko Sipho | B10: 7633447 | F10: 2 | G10: 2 | H10: =G10*200 -> 400
A11: Hlophe Sibongile | B11: 76274234 | F11: 2 | G11: 2 | H11: =G11*200 -> 400
A12: Shongwe Thabile | B12: 78542803 | F12: 2 | G12: 2 | H12: =G12*200 -> 400
A13: Hlophe Saulinah | B13: 78437795 | F13: 1 | G13: 1 | H13: =G13*200 -> 200
A14: Mdluli Gladys | B14: 76914263 | F14: 3 | G14: 3 | H14: =G14*200 -> 600
A15: Motsa Mavis | B15: 76419290 | F15: 1 | G15: 1 | H15: =G15*200 -> 200
A16: Hlophe Lomacala | B16: 76794648 | F16: 1 | G16: 1 | H16: =G16*200 -> 200
A17: Hlophe Lomacala | B17: 76794648 | F17: 2 | G17: 2 | H17: =G17*200 -> 400
A18: Ndlovu Matilda | B18: 76606547 | F18: 2 | G18: 2 | H18: =G18*200 -> 400
A19: Mabuza Sibongile | B19: 76727653 | F19: 4 | G19: 4 | H19: =G19*200 -> 800
A20: Nzimandze Cebsile | B20: 78775945 | F20: 1 | G20: 1 | H20: =G20*200 -> 200
A21: Maseko Vusi | B21: 76830090 | F21: 2 | G21: 2 | H21: =G21*200 -> 400
... A30: Nompumelelo Dlamini | B30: 76297184 | F30: 2 | G30: 2 | H30: =G30*200 -> 400
E31: Total | F31: =SUM(F10:F29) -> 33 | G31: =SUM(G10:G29) -> 33 | H31: =SUM(H10:H30) -> 7000
E32: Total number of fields ploughed | F32: =COUNT(G2:G30) -> 21
D34: Checked By
D35: Signature
D36: Date

Sheet Mangcongco
A1: ICBC Ploughing Project
B2: Completed
A3: Name of ICBC: | B3: Mangcongco ICBC | E3: Name of Pastor | F3: Ndumiso Dlamini
A5: Contractor | B5: Hlezephi Gugu Hlatjwako | E5: Contractor's ID Number
A6: Bank | B6: First National Bank | E6: Account Holder's Name | F6: Swaziland Building Society
A7: Branch Code | E7: Account Number | F7: 62121264212
A9: Contractor | E9: Account Holder's Name
A10: Bank | E10: Account Number
A12: Community Member’s Name & Surname | B12: Contact Details | C12: Date | D12: Start Time (Date & Time) | E12: Completion time (Date & Time) | F12: Number of Hours | G12: Actual Number of Hours | H12: Amount | I12: Location
A13: NDUMISO DLAMINI | B13: 76766982 | C13: 45758 | D13: 0500HRS | E13: 0700HRS | G13: 2 | H13: =G13*200 -> 400
A14: LANGA ZWANE | B14: 76910294 | C14: 45758 | D14: 0720HRS | E14: 0815HRS | G14: 0.9 | H14: =G14*200 -> 180
A15: BHEKIE KUNENE | B15: 76674700 | C15: 45758 | D15: 0820HRS | E15: 1020HRS | G15: 2 | H15: =G15*200 -> 400
A16: JABULANI ZIKALALA | B16: 76532375 | C16: 45758 | D16: 1025HRS | E16: 1225HRS | G16: 2 | H16: =G16*200 -> 400
A17: SOFIE MAMBA | B17: 76337303 | C17: 45758 | D17: 1230HRS | E17: 1330HRS | G17: 1 | H17: =G17*200 -> 200
A18: MEBRA ZIKALALA | B18: 76033446 | C18: 45758 | D18: 1335HRS | E18: 1435HRS | G18: 1 | H18: =G18*200 -> 200
A19: ENOCK ZWANE | B19: 76784295 | C19: 45758 | D19: 1400HRS | E19: 1420HRS | G19: 2 | H19: =G19*200 -> 400
A20: MPHOHLO MABUZA | B20: 76404190 | C20: 45758 | D20: 1640HRS | E20: 1845HRS | G20: 2 | H20: =G20*200 -> 400
A21: THEMBA ZWANE | B21: 76421169 | C21: 45758 | D21: 1900HRS | E21: 2100HRS | G21: 2 | H21: =G21*200 -> 400
A22: NTOKOZO ZIKALALA | B22: 76792418 | C22: 45788 | D22: 2105HRS | E22: 2305HRS | G22: 2 | H22: =G22*200 -> 400
A23: SARAH MAMBA | B23: 76726340 | C23: 45788 | D23: 0500HRS | E23: 0600HRS | G23: 1 | H23: =G23*200 -> 200
A24: SIKUPHI DVUBA | B24: 76910294 | C24: 45788 | D24: 0620HRS | E24: 0720HRS | G24: 1 | H24: =G24*200 -> 200
... A47: SAKAHMUZI ZIKALALA | B47: 76516334 | C47: 45849 | D47: 2240HRS | E47: 2340HRS | G47: 1 | H47: =G47*200 -> 200
H48: =G48*200 -> 0
H49: =G49*200 -> 0
H50: =G50*200 -> 0
E51: Total | F51: =SUM(F12:F50) -> 0 | G51: =SUM(G1:G50) -> 50.7 | H51: =SUM(H12:H50) -> 10140
E52: Total number of fields ploughed | F52: =COUNT(G16:G50) -> 32
D54: Checked By
D56: Signature
D58: Date

Sheet Mabhukwini
A1: ICBC Ploughing Project
B2: Completed
A3: Name of ICBC: | B3: Mabhukwini ICBC | E3: Name of Pastor | F3: Dumisani Ernest Dlamini
A5: Contractor | E5: Contractor's ID Number
A6: Bank | E6: Account Holder's Name
A7: Branch Code | E7: Account Number
A12: Community Member’s Name & Surname | B12: Contact Details | C12: Date | D12: Start Time (Date & Time) | E12: Completion time (Date & Time) | F12: Number of Hours | G12: Actual Number of Hours | H12: Amount | I12: Location
A13: Sabelo Matsebula | B13: 76783160 | C13: 45966 | G13: 2 | H13: =G13*200 -> 400
A14: Make laMthembu | B14: 78261309 | C14: 45967 | G14: 2 | H14: =G14*200 -> 400
A15: Nonhlanhla Makhubu | B15: 78361597 | C15: 45968 | G15: 1 | H15: =G15*200 -> 200
A16: Umphakatsi | C16: 45969 | G16: 1 | H16: =G16*200 -> 200
A17: Sarah Dube | C17: 45970 | G17: 1 | H17: =G17*200 -> 200
A18: Mbhamu Ngozo | B18: 76141577 | C18: 45968 | G18: 1 | H18: =G18*200 -> 200
A19: Thailah Ngozo | B19: 76657462 | C19: 45968 | G19: 3 | H19: =G19*200 -> 600
A20: Xolani Ngozo | B20: 76083659 | C20: 45968 | G20: 2 | H20: =G20*200 -> 400
A21: Mthunzi Maseko | B21: 76531093 | C21: 45968 | G21: 2 | H21: =G21*200 -> 400
A22: Mlembe Ngozo | B22: 76523854 | C22: 45968 | G22: 1 | H22: =G22*200 -> 200
A23: Makhiwa Dlamini | B23: 76364990 | C23: 45968 | G23: 1 | H23: =G23*200 -> 200
A24: Polycup Dlamini | B24: 76759301 | C24: 45968 | G24: 2 | H24: =G24*200 -> 400
A25: Victoria Dlamini | B25: 76657375 | C25: 45968 | G25: 2 | H25: =G25*200 -> 400
A26: Elizabeth Zikalala | B26: 76428815 | C26: 45969 | G26: 1 | H26: =G26*200 -> 200
A27: Nondumiso ndlangamandla | B27: 76428815 | C27: 45969 | G27: 1 | H27: =G27*200 -> 200
A28: Bheki Sibisi | B28: 76702262 | C28: 45969 | G28: 1 | H28: =G28*200 -> 200
A29: Iren Mntjali | B29: 76694104 | C29: 45969 | G29: 2 | H29: =G29*200 -> 400
... A39: Bertina Ntjangase | B39: 78338332 | C39: 45970 | G39: 2 | H39: =G39*200 -> 400
A40: Dumsani Dlamini | B40: 76213717 | G40: 2 | H40: =G40*200 -> 400
A41: Thembi Dlamini | B41: 76793001 | G41: 2 | H41: =G41*200 -> 400
A42: Evelyn Ndzimandze | B42: 76182674 | G42: 2 | H42: =G42*200 -> 400
A43: Samkelo Ngozo | B43: 76285055 | G43: 4 | H43: =G43*200 -> 800
A44: Jabulani Ngozo | B44: 76344590 | G44: 2 | H44: =G44*200 -> 400
A45: Phumzile Ngozo | B45: 76344590 | G45: 1 | H45: =G45*200 -> 200
A46: Londi Kheswa | B46: 76424714 | G46: 2 | H46: =G46*200 -> 400
H47: =G47*200 -> 0
E48: Total | F48: =SUM(F12:F47) -> 0 | G48: =SUM(G1:G47) -> 55 | H48: =SUM(H12:H47) -> 11000
E49: Total number of fields ploughed | F49: =COUNT(G13:G47) -> 34
D51: Checked By
D53: Signature
D55: Date

Sheet Makhungutja
A1: ICBC Ploughing Project
B2: Completed
A3: Name of ICBC: | B3: Makhungutja ICBC | E3: Name of Pastor | F3: Simphiwe Jele
A5: Contractor | B5: Sambane Multi-purpose | E5: Contractor's ID Number
A6: Bank | B6: Nedbank | E6: Account Holder's Name | F6: Sambane multi-purpose
A7: Branch Code | E7: Account Number | F7: 12990142112
A12: Community Member’s Name & Surname | B12: Contact Details | C12: Date | D12: Start Time (Date & Time) | E12: Completion time (Date & Time) | F12: Number of Hours | G12: Actual Number of Hours | H12: Amount | I12: Location
A13: Twana Malinga | B13: 76891635 | C13: 45922 | D13: 7:09AM | E13: 10:10AM | F13: 3 | G13: 3 | H13: =G13*200 -> 600
A14: Lindiwe Malinga | B14: 76603119 | F14: 1 | G14: 1 | H14: =G14*200 -> 200
A15: Constance Manyatsi | B15: 76561923 | F15: 1 | G15: 1 | H15: =G15*200 -> 200
A16: Nonsikelelo Dludlu | B16: 76409879 | F16: 1 | G16: 1 | H16: =G16*200 -> 200
A17: Bafana Dlamini | B17: 76713052 | F17: 3 | G17: 3 | H17: =G17*200 -> 600
A18: Margret Hlophe | B18: 76924611 | F18: 2 | G18: 2 | H18: =G18*200 -> 400
A19: Nhlanhla Vilakati | B19: 76194923 | F19: 2 | G19: 2 | H19: =G19*200 -> 400
A20: Musa Vilakati | B20: 76302463 | F20: 1 | G20: 1 | H20: =G20*200 -> 200
A21: Sipho Dlamini | B21: 76588373 | F21: 1 | G21: 1 | H21: =G21*200 -> 200
A22: Nkonzo Mabeleza | B22: 76424583 | F22: 2 | G22: 2 | H22: =G22*200 -> 400
A23: Ntokozo Zwane | B23: 7627298 | F23: 2 | G23: 2 | H23: =G23*200 -> 400
A24: Boy Vilakati | B24: 76424583 | F24: 1 | G24: 1 | H24: =G24*200 -> 200
A25: Thabani Hlophe | B25: 78386148 | F25: 2 | G25: 2 | H25: =G25*200 -> 400
... A39: Nelile Phakathi | B39: 78364019 | F39: 1 | G39: 1 | H39: =G39*200 -> 200
H40: =G40*200 -> 0
H41: =G41*200 -> 0
H42: =G42*200 -> 0
H43: =G43*200 -> 0
H44: =G44*200 -> 0
H45: =G45*200 -> 0
H46: =G46*200 -> 0
H47: =G47*200 -> 0
E48: Total | F48: =SUM(F12:F47) -> 50 | G48: =SUM(G1:G47) -> 50 | H48: =SUM(H12:H47) -> 10000
E49: Total number of fields ploughed | F49: =COUNT(G13:G47) -> 27
D51: Checked By
D53: Signature
D55: Date

Sheet Mantabeni
A1: ICBC Ploughing Project
B2: Completed
A3: Name of ICBC: | B3: Mantabeni ICBC | E3: Name of Pastor | F3: Bongani Titus Dlamini
A5: Contractor | B5: Ayanda Buhle Dlamini | E5: Contractor's ID Number | F5: 8609186100491
A6: Bank | B6: NEDBANK | E6: Account Holder's Name | F6: Ayanda Buhle Dlamini
A7: Branch Code | B7: 36064 | E7: Account Number | F7: 12991495442
A10: Community Member’s Name & Surname | B10: Contact Details | C10: Date | D10: Start Time (Date & Time) | E10: Completion time (Date & Time) | F10: Number of Hours | G10: Actual Number of Hours | H10: Amount | I10: Location
A11: Johannes Hlophe | B11: 76143027 | C11: 45966 | D11: 0.22222222 | E11: 0.30555556 | G11: 2.5 | H11: =G11*200 -> 500
A12: Boy Nhlabatsi | B12: 76724624 | C12: 45966 | D12: 0.30555556 | E12: 0.36805556 | G12: 1.5 | H12: =G12*200 -> 300
A13: Charity Hlophe | B13: 76628080 | C13: 45966 | D13: 0.375 | E13: 0.4375 | G13: 1.5 | H13: =G13*200 -> 300
A14: Mario Nhlabatsi | B14: 76264577 | C14: 45966 | D14: 0.4375 | E14: 0.45833333 | G14: 0.5 | H14: =G14*200 -> 100
A15: Elizabeth Nhlabatsi | B15: 78285723 | C15: 45966 | D15: 0.47916667 | E15: 0.52083333 | G15: 1 | H15: =G15*200 -> 200
A16: Gogo Nkhambule | B16: 76264419 | C16: 45966 | D16: 0.52083333 | E16: 0.5625 | G16: 1 | H16: =G16*200 -> 200
A17: Veronica Mabaso | B17: 76042627 | C17: 45967 | D17: 0.20138889 | E17: 0.28472222 | G17: 2 | H17: =G17*200 -> 400
A18: Thembinkosi Mabaso | B18: 76370003 | C18: 45967 | D18: 0.28819444 | E18: 0.35416667 | G18: 1.5 | H18: =G18*200 -> 300
A19: Duma Mamba | B19: 76224672 | C19: 45967 | D19: 0.35763889 | E19: 0.44097222 | G19: 2 | H19: =G19*200 -> 400
A20: Nomsa Lokotfwako | B20: 76732931 | C20: 45967 | D20: 0.45833333 | E20: 0.52083333 | G20: 1.5 | H20: =G20*200 -> 300
A21: Lomagugu Mabaso | B21: 76250317 | C21: 45967 | D21: 0.54166667 | E21: 0.60416667 | G21: 1.5 | H21: =G21*200 -> 300
A22: Gladys Dlamini | B22: 78259902 | C22: 45967 | D22: 0.61458333 | E22: 0.65625 | G22: 1 | H22: =G22*200 -> 200
A23: Sarah Lokotfwako | C23: 45968 | D23: 0.20138889 | E23: 0.24305556 | G23: 1 | H23: =G23*200 -> 200
A24: Samkeliso Lokotfwako | B24: 78267330 | C24: 45968 | D24: 0.25 | E24: 0.29166667 | G24: 1 | H24: =G24*200 -> 200
A25: Mhlatase Lokotfwako | C25: 45968 | D25: 0.30208333 | E25: 0.32291667 | G25: 0.5 | H25: =G25*200 -> 100
A26: Thulisile Dlamini | C26: 45968 | D26: 0.32638889 | E26: 0.34722222 | G26: 0.5 | H26: =G26*200 -> 100
A27: Compton Nhlabatsi | B27: 76429862 | C27: 45968 | D27: 0.34722222 | E27: 0.38888889 | G27: 1 | H27: =G27*200 -> 200
A28: Ntombifuthi Nhlabatsi | C28: 45968 | D28: 0.40625 | E28: 0.44791667 | G28: 1 | H28: =G28*200 -> 200
A29: Gogo Hlophe | C29: 45968 | D29: 0.45833333 | E29: 0.52083333 | G29: 1.5 | H29: =G29*200 -> 300
A30: Bongiwe Gama | B30: 76610850 | C30: 45968 | D30: 0.54166667 | E30: 0.58333333 | G30: 1 | H30: =G30*200 -> 200
A31: Letsiwe Ngwenya | B31: 76634977 | C31: 45969 | D31: 0.22916667 | E31: 0.27083333 | G31: 1 | H31: =G31*200 -> 200
A32: Gogo Ngomane | B32: 78121261 | C32: 45969 | D32: 0.27430556 | E32: 0.35763889 | G32: 2 | H32: =G32*200 -> 400
A33: Phindile Zwane | B33: 79719761 | C33: 45969 | D33: 0.36111111 | E33: 0.42361111 | G33: 1.5 | H33: =G33*200 -> 300
A34: Gogo Nhlabatsi | C34: 45969 | D34: 0.42708333 | E34: 0.44791667 | G34: 0.5 | H34: =G34*200 -> 100
A35: Xolani Nhlabatsi | B35: 79710470 | C35: 45969 | D35: 0.45138889 | E35: 0.49305556 | G35: 0.5 | H35: =G35*200 -> 100
A36: Musa Nhlabatsi | C36: 45969 | D36: 0.47916667 | E36: 0.5625 | G36: 1.5 | H36: =G36*200 -> 300
A37: Senzo Dlamini | B37: 76725660 | C37: 45969 | D37: 0.56597222 | E37: 0.60763889 | G37: 1 | H37: =G37*200 -> 200
A38: Nomthantazo Lokotfwako | B38: 76369541 | C38: 45969 | D38: 0.60763889 | E38: 0.64930556 | G38: 1 | H38: =G38*200 -> 200
A39: Thabsile Msibi | B39: 76222932 | C39: 45969 | D39: 0.65277778 | E39: 0.71527778 | G39: 1.5 | H39: =G39*200 -> 300
A40: Lungile Lokotfwako | B40: 76380900 | C40: 45969 | D40: 0.71875 | E40: 0.78125 | G40: 1.5 | H40: =G40*200 -> 300
A41: Lobetswane Fakudze | B41: 76552937 | C41: 45971 | D41: 0.21527778 | E41: 0.27777778 | G41: 1.5 | H41: =G41*200 -> 300
A42: Thembi Hlophe | B42: 76342002 | C42: 45971 | D42: 0.27777778 | E42: 0.34027778 | G42: 1.5 | H42: =G42*200 -> 300
A43: Nozizwe Lokotfwako | B43: 79912731 | C43: 45971 | D43: 0.36111111 | E43: 0.42361111 | G43: 1.5 | H43: =G43*200 -> 300
...

Sheet Mbowane
A1: ICBC Ploughing Project
B2: Not Started
A3: Name of ICBC: | C3: Mbowane ICBC | F3: Name of Pastor | G3: Bongani Mngometulu
A4: Contractor's Full Name | C4: Rose Vilane | F4: Contractor's ID Number
A5: Bank | C5: Standard Bank | F5: Account Holder's Name | G5: Rose Vilane
A6: Branch Code | C6: Nhlangano code | F6: Account Number | G6: 9110002635588
A9: Community Member’s Name & Surname | C9: Contact Details | D9: Date | E9: Start Time (Date & Time) | F9: Completion time (Date & Time) | G9: Number of Hours | H9: Actual Number of Hours | I9: Amount | J9: Location
I10: =H10*200 -> 0
I11: =H11*200 -> 0
I12: =H12*200 -> 0
I13: =H13*200 -> 0
I14: =H14*200 -> 0
I15: =H15*200 -> 0
I16: =H16*200 -> 0
I17: =H17*200 -> 0
I18: =H18*200 -> 0
I19: =H19*200 -> 0
I20: =H20*200 -> 0
I21: =H21*200 -> 0
... I43: =H43*200 -> 0
I44: =H44*200 -> 0 | K44: Only One Hour and had registered for 2
I45: =H45*200 -> 0
F46: Total | G46: =SUM(G9:G45) -> 0 | H46: =SUM(H9:H45) -> 0 | I46: =SUM(I9:I45) -> 0
F47: Total number of fields ploughed | G47: =COUNT(G10:G45) -> 0
E49: Checked By
E50: Signature
E51: Date

Sheet Mcuba
A1: ICBC Ploughing Project
B2: Completed
A3: Name of ICBC: | B3: Mcuba ICBC | E3: Name of Pastor | F3: Johannes Ndwandwe
A4: Contractor's Full Name | B4: Vulamehlo Zinyane Co-ops | E4: Contractor's Number | F4: 76035013
A5: Bank | B5: Eswatini Bank | E5: Account Holder's Name | F5: Vulamehlo Zinyane Co-ops
A6: Branch Code | B6: Piggs Peak | E6: Account Number | F6: 77400342329
A9: Community Member’s Name & Surname | B9: Contact Details | C9: Date | D9: Start Time (Date & Time) | E9: Completion time (Date & Time) | F9: Number of Hours | G9: Actual Number of Hours | H9: Amount | I9: Location
A10: Jabulile Kunene | B10: 78377220 | C10: 45819 | D10: 0.22916667 | E10: 0.79166667 | G10: 2 | H10: =G10*200 -> 400
A11: Gogo Vilane | B11: 79712516 | G11: 2 | H11: =G11*200 -> 400
A12: Gwadi Kunene | B12: 76343055 | G12: 2 | H12: =G12*200 -> 400
A13: Wenzile Shongwe | B13: 78352959 | G13: 1 | H13: =G13*200 -> 200
A14: Theyila Shongwe | G14: 1 | H14: =G14*200 -> 200
A15: LaMabuza | B15: 76235018 | G15: 1 | H15: =G15*200 -> 200
A16: Twie Dlamini | B16: 79118050 | G16: 1 | H16: =G16*200 -> 200
A17: LaNdwandwe | B17: 76954442 | G17: 1 | H17: =G17*200 -> 200
A18: LaNhlabatsi | B18: 76613276 | G18: 1 | H18: =G18*200 -> 200
A19: Make LaNkhosi | G19: 1 | H19: =G19*200 -> 200
A20: LaZikalala | B20: 76859262 | C20: 45849 | D20: 0.22916667 | E20: 0.79166667 | G20: 4 | H20: =G20*200 -> 800
A21: Nabontombi | B21: 76284381 | G21: 1 | H21: =G21*200 -> 200
A22: Makwa Nigray | G22: 2 | H22: =G22*200 -> 400
A23: Tenele Tsabedze | B23: 78578986 | G23: 1 | H23: =G23*200 -> 200
A24: Make LaGumedze | B24: 78578986 | G24: 1 | H24: =G24*200 -> 200
A25: Mfana Sibili | B25: 76149164 | G25: 1 | H25: =G25*200 -> 200
A26: Nabojuba | B26: 7883337 | G26: 3 | H26: =G26*200 -> 600
A27: Majaha Masilela | B27: 78552779 | G27: 1 | H27: =G27*200 -> 200
A28: Nonhlanhla | B28: 76118477 | G28: 2 | H28: =G28*200 -> 400
A29: Tipa Shongwe | C29: 45880 | D29: 0.22916667 | E29: 0.79166667 | G29: 1 | H29: =G29*200 -> 200
A30: Phasika | G30: 1 | H30: =G30*200 -> 200
A31: Simon Shongwe | B31: 78713285 | G31: 1 | H31: =G31*200 -> 200
A32: LaMnisi | G32: 1 | H32: =G32*200 -> 200
A33: LaHlophe | B33: 76833915 | G33: 1 | H33: =G33*200 -> 200
A34: Nathi Shabangu | B34: 76240754 | G34: 1 | H34: =G34*200 -> 200
A35: Msehleni Magagula | B35: 76214183 | G35: 4 | H35: =G35*200 -> 800
A36: Nomen Tsabedze | B36: 78432764 | G36: 1 | H36: =G36*200 -> 200
A37: Bheki Masilela | B37: 76718374 | G37: 1 | H37: =G37*200 -> 200
A38: Bheki Matsebula | B38: 78030125 | G38: 2 | H38: =G38*200 -> 400
A39: Futhi | B39: 76535817 | C39: 45911 | D39: 0.22916667 | E39: 0.79166667 | G39: 1 | H39: =G39*200 -> 200
A40: Nhlanhla Tsabedze | B40: 76890879 | G40: 2 | H40: =G40*200 -> 400
A41: Njalo | B41: 79520911 | G41: 1 | H41: =G41*200 -> 200
A42: Bongani Tsabedze | B42: 76890879 | G42: 1 | H42: =G42*200 -> 200
...

Sheet Mlindazwe
A1: ICBC Ploughing Project
B2: Completed
A3: Name of ICBC: | B3: Mlindazwe ICBC | E3: Name of Pastor | F3: Phendulile Mlangeni
A4: Contractor's Full Name | B4: Tryphina Khumalo | E4: Contractor's ID Number
A5: Bank | B5: Standard Bank | E5: Account Holder's Name | F5: Mlangeni Phendulile Busisiwe
A6: Branch Code | B6: 660564 | E6: Account Number | F6: 9110001240997
A7: Swift Code | B7: SBICSZMX
A9: Community Member’s Name & Surname | B9: Contact Details | C9: Date | D9: Start Time (Date & Time) | E9: Completion time (Date & Time) | F9: Number of Hours | G9: Actual Number of Hours | H9: Amount | I9: Location
A10: Church Field | B10: 76111660 | C10: 1.11.25 | D10: 0.23611111 | E10: 0.27777778 | G10: 1 | H10: =200*G10 -> 200
A11: Umphakatsi | B11: 76518850 | C11: 1.11.25 | D11: 0.41666667 | E11: 0.45833333 | G11: 1 | H11: =200*G11 -> 200
A12: Mlindazwe High | B12: 76053757 | C12: 1.11.25 | D12: 0.32638889 | E12: 0.40972222 | G12: 2 | H12: =200*G12 -> 400
A13: Gogo Zwane Ngwenya (Ntuthuko) | B13: 76197465 | C13: 2.11.25 | D13: 0.33333333 | E13: 0.375 | G13: 1 | H13: =200*G13 -> 200
A14: Dlamini Jabu kamake Nelly | B14: 76535056 | C14: 3.11.25 | D14: 0.20833333 | E14: 0.29166667 | G14: 2 | H14: =200*G14 -> 400
A15: laMndzebele kaZwane | B15: 76516372 | C15: 4.11.25 | D15: 0.29166667 | E15: 0.375 | G15: 2 | H15: =200*G15 -> 400
A16: Make Masuku | B16: 78663241 | C16: 17.11.25 | D16: 0.22916667 | E16: 0.27083333 | G16: 1 | H16: =200*G16 -> 200
A17: LaNkhosi Zwane | C17: 4.11.25 | D17: 0.45833333 | E17: 0.54166667 | G17: 2 | H17: =200*G17 -> 400
A18: Masuku Ndoda | B18: 76549107 | C18: 1.11.25 | D18: 0.41666667 | E18: 0.54166667 | G18: 3 | H18: =200*G18 -> 600
A19: Zwane babe Mphumulo | B19: 76663848 | C19: 5.11.25 | D19: 0.25 | E19: 0.33333333 | G19: 2 | H19: =200*G19 -> 400
A20: Dolane Masuku | C20: 7.11.25 | D20: 0.24652778 | E20: 0.32986111 | G20: 2 | H20: =200*G20 -> 400
A21: Malumeza Dlamini | B21: 78140211 | C21: 7.11.25 | D21: 0.34375 | E21: 0.42708333 | G21: 2 | H21: =200*G21 -> 400
A22: laGama ka Nkunku | C22: 7.11.25 | D22: 0.47569444 | E22: 0.51736111 | G22: 1 | H22: =200*G22 -> 200
A23: Gogo Ncomu | C23: 7.11.25 | D23: 0.43055556 | E23: 0.47222222 | G23: 1 | H23: =200*G23 -> 200
A24: Zwane LaMazibuko | B24: 78315049 | C24: 6.11.25 | D24: 0.64652778 | E24: 0.72986111 | G24: 2 | H24: =200*G24 -> 400
A25: Zwane Gogo Mamba | C25: 7.11.25 | D25: 0.55694444 | E25: 0.64027778 | G25: 2 | H25: =200*G25 -> 400
A26: Dladla | C26: 7.11.25 | D26: 0.675 | E26: 0.71666667 | G26: 1 | H26: =200*G26 -> 200
A27: KaNkhosi khabo Mumcy | C27: 5.11.25 | D27: 0.45833333 | E27: 0.5 | G27: 1 | H27: =200*G27 -> 200
A28: Gogo Shiba Zwane | B28: 76439925 | C28: 6.11.25 | D28: 0.57013889 | E28: 0.61180556 | G28: 1 | H28: =200*G28 -> 200
A29: LaMkhonta Zwane | B29: 76065685 | C29: 8.11.25 | D29: 0.27083333 | E29: 0.39583333 | G29: 3 | H29: =200*G29 -> 600
A30: Zwane Thobisani | B30: 76179671 | C30: 6:11;25 | D30: 0.39930556 | E30: 0.48263889 | G30: 2 | H30: =200*G30 -> 400
A31: Zwane Gogo Dludlu | B31: 76414337 | C31: 5.11.25 | D31: 0.50347222 | E31: 0.58680556 | G31: 2 | H31: =200*G31 -> 400
A32: Gogo Phakathi | B32: 78112938 | C32: 5.11.25 | D32: 0.59722222 | E32: 0.63888889 | G32: 1 | H32: =200*G32 -> 200
A33: Gogo Seyama | C33: 5.11.25 | D33: 0.64583333 | E33: 0.6875 | G33: 1 | H33: =200*G33 -> 200
A34: Seyama Mfanzile | B34: 76655380 | C34: 6.11.25 | D34: 0.48958333 | E34: 0.57291667 | G34: 2 | H34: =200*G34 -> 400
A35: Mgabhi LaJele | B35: 76570795 | C35: 8.11.25 | D35: 0.22638889 | E35: 0.30972222 | G35: 2 | H35: =200*G35 -> 400
A36: Magutjwa | B36: 76403785 | C36: 22.11.25 | D36: 0.30208333 | E36: 0.34375 | G36: 1 | H36: =200*G36 -> 200
A37: Make Mahlaba | B37: 76634524 | C37: 08:11;25 | D37: 0.51041667 | E37: 0.55208333 | G37: 1 | H37: =200*G37 -> 200
A38: Mnkomo | C38: 08.11.25 | D38: 0.625 | E38: 0.66666667 | G38: 1 | H38: =200*G38 -> 200
A39: Lokotfwako Khalebusuku | B39: 76616821 | C39: 17.11.25 | D39: 0.39583333 | E39: 0.4375 | G39: 1 | H39: =200*G39 -> 200
A40: Lokotfwako Lomathemba | B40: 76524972 | C40: 17.11.25 | D40: 0.29166667 | E40: 0.33333333 | G40: 1 | H40: =200*G40 -> 200
A41: Lokotfwako Zebulon | B41: 79608035 | C41: 17.11.25 | D41: 0.34375 | E41: 0.38541667 | G41: 1 | H41: =200*G41 -> 200
...

Sheet Mhlabubovu
A1: ICBC Ploughing Project
B2: In Progress - NMC
A3: Name of ICBC: | B3: Mhlabubovu ICBC | E3: Name of Pastor
A4: Contractor's Full Name | E4: Contractor's ID Number
A5: Bank | E5: Account Holder's Name
A6: Branch Code | E6: Account Number
A7: Swift Code
A9: Community Member’s Name & Surname | B9: Contact Details | C9: Date | D9: Start Time (Date & Time) | E9: Completion time (Date & Time) | F9: Number of Hours | G9: Actual Number of Hours | H9: Amount | I9: Location
A10: Ncamiso B Maziya | B10: 76992327 | C10: 45985 | F10: 3 | G10: 3 | H10: =G9:G10*200 -> 600
A11: Vuyisile Zikalala | B11: 78135724 | C11: 45995 | F11: 1 | G11: 2 | H11: =G10:G11*200 -> 400
A12: Nonhlanhla Maseko | B12: 76526942 | C12: 45972 | F12: 1 | G12: 1 | H12: =G11:G12*200 -> 200
A13: Xolile Zikalala | B13: 76186122 | C13: 45992 | F13: 1 | G13: 2 | H13: =G12:G13*200 -> 400
A14: Thabo Simelane | B14: 76202010 | C14: 45972 | F14: 1 | G14: 1 | H14: =G13:G14*200 -> 200
A15: Thoko Ndzimandze | B15: 76421454 | F15: 1 | G15: 1 | H15: =G14:G15*200 -> 200
