Workbook

Sheet Jul-24
D1: Number of Sundays | E1: 4 | S1: ICBC | T1: =+C7 -> Church Attendance: | U1: Adults | V1: Youth & Children | W1: Home Visits | X1: =+C12 -> Salvations
C3: Total ICBC | G3: 2024 | H3: =+G3 -> 2024 | I3: =+H3 -> 2024 | J3: =+I3 -> 2024 | K3: =+J3 -> 2024 | L3: =+K3 -> 2024 | M3: =+L3 -> 2024 | S3: =+C3 -> Total ICBC | T3: =+L7 -> 10013 | U3: =+L8+L9 -> 2329 | V3: =+L10+L11 -> 7684 | W3: =+L14 -> 534 | X3: =+L12 -> 142
C4: July 2024 | G4: Jul | H4: =+G4 -> Jul | I4: =+H4 -> Jul | J4: =+I4 -> Jul | K4: =+J4 -> Jul | L4: =+K4 -> Jul | M4: =+L4 -> Jul
G5: 7 | H5: 14 | I5: 21 | J5: 28 | K5: 0 | L5: Total | M5: Average
C7: Church Attendance: | G7: =SUM(G8:G11) -> 2459 | H7: =SUM(H8:H11) -> 2425 | I7: =SUM(I8:I11) -> 2644 | J7: =SUM(J8:J11) -> 2485 | K7: =SUM(K8:K11) -> 0 | L7: =SUM(L8:L11) -> 10013 | M7: =ROUND((L7/$E$1),0) -> 2503
D8: Men | G8: =+G24+G40+G56+G72+G88+G104+G120+G136+G152+G168+G184+G200+G216+G232+G248+G264+G280+G296+G312+G328+G344+G360+G376+G392+G408+G424+G440+G456+G472+G488+G504+G520+G536+G552+G568+G584+G600+G616+G632+G648+G664+G680+G696+G712+G728+G744+G760+G776+G792+G808 -> 167 | H8: =+H24+H40+H56+H72+H88+H104+H120+H136+H152+H168+H184+H200+H216+H232+H248+H264+H280+H296+H312+H328+H344+H360+H376+H392+H408+H424+H440+H456+H472+H488+H504+H520+H536+H552+H568+H584+H600+H616+H632+H648+H664+H680+H696+H712+H728+H744+H760+H776+H792+H808 -> 150 | I8: =+I24+I40+I56+I72+I88+I104+I120+I136+I152+I168+I184+I200+I216+I232+I248+I264+I280+I296+I312+I328+I344+I360+I376+I392+I408+I424+I440+I456+I472+I488+I504+I520+I536+I552+I568+I584+I600+I616+I632+I648+I664+I680+I696+I712+I728+I744+I760+I776+I792+I808 -> 161 | J8: =+J24+J40+J56+J72+J88+J104+J120+J136+J152+J168+J184+J200+J216+J232+J248+J264+J280+J296+J312+J328+J344+J360+J376+J392+J408+J424+J440+J456+J472+J488+J504+J520+J536+J552+J568+J584+J600+J616+J632+J648+J664+J680+J696+J712+J728+J744+J760+J776+J792+J808 -> 157 | K8: =+K24+K40+K56+K72+K88+K104+K120+K136+K152+K168+K184+K200+K216+K232+K248+K264+K280+K296+K312+K328+K344+K360+K376+K392+K408+K424+K440+K456+K472+K488+K504+K520+K536+K552+K568+K584+K600+K616+K632+K648+K664+K680+K696+K712+K728+K744+K760+K776+K792+K808 -> 0 | L8: =SUM(G8:K8) -> 635 | M8: =ROUND((L8/$E$1),0) -> 159
D9: Women | G9: =+G25+G41+G57+G73+G89+G105+G121+G137+G153+G169+G185+G201+G217+G233+G249+G265+G281+G297+G313+G329+G345+G361+G377+G393+G409+G425+G441+G457+G473+G489+G505+G521+G537+G553+G569+G585+G601+G617+G633+G649+G665+G681+G697+G713+G729+G745+G761+G777+G793+G809 -> 428 | H9: =+H25+H41+H57+H73+H89+H105+H121+H137+H153+H169+H185+H201+H217+H233+H249+H265+H281+H297+H313+H329+H345+H361+H377+H393+H409+H425+H441+H457+H473+H489+H505+H521+H537+H553+H569+H585+H601+H617+H633+H649+H665+H681+H697+H713+H729+H745+H761+H777+H793+H809 -> 412 | I9: =+I25+I41+I57+I73+I89+I105+I121+I137+I153+I169+I185+I201+I217+I233+I249+I265+I281+I297+I313+I329+I345+I361+I377+I393+I409+I425+I441+I457+I473+I489+I505+I521+I537+I553+I569+I585+I601+I617+I633+I649+I665+I681+I697+I713+I729+I745+I761+I777+I793+I809 -> 460 | J9: =+J25+J41+J57+J73+J89+J105+J121+J137+J153+J169+J185+J201+J217+J233+J249+J265+J281+J297+J313+J329+J345+J361+J377+J393+J409+J425+J441+J457+J473+J489+J505+J521+J537+J553+J569+J585+J601+J617+J633+J649+J665+J681+J697+J713+J729+J745+J761+J777+J793+J809 -> 394 | K9: =+K25+K41+K57+K73+K89+K105+K121+K137+K153+K169+K185+K201+K217+K233+K249+K265+K281+K297+K313+K329+K345+K361+K377+K393+K409+K425+K441+K457+K473+K489+K505+K521+K537+K553+K569+K585+K601+K617+K633+K649+K665+K681+K697+K713+K729+K745+K761+K777+K793+K809 -> 0 | L9: =SUM(G9:K9) -> 1694 | M9: =ROUND((L9/$E$1),0) -> 424
D10: Youth | G10: =+G26+G42+G58+G74+G90+G106+G122+G138+G154+G170+G186+G202+G218+G234+G250+G266+G282+G298+G314+G330+G346+G362+G378+G394+G410+G426+G442+G458+G474+G490+G506+G522+G538+G554+G570+G586+G602+G618+G634+G650+G666+G682+G698+G714+G730+G746+G762+G778+G794+G810 -> 619 | H10: =+H26+H42+H58+H74+H90+H106+H122+H138+H154+H170+H186+H202+H218+H234+H250+H266+H282+H298+H314+H330+H346+H362+H378+H394+H410+H426+H442+H458+H474+H490+H506+H522+H538+H554+H570+H586+H602+H618+H634+H650+H666+H682+H698+H714+H730+H746+H762+H778+H794+H810 -> 583 | I10: =+I26+I42+I58+I74+I90+I106+I122+I138+I154+I170+I186+I202+I218+I234+I250+I266+I282+I298+I314+I330+I346+I362+I378+I394+I410+I426+I442+I458+I474+I490+I506+I522+I538+I554+I570+I586+I602+I618+I634+I650+I666+I682+I698+I714+I730+I746+I762+I778+I794+I810 -> 668 | J10: =+J26+J42+J58+J74+J90+J106+J122+J138+J154+J170+J186+J202+J218+J234+J250+J266+J282+J298+J314+J330+J346+J362+J378+J394+J410+J426+J442+J458+J474+J490+J506+J522+J538+J554+J570+J586+J602+J618+J634+J650+J666+J682+J698+J714+J730+J746+J762+J778+J794+J810 -> 647 | K10: =+K26+K42+K58+K74+K90+K106+K122+K138+K154+K170+K186+K202+K218+K234+K250+K266+K282+K298+K314+K330+K346+K362+K378+K394+K410+K426+K442+K458+K474+K490+K506+K522+K538+K554+K570+K586+K602+K618+K634+K650+K666+K682+K698+K714+K730+K746+K762+K778+K794+K810 -> 0 | L10: =SUM(G10:K10) -> 2517 | M10: =ROUND((L10/$E$1),0) -> 629
D11: Children | G11: =+G27+G43+G59+G75+G91+G107+G123+G139+G155+G171+G187+G203+G219+G235+G251+G267+G283+G299+G315+G331+G347+G363+G379+G395+G411+G427+G443+G459+G475+G491+G507+G523+G539+G555+G571+G587+G603+G619+G635+G651+G667+G683+G699+G715+G731+G747+G763+G779+G795+G811 -> 1245 | H11: =+H27+H43+H59+H75+H91+H107+H123+H139+H155+H171+H187+H203+H219+H235+H251+H267+H283+H299+H315+H331+H347+H363+H379+H395+H411+H427+H443+H459+H475+H491+H507+H523+H539+H555+H571+H587+H603+H619+H635+H651+H667+H683+H699+H715+H731+H747+H763+H779+H795+H811 -> 1280 | I11: =+I27+I43+I59+I75+I91+I107+I123+I139+I155+I171+I187+I203+I219+I235+I251+I267+I283+I299+I315+I331+I347+I363+I379+I395+I411+I427+I443+I459+I475+I491+I507+I523+I539+I555+I571+I587+I603+I619+I635+I651+I667+I683+I699+I715+I731+I747+I763+I779+I795+I811 -> 1355 | J11: =+J27+J43+J59+J75+J91+J107+J123+J139+J155+J171+J187+J203+J219+J235+J251+J267+J283+J299+J315+J331+J347+J363+J379+J395+J411+J427+J443+J459+J475+J491+J507+J523+J539+J555+J571+J587+J603+J619+J635+J651+J667+J683+J699+J715+J731+J747+J763+J779+J795+J811 -> 1287 | K11: =+K27+K43+K59+K75+K91+K107+K123+K139+K155+K171+K187+K203+K219+K235+K251+K267+K283+K299+K315+K331+K347+K363+K379+K395+K411+K427+K443+K459+K475+K491+K507+K523+K539+K555+K571+K587+K603+K619+K635+K651+K667+K683+K699+K715+K731+K747+K763+K779+K795+K811 -> 0 | L11: =SUM(G11:K11) -> 5167 | M11: =ROUND((L11/$E$1),0) -> 1292
C12: Salvations | G12: =+G28+G44+G60+G76+G92+G108+G124+G140+G156+G172+G188+G204+G220+G236+G252+G268+G284+G300+G316+G332+G348+G364+G380+G396+G412+G428+G444+G460+G476+G492+G508+G524+G540+G556+G572+G588+G604+G620+G636+G652+G668+G684+G700+G716+G732+G748+G764+G780+G796+G812 -> 62 | H12: =+H28+H44+H60+H76+H92+H108+H124+H140+H156+H172+H188+H204+H220+H236+H252+H268+H284+H300+H316+H332+H348+H364+H380+H396+H412+H428+H444+H460+H476+H492+H508+H524+H540+H556+H572+H588+H604+H620+H636+H652+H668+H684+H700+H716+H732+H748+H764+H780+H796+H812 -> 19 | I12: =+I28+I44+I60+I76+I92+I108+I124+I140+I156+I172+I188+I204+I220+I236+I252+I268+I284+I300+I316+I332+I348+I364+I380+I396+I412+I428+I444+I460+I476+I492+I508+I524+I540+I556+I572+I588+I604+I620+I636+I652+I668+I684+I700+I716+I732+I748+I764+I780+I796+I812 -> 29 | J12: =+J28+J44+J60+J76+J92+J108+J124+J140+J156+J172+J188+J204+J220+J236+J252+J268+J284+J300+J316+J332+J348+J364+J380+J396+J412+J428+J444+J460+J476+J492+J508+J524+J540+J556+J572+J588+J604+J620+J636+J652+J668+J684+J700+J716+J732+J748+J764+J780+J796+J812 -> 32 | K12: =+K28+K44+K60+K76+K92+K108+K124+K140+K156+K172+K188+K204+K220+K236+K252+K268+K284+K300+K316+K332+K348+K364+K380+K396+K412+K428+K444+K460+K476+K492+K508+K524+K540+K556+K572+K588+K604+K620+K636+K652+K668+K684+K700+K716+K732+K748+K764+K780+K796+K812 -> 0 | L12: =SUM(G12:K12) -> 142 | M12: =ROUND((L12/$E$1),0) -> 36
C13: Baptisms | G13: =+G29+G45+G61+G77+G93+G109+G125+G141+G157+G173+G189+G205+G221+G237+G253+G269+G285+G301+G317+G333+G349+G365+G381+G397+G413+G429+G445+G461+G477+G493+G509+G525+G541+G557+G573+G589+G605+G621+G637+G653+G669+G685+G701+G717+G733+G749+G765+G781+G797+G813 -> 0 | H13: =+H29+H45+H61+H77+H93+H109+H125+H141+H157+H173+H189+H205+H221+H237+H253+H269+H285+H301+H317+H333+H349+H365+H381+H397+H413+H429+H445+H461+H477+H493+H509+H525+H541+H557+H573+H589+H605+H621+H637+H653+H669+H685+H701+H717+H733+H749+H765+H781+H797+H813 -> 0 | I13: =+I29+I45+I61+I77+I93+I109+I125+I141+I157+I173+I189+I205+I221+I237+I253+I269+I285+I301+I317+I333+I349+I365+I381+I397+I413+I429+I445+I461+I477+I493+I509+I525+I541+I557+I573+I589+I605+I621+I637+I653+I669+I685+I701+I717+I733+I749+I765+I781+I797+I813 -> 2 | J13: =+J29+J45+J61+J77+J93+J109+J125+J141+J157+J173+J189+J205+J221+J237+J253+J269+J285+J301+J317+J333+J349+J365+J381+J397+J413+J429+J445+J461+J477+J493+J509+J525+J541+J557+J573+J589+J605+J621+J637+J653+J669+J685+J701+J717+J733+J749+J765+J781+J797+J813 -> 0 | K13: =+K29+K45+K61+K77+K93+K109+K125+K141+K157+K173+K189+K205+K221+K237+K253+K269+K285+K301+K317+K333+K349+K365+K381+K397+K413+K429+K445+K461+K477+K493+K509+K525+K541+K557+K573+K589+K605+K621+K637+K653+K669+K685+K701+K717+K733+K749+K765+K781+K797+K813 -> 0 | L13: =SUM(G13:K13) -> 2 | M13: =ROUND((L13/$E$1),0) -> 1
C14: Home Visits | G14: =+G30+G46+G62+G78+G94+G110+G126+G142+G158+G174+G190+G206+G222+G238+G254+G270+G286+G302+G318+G334+G350+G366+G382+G398+G414+G430+G446+G462+G478+G494+G510+G526+G542+G558+G574+G590+G606+G622+G638+G654+G670+G686+G702+G718+G734+G750+G766+G782+G798+G814 -> 135 | H14: =+H30+H46+H62+H78+H94+H110+H126+H142+H158+H174+H190+H206+H222+H238+H254+H270+H286+H302+H318+H334+H350+H366+H382+H398+H414+H430+H446+H462+H478+H494+H510+H526+H542+H558+H574+H590+H606+H622+H638+H654+H670+H686+H702+H718+H734+H750+H766+H782+H798+H814 -> 141 | I14: =+I30+I46+I62+I78+I94+I110+I126+I142+I158+I174+I190+I206+I222+I238+I254+I270+I286+I302+I318+I334+I350+I366+I382+I398+I414+I430+I446+I462+I478+I494+I510+I526+I542+I558+I574+I590+I606+I622+I638+I654+I670+I686+I702+I718+I734+I750+I766+I782+I798+I814 -> 119 | J14: =+J30+J46+J62+J78+J94+J110+J126+J142+J158+J174+J190+J206+J222+J238+J254+J270+J286+J302+J318+J334+J350+J366+J382+J398+J414+J430+J446+J462+J478+J494+J510+J526+J542+J558+J574+J590+J606+J622+J638+J654+J670+J686+J702+J718+J734+J750+J766+J782+J798+J814 -> 139 | K14: =+K30+K46+K62+K78+K94+K110+K126+K142+K158+K174+K190+K206+K222+K238+K254+K270+K286+K302+K318+K334+K350+K366+K382+K398+K414+K430+K446+K462+K478+K494+K510+K526+K542+K558+K574+K590+K606+K622+K638+K654+K670+K686+K702+K718+K734+K750+K766+K782+K798+K814 -> 0 | L14: =SUM(G14:K14) -> 534 | M14: =ROUND((L14/$E$1),0) -> 134
C15: Meals / Food Packs | G15: =+G31+G47+G63+G79+G95+G111+G127+G143+G159+G175+G191+G207+G223+G239+G255+G271+G287+G303+G319+G335+G351+G367+G383+G399+G415+G431+G447+G463+G479+G495+G511+G527+G543+G559+G575+G591+G607+G623+G639+G655+G671+G687+G703+G719+G735+G751+G767+G783+G799+G815 -> 2734 | H15: =+H31+H47+H63+H79+H95+H111+H127+H143+H159+H175+H191+H207+H223+H239+H255+H271+H287+H303+H319+H335+H351+H367+H383+H399+H415+H431+H447+H463+H479+H495+H511+H527+H543+H559+H575+H591+H607+H623+H639+H655+H671+H687+H703+H719+H735+H751+H767+H783+H799+H815 -> 3207 | I15: =+I31+I47+I63+I79+I95+I111+I127+I143+I159+I175+I191+I207+I223+I239+I255+I271+I287+I303+I319+I335+I351+I367+I383+I399+I415+I431+I447+I463+I479+I495+I511+I527+I543+I559+I575+I591+I607+I623+I639+I655+I671+I687+I703+I719+I735+I751+I767+I783+I799+I815 -> 2063 | J15: =+J31+J47+J63+J79+J95+J111+J127+J143+J159+J175+J191+J207+J223+J239+J255+J271+J287+J303+J319+J335+J351+J367+J383+J399+J415+J431+J447+J463+J479+J495+J511+J527+J543+J559+J575+J591+J607+J623+J639+J655+J671+J687+J703+J719+J735+J751+J767+J783+J799+J815 -> 2115 | K15: =+K31+K47+K63+K79+K95+K111+K127+K143+K159+K175+K191+K207+K223+K239+K255+K271+K287+K303+K319+K335+K351+K367+K383+K399+K415+K431+K447+K463+K479+K495+K511+K527+K543+K559+K575+K591+K607+K623+K639+K655+K671+K687+K703+K719+K735+K751+K767+K783+K799+K815 -> 0 | L15: =SUM(G15:K15) -> 10119 | M15: =ROUND((L15/$E$1),0) -> 2530
C16: Preschool Attendance | G16: =+G32+G48+G64+G80+G96+G112+G128+G144+G160+G176+G192+G208+G224+G240+G256+G272+G288+G304+G320+G336+G352+G368+G384+G400+G416+G432+G448+G464+G480+G496+G512+G528+G544+G560+G576+G592+G608+G624+G640+G656+G672+G688+G704+G720+G736+G752+G768+G784+G800+G816 -> 237 | H16: =+H32+H48+H64+H80+H96+H112+H128+H144+H160+H176+H192+H208+H224+H240+H256+H272+H288+H304+H320+H336+H352+H368+H384+H400+H416+H432+H448+H464+H480+H496+H512+H528+H544+H560+H576+H592+H608+H624+H640+H656+H672+H688+H704+H720+H736+H752+H768+H784+H800+H816 -> 260 | I16: =+I32+I48+I64+I80+I96+I112+I128+I144+I160+I176+I192+I208+I224+I240+I256+I272+I288+I304+I320+I336+I352+I368+I384+I400+I416+I432+I448+I464+I480+I496+I512+I528+I544+I560+I576+I592+I608+I624+I640+I656+I672+I688+I704+I720+I736+I752+I768+I784+I800+I816 -> 40 | J16: =+J32+J48+J64+J80+J96+J112+J128+J144+J160+J176+J192+J208+J224+J240+J256+J272+J288+J304+J320+J336+J352+J368+J384+J400+J416+J432+J448+J464+J480+J496+J512+J528+J544+J560+J576+J592+J608+J624+J640+J656+J672+J688+J704+J720+J736+J752+J768+J784+J800+J816 -> 40 | K16: =+K32+K48+K64+K80+K96+K112+K128+K144+K160+K176+K192+K208+K224+K240+K256+K272+K288+K304+K320+K336+K352+K368+K384+K400+K416+K432+K448+K464+K480+K496+K512+K528+K544+K560+K576+K592+K608+K624+K640+K656+K672+K688+K704+K720+K736+K752+K768+K784+K800+K816 -> 0 | L16: =SUM(G16:K16) -> 577 | M16: =ROUND((L16/$E$1),0) -> 144
A19: 1 | C19: Hawane CLC Church | G19: =+$G$3 -> 2024 | H19: =+G19 -> 2024 | I19: =+H19 -> 2024 | J19: =+I19 -> 2024 | K19: =+J19 -> 2024 | L19: =+K19 -> 2024 | M19: =+L19 -> 2024 | S19: =+C19 -> Hawane CLC Church | T19: =+L23 -> 870 | U19: =+L24+L25 -> 233 | V19: =+L26+L27 -> 637 | W19: =+L30 -> 15 | X19: =+L28 -> 1
C20: =+$C4 -> July 2024 | G20: =+$G$4 -> Jul | H20: =+G20 -> Jul | I20: =+H20 -> Jul | J20: =+I20 -> Jul | K20: =+J20 -> Jul | L20: =+K20 -> Jul | M20: =+L20 -> Jul
G21: =+$G$5 -> 7 | H21: =+$H$5 -> 14 | I21: =+$I$5 -> 21 | J21: =+$J$5 -> 28 | K21: =+$K$5 -> 0 | L21: Total | M21: Average
C23: Church Attendance: | G23: =SUM(G24:G27) -> 193 | H23: =SUM(H24:H27) -> 234 | I23: =SUM(I24:I27) -> 231 | J23: =SUM(J24:J27) -> 212 | K23: =SUM(K24:K27) -> 0 | L23: =SUM(L24:L27) -> 870 | M23: =ROUND((L23/$E$1),0) -> 218
D24: Men | G24: 12 | H24: 20 | I24: 14 | J24: 18 | L24: =SUM(G24:K24) -> 64 | M24: =ROUND((L24/$E$1),0) -> 16
D25: Women | G25: 34 | H25: 46 | I25: 57 | J25: 32 | L25: =SUM(G25:K25) -> 169 | M25: =ROUND((L25/$E$1),0) -> 42
D26: Youth | G26: 77 | H26: 85 | I26: 90 | J26: 100 | L26: =SUM(G26:K26) -> 352 | M26: =ROUND((L26/$E$1),0) -> 88
D27: Children | G27: 70 | H27: 83 | I27: 70 | J27: 62 | L27: =SUM(G27:K27) -> 285 | M27: =ROUND((L27/$E$1),0) -> 71
C28: Salvations | J28: 1 | L28: =SUM(G28:K28) -> 1 | M28: =ROUND((L28/$E$1),0) -> 0
C29: Baptisms | L29: =SUM(G29:K29) -> 0 | M29: =ROUND((L29/$E$1),0) -> 0
C30: Home Visits | H30: 7 | I30: 3 | J30: 5 | L30: =SUM(G30:K30) -> 15 | M30: =ROUND((L30/$E$1),0) -> 4
C31: Meals / Food Packs | J31: 108 | L31: =SUM(G31:K31) -> 108 | M31: =ROUND((L31/$E$1),0) -> 27
C32: Preschool Attendance | L32: =SUM(G32:K32) -> 0 | M32: =ROUND((L32/$E$1),0) -> 0
A35: =+A19+1 -> 2 | C35: Ngwenya | G35: =+$G$3 -> 2024 | H35: =+G35 -> 2024 | I35: =+H35 -> 2024 | J35: =+I35 -> 2024 | K35: =+J35 -> 2024 | L35: =+K35 -> 2024 | M35: =+L35 -> 2024 | S35: =+C35 -> Ngwenya | T35: =+L39 -> 273 | U35: =+L40+L41 -> 63 | V35: =+L42+L43 -> 210 | W35: =+L46 -> 37 | X35: =+L44 -> 12
C36: =+$C20 -> July 2024 | G36: =+$G$4 -> Jul | H36: =+G36 -> Jul | I36: =+H36 -> Jul | J36: =+I36 -> Jul | K36: =+J36 -> Jul | L36: =+K36 -> Jul | M36: =+L36 -> Jul
G37: =+$G$5 -> 7 | H37: =+$H$5 -> 14 | I37: =+$I$5 -> 21 | J37: =+$J$5 -> 28 | K37: =+$K$5 -> 0 | L37: Total | M37: Average
C39: Church Attendance: | G39: =SUM(G40:G43) -> 63 | H39: =SUM(H40:H43) -> 57 | I39: =SUM(I40:I43) -> 80 | J39: =SUM(J40:J43) -> 73 | K39: =SUM(K40:K43) -> 0 | L39: =SUM(L40:L43) -> 273 | M39: =ROUND((L39/$E$1),0) -> 68
D40: Men | G40: 3 | H40: 2 | I40: 6 | J40: 4 | L40: =SUM(G40:K40) -> 15 | M40: =ROUND((L40/$E$1),0) -> 4
D41: Women | G41: 10 | H41: 10 | I41: 14 | J41: 14 | L41: =SUM(G41:K41) -> 48 | M41: =ROUND((L41/$E$1),0) -> 12
D42: Youth | G42: 15 | H42: 15 | I42: 20 | J42: 20 | L42: =SUM(G42:K42) -> 70 | M42: =ROUND((L42/$E$1),0) -> 18
D43: Children | G43: 35 | H43: 30 | I43: 40 | J43: 35 | L43: =SUM(G43:K43) -> 140 | M43: =ROUND((L43/$E$1),0) -> 35
C44: Salvations | G44: 5 | I44: 3 | J44: 4 | L44: =SUM(G44:K44) -> 12 | M44: =ROUND((L44/$E$1),0) -> 3
C45: Baptisms | L45: =SUM(G45:K45) -> 0 | M45: =ROUND((L45/$E$1),0) -> 0
C46: Home Visits | G46: 8 | H46: 12 | I46: 9 | J46: 8 | L46: =SUM(G46:K46) -> 37 | M46: =ROUND((L46/$E$1),0) -> 9
C47: Meals / Food Packs | G47: 144 | H47: 108 | I47: 144 | J47: 144 | L47: =SUM(G47:K47) -> 540 | M47: =ROUND((L47/$E$1),0) -> 135
C48: Preschool Attendance | L48: =SUM(G48:K48) -> 0 | M48: =ROUND((L48/$E$1),0) -> 0
...

Sheet Aug-24
D1: Number of Sundays | E1: 4 | S1: ICBC | T1: =+C7 -> Church Attendance: | U1: Adults | V1: Youth & Children | W1: Home Visits | X1: =+C12 -> Salvations
C3: Total ICBC | G3: 2024 | H3: =+G3 -> 2024 | I3: =+H3 -> 2024 | J3: =+I3 -> 2024 | K3: =+J3 -> 2024 | L3: =+K3 -> 2024 | M3: =+L3 -> 2024 | S3: =+C3 -> Total ICBC | T3: =+L7 -> 10298 | U3: =+L8+L9 -> 2499 | V3: =+L10+L11 -> 7799 | W3: =+L14 -> 587 | X3: =+L12 -> 122
C4: August 2024 | G4: Aug | H4: =+G4 -> Aug | I4: =+H4 -> Aug | J4: =+I4 -> Aug | K4: =+J4 -> Aug | L4: =+K4 -> Aug | M4: =+L4 -> Aug
G5: 4 | H5: 11 | I5: 18 | J5: 25 | K5: 0 | L5: Total | M5: Average
C7: Church Attendance: | G7: =SUM(G8:G11) -> 2369 | H7: =SUM(H8:H11) -> 2663 | I7: =SUM(I8:I11) -> 2681 | J7: =SUM(J8:J11) -> 2585 | K7: =SUM(K8:K11) -> 0 | L7: =SUM(L8:L11) -> 10298 | M7: =ROUND((L7/$E$1),0) -> 2575
D8: Men | G8: =+G24+G40+G56+G72+G88+G104+G120+G136+G152+G168+G184+G200+G216+G232+G248+G264+G280+G296+G312+G328+G344+G360+G376+G392+G408+G424+G440+G456+G472+G488+G504+G520+G536+G552+G568+G584+G600+G616+G632+G648+G664+G680+G696+G712+G728+G744+G760+G776+G792+G808 -> 156 | H8: =+H24+H40+H56+H72+H88+H104+H120+H136+H152+H168+H184+H200+H216+H232+H248+H264+H280+H296+H312+H328+H344+H360+H376+H392+H408+H424+H440+H456+H472+H488+H504+H520+H536+H552+H568+H584+H600+H616+H632+H648+H664+H680+H696+H712+H728+H744+H760+H776+H792+H808 -> 180 | I8: =+I24+I40+I56+I72+I88+I104+I120+I136+I152+I168+I184+I200+I216+I232+I248+I264+I280+I296+I312+I328+I344+I360+I376+I392+I408+I424+I440+I456+I472+I488+I504+I520+I536+I552+I568+I584+I600+I616+I632+I648+I664+I680+I696+I712+I728+I744+I760+I776+I792+I808 -> 173 | J8: =+J24+J40+J56+J72+J88+J104+J120+J136+J152+J168+J184+J200+J216+J232+J248+J264+J280+J296+J312+J328+J344+J360+J376+J392+J408+J424+J440+J456+J472+J488+J504+J520+J536+J552+J568+J584+J600+J616+J632+J648+J664+J680+J696+J712+J728+J744+J760+J776+J792+J808 -> 158 | K8: =+K24+K40+K56+K72+K88+K104+K120+K136+K152+K168+K184+K200+K216+K232+K248+K264+K280+K296+K312+K328+K344+K360+K376+K392+K408+K424+K440+K456+K472+K488+K504+K520+K536+K552+K568+K584+K600+K616+K632+K648+K664+K680+K696+K712+K728+K744+K760+K776+K792+K808 -> 0 | L8: =SUM(G8:K8) -> 667 | M8: =ROUND((L8/$E$1),0) -> 167
D9: Women | G9: =+G25+G41+G57+G73+G89+G105+G121+G137+G153+G169+G185+G201+G217+G233+G249+G265+G281+G297+G313+G329+G345+G361+G377+G393+G409+G425+G441+G457+G473+G489+G505+G521+G537+G553+G569+G585+G601+G617+G633+G649+G665+G681+G697+G713+G729+G745+G761+G777+G793+G809 -> 448 | H9: =+H25+H41+H57+H73+H89+H105+H121+H137+H153+H169+H185+H201+H217+H233+H249+H265+H281+H297+H313+H329+H345+H361+H377+H393+H409+H425+H441+H457+H473+H489+H505+H521+H537+H553+H569+H585+H601+H617+H633+H649+H665+H681+H697+H713+H729+H745+H761+H777+H793+H809 -> 487 | I9: =+I25+I41+I57+I73+I89+I105+I121+I137+I153+I169+I185+I201+I217+I233+I249+I265+I281+I297+I313+I329+I345+I361+I377+I393+I409+I425+I441+I457+I473+I489+I505+I521+I537+I553+I569+I585+I601+I617+I633+I649+I665+I681+I697+I713+I729+I745+I761+I777+I793+I809 -> 479 | J9: =+J25+J41+J57+J73+J89+J105+J121+J137+J153+J169+J185+J201+J217+J233+J249+J265+J281+J297+J313+J329+J345+J361+J377+J393+J409+J425+J441+J457+J473+J489+J505+J521+J537+J553+J569+J585+J601+J617+J633+J649+J665+J681+J697+J713+J729+J745+J761+J777+J793+J809 -> 418 | K9: =+K25+K41+K57+K73+K89+K105+K121+K137+K153+K169+K185+K201+K217+K233+K249+K265+K281+K297+K313+K329+K345+K361+K377+K393+K409+K425+K441+K457+K473+K489+K505+K521+K537+K553+K569+K585+K601+K617+K633+K649+K665+K681+K697+K713+K729+K745+K761+K777+K793+K809 -> 0 | L9: =SUM(G9:K9) -> 1832 | M9: =ROUND((L9/$E$1),0) -> 458
D10: Youth | G10: =+G26+G42+G58+G74+G90+G106+G122+G138+G154+G170+G186+G202+G218+G234+G250+G266+G282+G298+G314+G330+G346+G362+G378+G394+G410+G426+G442+G458+G474+G490+G506+G522+G538+G554+G570+G586+G602+G618+G634+G650+G666+G682+G698+G714+G730+G746+G762+G778+G794+G810 -> 653 | H10: =+H26+H42+H58+H74+H90+H106+H122+H138+H154+H170+H186+H202+H218+H234+H250+H266+H282+H298+H314+H330+H346+H362+H378+H394+H410+H426+H442+H458+H474+H490+H506+H522+H538+H554+H570+H586+H602+H618+H634+H650+H666+H682+H698+H714+H730+H746+H762+H778+H794+H810 -> 687 | I10: =+I26+I42+I58+I74+I90+I106+I122+I138+I154+I170+I186+I202+I218+I234+I250+I266+I282+I298+I314+I330+I346+I362+I378+I394+I410+I426+I442+I458+I474+I490+I506+I522+I538+I554+I570+I586+I602+I618+I634+I650+I666+I682+I698+I714+I730+I746+I762+I778+I794+I810 -> 657 | J10: =+J26+J42+J58+J74+J90+J106+J122+J138+J154+J170+J186+J202+J218+J234+J250+J266+J282+J298+J314+J330+J346+J362+J378+J394+J410+J426+J442+J458+J474+J490+J506+J522+J538+J554+J570+J586+J602+J618+J634+J650+J666+J682+J698+J714+J730+J746+J762+J778+J794+J810 -> 608 | K10: =+K26+K42+K58+K74+K90+K106+K122+K138+K154+K170+K186+K202+K218+K234+K250+K266+K282+K298+K314+K330+K346+K362+K378+K394+K410+K426+K442+K458+K474+K490+K506+K522+K538+K554+K570+K586+K602+K618+K634+K650+K666+K682+K698+K714+K730+K746+K762+K778+K794+K810 -> 0 | L10: =SUM(G10:K10) -> 2605 | M10: =ROUND((L10/$E$1),0) -> 651
D11: Children | G11: =+G27+G43+G59+G75+G91+G107+G123+G139+G155+G171+G187+G203+G219+G235+G251+G267+G283+G299+G315+G331+G347+G363+G379+G395+G411+G427+G443+G459+G475+G491+G507+G523+G539+G555+G571+G587+G603+G619+G635+G651+G667+G683+G699+G715+G731+G747+G763+G779+G795+G811 -> 1112 | H11: =+H27+H43+H59+H75+H91+H107+H123+H139+H155+H171+H187+H203+H219+H235+H251+H267+H283+H299+H315+H331+H347+H363+H379+H395+H411+H427+H443+H459+H475+H491+H507+H523+H539+H555+H571+H587+H603+H619+H635+H651+H667+H683+H699+H715+H731+H747+H763+H779+H795+H811 -> 1309 | I11: =+I27+I43+I59+I75+I91+I107+I123+I139+I155+I171+I187+I203+I219+I235+I251+I267+I283+I299+I315+I331+I347+I363+I379+I395+I411+I427+I443+I459+I475+I491+I507+I523+I539+I555+I571+I587+I603+I619+I635+I651+I667+I683+I699+I715+I731+I747+I763+I779+I795+I811 -> 1372 | J11: =+J27+J43+J59+J75+J91+J107+J123+J139+J155+J171+J187+J203+J219+J235+J251+J267+J283+J299+J315+J331+J347+J363+J379+J395+J411+J427+J443+J459+J475+J491+J507+J523+J539+J555+J571+J587+J603+J619+J635+J651+J667+J683+J699+J715+J731+J747+J763+J779+J795+J811 -> 1401 | K11: =+K27+K43+K59+K75+K91+K107+K123+K139+K155+K171+K187+K203+K219+K235+K251+K267+K283+K299+K315+K331+K347+K363+K379+K395+K411+K427+K443+K459+K475+K491+K507+K523+K539+K555+K571+K587+K603+K619+K635+K651+K667+K683+K699+K715+K731+K747+K763+K779+K795+K811 -> 0 | L11: =SUM(G11:K11) -> 5194 | M11: =ROUND((L11/$E$1),0) -> 1299
C12: Salvations | G12: =+G28+G44+G60+G76+G92+G108+G124+G140+G156+G172+G188+G204+G220+G236+G252+G268+G284+G300+G316+G332+G348+G364+G380+G396+G412+G428+G444+G460+G476+G492+G508+G524+G540+G556+G572+G588+G604+G620+G636+G652+G668+G684+G700+G716+G732+G748+G764+G780+G796+G812 -> 27 | H12: =+H28+H44+H60+H76+H92+H108+H124+H140+H156+H172+H188+H204+H220+H236+H252+H268+H284+H300+H316+H332+H348+H364+H380+H396+H412+H428+H444+H460+H476+H492+H508+H524+H540+H556+H572+H588+H604+H620+H636+H652+H668+H684+H700+H716+H732+H748+H764+H780+H796+H812 -> 28 | I12: =+I28+I44+I60+I76+I92+I108+I124+I140+I156+I172+I188+I204+I220+I236+I252+I268+I284+I300+I316+I332+I348+I364+I380+I396+I412+I428+I444+I460+I476+I492+I508+I524+I540+I556+I572+I588+I604+I620+I636+I652+I668+I684+I700+I716+I732+I748+I764+I780+I796+I812 -> 34 | J12: =+J28+J44+J60+J76+J92+J108+J124+J140+J156+J172+J188+J204+J220+J236+J252+J268+J284+J300+J316+J332+J348+J364+J380+J396+J412+J428+J444+J460+J476+J492+J508+J524+J540+J556+J572+J588+J604+J620+J636+J652+J668+J684+J700+J716+J732+J748+J764+J780+J796+J812 -> 33 | K12: =+K28+K44+K60+K76+K92+K108+K124+K140+K156+K172+K188+K204+K220+K236+K252+K268+K284+K300+K316+K332+K348+K364+K380+K396+K412+K428+K444+K460+K476+K492+K508+K524+K540+K556+K572+K588+K604+K620+K636+K652+K668+K684+K700+K716+K732+K748+K764+K780+K796+K812 -> 0 | L12: =SUM(G12:K12) -> 122 | M12: =ROUND((L12/$E$1),0) -> 31
C13: Baptisms | G13: =+G29+G45+G61+G77+G93+G109+G125+G141+G157+G173+G189+G205+G221+G237+G253+G269+G285+G301+G317+G333+G349+G365+G381+G397+G413+G429+G445+G461+G477+G493+G509+G525+G541+G557+G573+G589+G605+G621+G637+G653+G669+G685+G701+G717+G733+G749+G765+G781+G797+G813 -> 0 | H13: =+H29+H45+H61+H77+H93+H109+H125+H141+H157+H173+H189+H205+H221+H237+H253+H269+H285+H301+H317+H333+H349+H365+H381+H397+H413+H429+H445+H461+H477+H493+H509+H525+H541+H557+H573+H589+H605+H621+H637+H653+H669+H685+H701+H717+H733+H749+H765+H781+H797+H813 -> 0 | I13: =+I29+I45+I61+I77+I93+I109+I125+I141+I157+I173+I189+I205+I221+I237+I253+I269+I285+I301+I317+I333+I349+I365+I381+I397+I413+I429+I445+I461+I477+I493+I509+I525+I541+I557+I573+I589+I605+I621+I637+I653+I669+I685+I701+I717+I733+I749+I765+I781+I797+I813 -> 0 | J13: =+J29+J45+J61+J77+J93+J109+J125+J141+J157+J173+J189+J205+J221+J237+J253+J269+J285+J301+J317+J333+J349+J365+J381+J397+J413+J429+J445+J461+J477+J493+J509+J525+J541+J557+J573+J589+J605+J621+J637+J653+J669+J685+J701+J717+J733+J749+J765+J781+J797+J813 -> 0 | K13: =+K29+K45+K61+K77+K93+K109+K125+K141+K157+K173+K189+K205+K221+K237+K253+K269+K285+K301+K317+K333+K349+K365+K381+K397+K413+K429+K445+K461+K477+K493+K509+K525+K541+K557+K573+K589+K605+K621+K637+K653+K669+K685+K701+K717+K733+K749+K765+K781+K797+K813 -> 0 | L13: =SUM(G13:K13) -> 0 | M13: =ROUND((L13/$E$1),0) -> 0
C14: Home Visits | G14: =+G30+G46+G62+G78+G94+G110+G126+G142+G158+G174+G190+G206+G222+G238+G254+G270+G286+G302+G318+G334+G350+G366+G382+G398+G414+G430+G446+G462+G478+G494+G510+G526+G542+G558+G574+G590+G606+G622+G638+G654+G670+G686+G702+G718+G734+G750+G766+G782+G798+G814 -> 137 | H14: =+H30+H46+H62+H78+H94+H110+H126+H142+H158+H174+H190+H206+H222+H238+H254+H270+H286+H302+H318+H334+H350+H366+H382+H398+H414+H430+H446+H462+H478+H494+H510+H526+H542+H558+H574+H590+H606+H622+H638+H654+H670+H686+H702+H718+H734+H750+H766+H782+H798+H814 -> 154 | I14: =+I30+I46+I62+I78+I94+I110+I126+I142+I158+I174+I190+I206+I222+I238+I254+I270+I286+I302+I318+I334+I350+I366+I382+I398+I414+I430+I446+I462+I478+I494+I510+I526+I542+I558+I574+I590+I606+I622+I638+I654+I670+I686+I702+I718+I734+I750+I766+I782+I798+I814 -> 177 | J14: =+J30+J46+J62+J78+J94+J110+J126+J142+J158+J174+J190+J206+J222+J238+J254+J270+J286+J302+J318+J334+J350+J366+J382+J398+J414+J430+J446+J462+J478+J494+J510+J526+J542+J558+J574+J590+J606+J622+J638+J654+J670+J686+J702+J718+J734+J750+J766+J782+J798+J814 -> 119 | K14: =+K30+K46+K62+K78+K94+K110+K126+K142+K158+K174+K190+K206+K222+K238+K254+K270+K286+K302+K318+K334+K350+K366+K382+K398+K414+K430+K446+K462+K478+K494+K510+K526+K542+K558+K574+K590+K606+K622+K638+K654+K670+K686+K702+K718+K734+K750+K766+K782+K798+K814 -> 0 | L14: =SUM(G14:K14) -> 587 | M14: =ROUND((L14/$E$1),0) -> 147
C15: Meals / Food Packs | G15: =+G31+G47+G63+G79+G95+G111+G127+G143+G159+G175+G191+G207+G223+G239+G255+G271+G287+G303+G319+G335+G351+G367+G383+G399+G415+G431+G447+G463+G479+G495+G511+G527+G543+G559+G575+G591+G607+G623+G639+G655+G671+G687+G703+G719+G735+G751+G767+G783+G799+G815 -> 2054 | H15: =+H31+H47+H63+H79+H95+H111+H127+H143+H159+H175+H191+H207+H223+H239+H255+H271+H287+H303+H319+H335+H351+H367+H383+H399+H415+H431+H447+H463+H479+H495+H511+H527+H543+H559+H575+H591+H607+H623+H639+H655+H671+H687+H703+H719+H735+H751+H767+H783+H799+H815 -> 2112 | I15: =+I31+I47+I63+I79+I95+I111+I127+I143+I159+I175+I191+I207+I223+I239+I255+I271+I287+I303+I319+I335+I351+I367+I383+I399+I415+I431+I447+I463+I479+I495+I511+I527+I543+I559+I575+I591+I607+I623+I639+I655+I671+I687+I703+I719+I735+I751+I767+I783+I799+I815 -> 3046 | J15: =+J31+J47+J63+J79+J95+J111+J127+J143+J159+J175+J191+J207+J223+J239+J255+J271+J287+J303+J319+J335+J351+J367+J383+J399+J415+J431+J447+J463+J479+J495+J511+J527+J543+J559+J575+J591+J607+J623+J639+J655+J671+J687+J703+J719+J735+J751+J767+J783+J799+J815 -> 3238 | K15: =+K31+K47+K63+K79+K95+K111+K127+K143+K159+K175+K191+K207+K223+K239+K255+K271+K287+K303+K319+K335+K351+K367+K383+K399+K415+K431+K447+K463+K479+K495+K511+K527+K543+K559+K575+K591+K607+K623+K639+K655+K671+K687+K703+K719+K735+K751+K767+K783+K799+K815 -> 0 | L15: =SUM(G15:K15) -> 10450 | M15: =ROUND((L15/$E$1),0) -> 2613
C16: Preschool Attendance | G16: =+G32+G48+G64+G80+G96+G112+G128+G144+G160+G176+G192+G208+G224+G240+G256+G272+G288+G304+G320+G336+G352+G368+G384+G400+G416+G432+G448+G464+G480+G496+G512+G528+G544+G560+G576+G592+G608+G624+G640+G656+G672+G688+G704+G720+G736+G752+G768+G784+G800+G816 -> 0 | H16: =+H32+H48+H64+H80+H96+H112+H128+H144+H160+H176+H192+H208+H224+H240+H256+H272+H288+H304+H320+H336+H352+H368+H384+H400+H416+H432+H448+H464+H480+H496+H512+H528+H544+H560+H576+H592+H608+H624+H640+H656+H672+H688+H704+H720+H736+H752+H768+H784+H800+H816 -> 0 | I16: =+I32+I48+I64+I80+I96+I112+I128+I144+I160+I176+I192+I208+I224+I240+I256+I272+I288+I304+I320+I336+I352+I368+I384+I400+I416+I432+I448+I464+I480+I496+I512+I528+I544+I560+I576+I592+I608+I624+I640+I656+I672+I688+I704+I720+I736+I752+I768+I784+I800+I816 -> 0 | J16: =+J32+J48+J64+J80+J96+J112+J128+J144+J160+J176+J192+J208+J224+J240+J256+J272+J288+J304+J320+J336+J352+J368+J384+J400+J416+J432+J448+J464+J480+J496+J512+J528+J544+J560+J576+J592+J608+J624+J640+J656+J672+J688+J704+J720+J736+J752+J768+J784+J800+J816 -> 0 | K16: =+K32+K48+K64+K80+K96+K112+K128+K144+K160+K176+K192+K208+K224+K240+K256+K272+K288+K304+K320+K336+K352+K368+K384+K400+K416+K432+K448+K464+K480+K496+K512+K528+K544+K560+K576+K592+K608+K624+K640+K656+K672+K688+K704+K720+K736+K752+K768+K784+K800+K816 -> 0 | L16: =SUM(G16:K16) -> 0 | M16: =ROUND((L16/$E$1),0) -> 0
A19: 1 | C19: Hawane CLC Church | G19: =+$G$3 -> 2024 | H19: =+G19 -> 2024 | I19: =+H19 -> 2024 | J19: =+I19 -> 2024 | K19: =+J19 -> 2024 | L19: =+K19 -> 2024 | M19: =+L19 -> 2024 | S19: =+C19 -> Hawane CLC Church | T19: =+L23 -> 902 | U19: =+L24+L25 -> 274 | V19: =+L26+L27 -> 628 | W19: =+L30 -> 28 | X19: =+L28 -> 0
C20: =+$C4 -> August 2024 | G20: =+$G$4 -> Aug | H20: =+G20 -> Aug | I20: =+H20 -> Aug | J20: =+I20 -> Aug | K20: =+J20 -> Aug | L20: =+K20 -> Aug | M20: =+L20 -> Aug
G21: =+$G$5 -> 4 | H21: =+$H$5 -> 11 | I21: =+$I$5 -> 18 | J21: =+$J$5 -> 25 | K21: =+$K$5 -> 0 | L21: Total | M21: Average
C23: Church Attendance: | G23: =SUM(G24:G27) -> 204 | H23: =SUM(H24:H27) -> 226 | I23: =SUM(I24:I27) -> 248 | J23: =SUM(J24:J27) -> 224 | K23: =SUM(K24:K27) -> 0 | L23: =SUM(L24:L27) -> 902 | M23: =ROUND((L23/$E$1),0) -> 226
D24: Men | G24: 14 | H24: 18 | I24: 23 | J24: 20 | L24: =SUM(G24:K24) -> 75 | M24: =ROUND((L24/$E$1),0) -> 19
D25: Women | G25: 39 | H25: 45 | I25: 60 | J25: 55 | L25: =SUM(G25:K25) -> 199 | M25: =ROUND((L25/$E$1),0) -> 50
D26: Youth | G26: 74 | H26: 100 | I26: 85 | J26: 75 | L26: =SUM(G26:K26) -> 334 | M26: =ROUND((L26/$E$1),0) -> 84
D27: Children | G27: 77 | H27: 63 | I27: 80 | J27: 74 | L27: =SUM(G27:K27) -> 294 | M27: =ROUND((L27/$E$1),0) -> 74
C28: Salvations | L28: =SUM(G28:K28) -> 0 | M28: =ROUND((L28/$E$1),0) -> 0
C29: Baptisms | L29: =SUM(G29:K29) -> 0 | M29: =ROUND((L29/$E$1),0) -> 0
C30: Home Visits | G30: 6 | H30: 7 | I30: 8 | J30: 7 | L30: =SUM(G30:K30) -> 28 | M30: =ROUND((L30/$E$1),0) -> 7
C31: Meals / Food Packs | L31: =SUM(G31:K31) -> 0 | M31: =ROUND((L31/$E$1),0) -> 0
C32: Preschool Attendance | L32: =SUM(G32:K32) -> 0 | M32: =ROUND((L32/$E$1),0) -> 0
A35: =+A19+1 -> 2 | C35: Ngwenya | G35: =+$G$3 -> 2024 | H35: =+G35 -> 2024 | I35: =+H35 -> 2024 | J35: =+I35 -> 2024 | K35: =+J35 -> 2024 | L35: =+K35 -> 2024 | M35: =+L35 -> 2024 | S35: =+C35 -> Ngwenya | T35: =+L39 -> 295 | U35: =+L40+L41 -> 79 | V35: =+L42+L43 -> 216 | W35: =+L46 -> 40 | X35: =+L44 -> 4
C36: =+$C20 -> August 2024 | G36: =+$G$4 -> Aug | H36: =+G36 -> Aug | I36: =+H36 -> Aug | J36: =+I36 -> Aug | K36: =+J36 -> Aug | L36: =+K36 -> Aug | M36: =+L36 -> Aug
G37: =+$G$5 -> 4 | H37: =+$H$5 -> 11 | I37: =+$I$5 -> 18 | J37: =+$J$5 -> 25 | K37: =+$K$5 -> 0 | L37: Total | M37: Average
C39: Church Attendance: | G39: =SUM(G40:G43) -> 63 | H39: =SUM(H40:H43) -> 72 | I39: =SUM(I40:I43) -> 75 | J39: =SUM(J40:J43) -> 85 | K39: =SUM(K40:K43) -> 0 | L39: =SUM(L40:L43) -> 295 | M39: =ROUND((L39/$E$1),0) -> 74
D40: Men | G40: 6 | H40: 5 | I40: 5 | J40: 6 | L40: =SUM(G40:K40) -> 22 | M40: =ROUND((L40/$E$1),0) -> 6
D41: Women | G41: 12 | H41: 14 | I41: 16 | J41: 15 | L41: =SUM(G41:K41) -> 57 | M41: =ROUND((L41/$E$1),0) -> 14
D42: Youth | G42: 15 | H42: 18 | I42: 22 | J42: 24 | L42: =SUM(G42:K42) -> 79 | M42: =ROUND((L42/$E$1),0) -> 20
D43: Children | G43: 30 | H43: 35 | I43: 32 | J43: 40 | L43: =SUM(G43:K43) -> 137 | M43: =ROUND((L43/$E$1),0) -> 34
C44: Salvations | H44: 1 | I44: 2 | J44: 1 | L44: =SUM(G44:K44) -> 4 | M44: =ROUND((L44/$E$1),0) -> 1
C45: Baptisms | L45: =SUM(G45:K45) -> 0 | M45: =ROUND((L45/$E$1),0) -> 0
C46: Home Visits | G46: 10 | H46: 11 | I46: 10 | J46: 9 | L46: =SUM(G46:K46) -> 40 | M46: =ROUND((L46/$E$1),0) -> 10
C47: Meals / Food Packs | G47: 72 | H47: 144 | I47: 72 | J47: 144 | L47: =SUM(G47:K47) -> 432 | M47: =ROUND((L47/$E$1),0) -> 108
C48: Preschool Attendance | L48: =SUM(G48:K48) -> 0 | M48: =ROUND((L48/$E$1),0) -> 0
...

Sheet Sep-24
D1: Number of Sundays | E1: 5 | S1: ICBC | T1: =+C7 -> Church Attendance: | U1: Adults | V1: Youth & Children | W1: Home Visits | X1: =+C12 -> Salvations
C3: Total ICBC | G3: 2024 | H3: =+G3 -> 2024 | I3: =+H3 -> 2024 | J3: =+I3 -> 2024 | K3: =+J3 -> 2024 | L3: =+K3 -> 2024 | M3: =+L3 -> 2024 | S3: =+C3 -> Total ICBC | T3: =+L7 -> 13012 | U3: =+L8+L9 -> 3311 | V3: =+L10+L11 -> 9701 | W3: =+L14 -> 1252 | X3: =+L12 -> 150
C4: September 2024 | G4: Sep | H4: =+G4 -> Sep | I4: =+H4 -> Sep | J4: =+I4 -> Sep | K4: =+J4 -> Sep | L4: =+K4 -> Sep | M4: =+L4 -> Sep
G5: 1 | H5: 8 | I5: 15 | J5: 22 | K5: 29 | L5: Total | M5: Average
C7: Church Attendance: | G7: =SUM(G8:G11) -> 2569 | H7: =SUM(H8:H11) -> 2918 | I7: =SUM(I8:I11) -> 2513 | J7: =SUM(J8:J11) -> 1956 | K7: =SUM(K8:K11) -> 3056 | L7: =SUM(L8:L11) -> 13012 | M7: =ROUND((L7/$E$1),0) -> 2602
D8: Men | G8: =+G24+G40+G56+G72+G88+G104+G120+G136+G152+G168+G184+G200+G216+G232+G248+G264+G280+G296+G312+G328+G344+G360+G376+G392+G408+G424+G440+G456+G472+G488+G504+G520+G536+G552+G568+G584+G600+G616+G632+G648+G664+G680+G696+G712+G728+G744+G760+G776+G792+G808 -> 168 | H8: =+H24+H40+H56+H72+H88+H104+H120+H136+H152+H168+H184+H200+H216+H232+H248+H264+H280+H296+H312+H328+H344+H360+H376+H392+H408+H424+H440+H456+H472+H488+H504+H520+H536+H552+H568+H584+H600+H616+H632+H648+H664+H680+H696+H712+H728+H744+H760+H776+H792+H808 -> 202 | I8: =+I24+I40+I56+I72+I88+I104+I120+I136+I152+I168+I184+I200+I216+I232+I248+I264+I280+I296+I312+I328+I344+I360+I376+I392+I408+I424+I440+I456+I472+I488+I504+I520+I536+I552+I568+I584+I600+I616+I632+I648+I664+I680+I696+I712+I728+I744+I760+I776+I792+I808 -> 161 | J8: =+J24+J40+J56+J72+J88+J104+J120+J136+J152+J168+J184+J200+J216+J232+J248+J264+J280+J296+J312+J328+J344+J360+J376+J392+J408+J424+J440+J456+J472+J488+J504+J520+J536+J552+J568+J584+J600+J616+J632+J648+J664+J680+J696+J712+J728+J744+J760+J776+J792+J808 -> 154 | K8: =+K24+K40+K56+K72+K88+K104+K120+K136+K152+K168+K184+K200+K216+K232+K248+K264+K280+K296+K312+K328+K344+K360+K376+K392+K408+K424+K440+K456+K472+K488+K504+K520+K536+K552+K568+K584+K600+K616+K632+K648+K664+K680+K696+K712+K728+K744+K760+K776+K792+K808 -> 237 | L8: =SUM(G8:K8) -> 922 | M8: =ROUND((L8/$E$1),0) -> 184
D9: Women | G9: =+G25+G41+G57+G73+G89+G105+G121+G137+G153+G169+G185+G201+G217+G233+G249+G265+G281+G297+G313+G329+G345+G361+G377+G393+G409+G425+G441+G457+G473+G489+G505+G521+G537+G553+G569+G585+G601+G617+G633+G649+G665+G681+G697+G713+G729+G745+G761+G777+G793+G809 -> 459 | H9: =+H25+H41+H57+H73+H89+H105+H121+H137+H153+H169+H185+H201+H217+H233+H249+H265+H281+H297+H313+H329+H345+H361+H377+H393+H409+H425+H441+H457+H473+H489+H505+H521+H537+H553+H569+H585+H601+H617+H633+H649+H665+H681+H697+H713+H729+H745+H761+H777+H793+H809 -> 533 | I9: =+I25+I41+I57+I73+I89+I105+I121+I137+I153+I169+I185+I201+I217+I233+I249+I265+I281+I297+I313+I329+I345+I361+I377+I393+I409+I425+I441+I457+I473+I489+I505+I521+I537+I553+I569+I585+I601+I617+I633+I649+I665+I681+I697+I713+I729+I745+I761+I777+I793+I809 -> 457 | J9: =+J25+J41+J57+J73+J89+J105+J121+J137+J153+J169+J185+J201+J217+J233+J249+J265+J281+J297+J313+J329+J345+J361+J377+J393+J409+J425+J441+J457+J473+J489+J505+J521+J537+J553+J569+J585+J601+J617+J633+J649+J665+J681+J697+J713+J729+J745+J761+J777+J793+J809 -> 384 | K9: =+K25+K41+K57+K73+K89+K105+K121+K137+K153+K169+K185+K201+K217+K233+K249+K265+K281+K297+K313+K329+K345+K361+K377+K393+K409+K425+K441+K457+K473+K489+K505+K521+K537+K553+K569+K585+K601+K617+K633+K649+K665+K681+K697+K713+K729+K745+K761+K777+K793+K809 -> 556 | L9: =SUM(G9:K9) -> 2389 | M9: =ROUND((L9/$E$1),0) -> 478
D10: Youth | G10: =+G26+G42+G58+G74+G90+G106+G122+G138+G154+G170+G186+G202+G218+G234+G250+G266+G282+G298+G314+G330+G346+G362+G378+G394+G410+G426+G442+G458+G474+G490+G506+G522+G538+G554+G570+G586+G602+G618+G634+G650+G666+G682+G698+G714+G730+G746+G762+G778+G794+G810 -> 638 | H10: =+H26+H42+H58+H74+H90+H106+H122+H138+H154+H170+H186+H202+H218+H234+H250+H266+H282+H298+H314+H330+H346+H362+H378+H394+H410+H426+H442+H458+H474+H490+H506+H522+H538+H554+H570+H586+H602+H618+H634+H650+H666+H682+H698+H714+H730+H746+H762+H778+H794+H810 -> 768 | I10: =+I26+I42+I58+I74+I90+I106+I122+I138+I154+I170+I186+I202+I218+I234+I250+I266+I282+I298+I314+I330+I346+I362+I378+I394+I410+I426+I442+I458+I474+I490+I506+I522+I538+I554+I570+I586+I602+I618+I634+I650+I666+I682+I698+I714+I730+I746+I762+I778+I794+I810 -> 678 | J10: =+J26+J42+J58+J74+J90+J106+J122+J138+J154+J170+J186+J202+J218+J234+J250+J266+J282+J298+J314+J330+J346+J362+J378+J394+J410+J426+J442+J458+J474+J490+J506+J522+J538+J554+J570+J586+J602+J618+J634+J650+J666+J682+J698+J714+J730+J746+J762+J778+J794+J810 -> 499 | K10: =+K26+K42+K58+K74+K90+K106+K122+K138+K154+K170+K186+K202+K218+K234+K250+K266+K282+K298+K314+K330+K346+K362+K378+K394+K410+K426+K442+K458+K474+K490+K506+K522+K538+K554+K570+K586+K602+K618+K634+K650+K666+K682+K698+K714+K730+K746+K762+K778+K794+K810 -> 766 | L10: =SUM(G10:K10) -> 3349 | M10: =ROUND((L10/$E$1),0) -> 670
D11: Children | G11: =+G27+G43+G59+G75+G91+G107+G123+G139+G155+G171+G187+G203+G219+G235+G251+G267+G283+G299+G315+G331+G347+G363+G379+G395+G411+G427+G443+G459+G475+G491+G507+G523+G539+G555+G571+G587+G603+G619+G635+G651+G667+G683+G699+G715+G731+G747+G763+G779+G795+G811 -> 1304 | H11: =+H27+H43+H59+H75+H91+H107+H123+H139+H155+H171+H187+H203+H219+H235+H251+H267+H283+H299+H315+H331+H347+H363+H379+H395+H411+H427+H443+H459+H475+H491+H507+H523+H539+H555+H571+H587+H603+H619+H635+H651+H667+H683+H699+H715+H731+H747+H763+H779+H795+H811 -> 1415 | I11: =+I27+I43+I59+I75+I91+I107+I123+I139+I155+I171+I187+I203+I219+I235+I251+I267+I283+I299+I315+I331+I347+I363+I379+I395+I411+I427+I443+I459+I475+I491+I507+I523+I539+I555+I571+I587+I603+I619+I635+I651+I667+I683+I699+I715+I731+I747+I763+I779+I795+I811 -> 1217 | J11: =+J27+J43+J59+J75+J91+J107+J123+J139+J155+J171+J187+J203+J219+J235+J251+J267+J283+J299+J315+J331+J347+J363+J379+J395+J411+J427+J443+J459+J475+J491+J507+J523+J539+J555+J571+J587+J603+J619+J635+J651+J667+J683+J699+J715+J731+J747+J763+J779+J795+J811 -> 919 | K11: =+K27+K43+K59+K75+K91+K107+K123+K139+K155+K171+K187+K203+K219+K235+K251+K267+K283+K299+K315+K331+K347+K363+K379+K395+K411+K427+K443+K459+K475+K491+K507+K523+K539+K555+K571+K587+K603+K619+K635+K651+K667+K683+K699+K715+K731+K747+K763+K779+K795+K811 -> 1497 | L11: =SUM(G11:K11) -> 6352 | M11: =ROUND((L11/$E$1),0) -> 1270
C12: Salvations | G12: =+G28+G44+G60+G76+G92+G108+G124+G140+G156+G172+G188+G204+G220+G236+G252+G268+G284+G300+G316+G332+G348+G364+G380+G396+G412+G428+G444+G460+G476+G492+G508+G524+G540+G556+G572+G588+G604+G620+G636+G652+G668+G684+G700+G716+G732+G748+G764+G780+G796+G812 -> 31 | H12: =+H28+H44+H60+H76+H92+H108+H124+H140+H156+H172+H188+H204+H220+H236+H252+H268+H284+H300+H316+H332+H348+H364+H380+H396+H412+H428+H444+H460+H476+H492+H508+H524+H540+H556+H572+H588+H604+H620+H636+H652+H668+H684+H700+H716+H732+H748+H764+H780+H796+H812 -> 29 | I12: =+I28+I44+I60+I76+I92+I108+I124+I140+I156+I172+I188+I204+I220+I236+I252+I268+I284+I300+I316+I332+I348+I364+I380+I396+I412+I428+I444+I460+I476+I492+I508+I524+I540+I556+I572+I588+I604+I620+I636+I652+I668+I684+I700+I716+I732+I748+I764+I780+I796+I812 -> 19 | J12: =+J28+J44+J60+J76+J92+J108+J124+J140+J156+J172+J188+J204+J220+J236+J252+J268+J284+J300+J316+J332+J348+J364+J380+J396+J412+J428+J444+J460+J476+J492+J508+J524+J540+J556+J572+J588+J604+J620+J636+J652+J668+J684+J700+J716+J732+J748+J764+J780+J796+J812 -> 26 | K12: =+K28+K44+K60+K76+K92+K108+K124+K140+K156+K172+K188+K204+K220+K236+K252+K268+K284+K300+K316+K332+K348+K364+K380+K396+K412+K428+K444+K460+K476+K492+K508+K524+K540+K556+K572+K588+K604+K620+K636+K652+K668+K684+K700+K716+K732+K748+K764+K780+K796+K812 -> 45 | L12: =SUM(G12:K12) -> 150 | M12: =ROUND((L12/$E$1),0) -> 30
C13: Baptisms | G13: =+G29+G45+G61+G77+G93+G109+G125+G141+G157+G173+G189+G205+G221+G237+G253+G269+G285+G301+G317+G333+G349+G365+G381+G397+G413+G429+G445+G461+G477+G493+G509+G525+G541+G557+G573+G589+G605+G621+G637+G653+G669+G685+G701+G717+G733+G749+G765+G781+G797+G813 -> 0 | H13: =+H29+H45+H61+H77+H93+H109+H125+H141+H157+H173+H189+H205+H221+H237+H253+H269+H285+H301+H317+H333+H349+H365+H381+H397+H413+H429+H445+H461+H477+H493+H509+H525+H541+H557+H573+H589+H605+H621+H637+H653+H669+H685+H701+H717+H733+H749+H765+H781+H797+H813 -> 0 | I13: =+I29+I45+I61+I77+I93+I109+I125+I141+I157+I173+I189+I205+I221+I237+I253+I269+I285+I301+I317+I333+I349+I365+I381+I397+I413+I429+I445+I461+I477+I493+I509+I525+I541+I557+I573+I589+I605+I621+I637+I653+I669+I685+I701+I717+I733+I749+I765+I781+I797+I813 -> 0 | J13: =+J29+J45+J61+J77+J93+J109+J125+J141+J157+J173+J189+J205+J221+J237+J253+J269+J285+J301+J317+J333+J349+J365+J381+J397+J413+J429+J445+J461+J477+J493+J509+J525+J541+J557+J573+J589+J605+J621+J637+J653+J669+J685+J701+J717+J733+J749+J765+J781+J797+J813 -> 0 | K13: =+K29+K45+K61+K77+K93+K109+K125+K141+K157+K173+K189+K205+K221+K237+K253+K269+K285+K301+K317+K333+K349+K365+K381+K397+K413+K429+K445+K461+K477+K493+K509+K525+K541+K557+K573+K589+K605+K621+K637+K653+K669+K685+K701+K717+K733+K749+K765+K781+K797+K813 -> 0 | L13: =SUM(G13:K13) -> 0 | M13: =ROUND((L13/$E$1),0) -> 0
C14: Home Visits | G14: =+G30+G46+G62+G78+G94+G110+G126+G142+G158+G174+G190+G206+G222+G238+G254+G270+G286+G302+G318+G334+G350+G366+G382+G398+G414+G430+G446+G462+G478+G494+G510+G526+G542+G558+G574+G590+G606+G622+G638+G654+G670+G686+G702+G718+G734+G750+G766+G782+G798+G814 -> 285 | H14: =+H30+H46+H62+H78+H94+H110+H126+H142+H158+H174+H190+H206+H222+H238+H254+H270+H286+H302+H318+H334+H350+H366+H382+H398+H414+H430+H446+H462+H478+H494+H510+H526+H542+H558+H574+H590+H606+H622+H638+H654+H670+H686+H702+H718+H734+H750+H766+H782+H798+H814 -> 293 | I14: =+I30+I46+I62+I78+I94+I110+I126+I142+I158+I174+I190+I206+I222+I238+I254+I270+I286+I302+I318+I334+I350+I366+I382+I398+I414+I430+I446+I462+I478+I494+I510+I526+I542+I558+I574+I590+I606+I622+I638+I654+I670+I686+I702+I718+I734+I750+I766+I782+I798+I814 -> 224 | J14: =+J30+J46+J62+J78+J94+J110+J126+J142+J158+J174+J190+J206+J222+J238+J254+J270+J286+J302+J318+J334+J350+J366+J382+J398+J414+J430+J446+J462+J478+J494+J510+J526+J542+J558+J574+J590+J606+J622+J638+J654+J670+J686+J702+J718+J734+J750+J766+J782+J798+J814 -> 167 | K14: =+K30+K46+K62+K78+K94+K110+K126+K142+K158+K174+K190+K206+K222+K238+K254+K270+K286+K302+K318+K334+K350+K366+K382+K398+K414+K430+K446+K462+K478+K494+K510+K526+K542+K558+K574+K590+K606+K622+K638+K654+K670+K686+K702+K718+K734+K750+K766+K782+K798+K814 -> 283 | L14: =SUM(G14:K14) -> 1252 | M14: =ROUND((L14/$E$1),0) -> 250
C15: Meals / Food Packs | G15: =+G31+G47+G63+G79+G95+G111+G127+G143+G159+G175+G191+G207+G223+G239+G255+G271+G287+G303+G319+G335+G351+G367+G383+G399+G415+G431+G447+G463+G479+G495+G511+G527+G543+G559+G575+G591+G607+G623+G639+G655+G671+G687+G703+G719+G735+G751+G767+G783+G799+G815 -> 1246 | H15: =+H31+H47+H63+H79+H95+H111+H127+H143+H159+H175+H191+H207+H223+H239+H255+H271+H287+H303+H319+H335+H351+H367+H383+H399+H415+H431+H447+H463+H479+H495+H511+H527+H543+H559+H575+H591+H607+H623+H639+H655+H671+H687+H703+H719+H735+H751+H767+H783+H799+H815 -> 1685 | I15: =+I31+I47+I63+I79+I95+I111+I127+I143+I159+I175+I191+I207+I223+I239+I255+I271+I287+I303+I319+I335+I351+I367+I383+I399+I415+I431+I447+I463+I479+I495+I511+I527+I543+I559+I575+I591+I607+I623+I639+I655+I671+I687+I703+I719+I735+I751+I767+I783+I799+I815 -> 2188 | J15: =+J31+J47+J63+J79+J95+J111+J127+J143+J159+J175+J191+J207+J223+J239+J255+J271+J287+J303+J319+J335+J351+J367+J383+J399+J415+J431+J447+J463+J479+J495+J511+J527+J543+J559+J575+J591+J607+J623+J639+J655+J671+J687+J703+J719+J735+J751+J767+J783+J799+J815 -> 1434 | K15: =+K31+K47+K63+K79+K95+K111+K127+K143+K159+K175+K191+K207+K223+K239+K255+K271+K287+K303+K319+K335+K351+K367+K383+K399+K415+K431+K447+K463+K479+K495+K511+K527+K543+K559+K575+K591+K607+K623+K639+K655+K671+K687+K703+K719+K735+K751+K767+K783+K799+K815 -> 1039 | L15: =SUM(G15:K15) -> 7592 | M15: =ROUND((L15/$E$1),0) -> 1518
C16: Preschool Attendance | G16: =+G32+G48+G64+G80+G96+G112+G128+G144+G160+G176+G192+G208+G224+G240+G256+G272+G288+G304+G320+G336+G352+G368+G384+G400+G416+G432+G448+G464+G480+G496+G512+G528+G544+G560+G576+G592+G608+G624+G640+G656+G672+G688+G704+G720+G736+G752+G768+G784+G800+G816 -> 0 | H16: =+H32+H48+H64+H80+H96+H112+H128+H144+H160+H176+H192+H208+H224+H240+H256+H272+H288+H304+H320+H336+H352+H368+H384+H400+H416+H432+H448+H464+H480+H496+H512+H528+H544+H560+H576+H592+H608+H624+H640+H656+H672+H688+H704+H720+H736+H752+H768+H784+H800+H816 -> 0 | I16: =+I32+I48+I64+I80+I96+I112+I128+I144+I160+I176+I192+I208+I224+I240+I256+I272+I288+I304+I320+I336+I352+I368+I384+I400+I416+I432+I448+I464+I480+I496+I512+I528+I544+I560+I576+I592+I608+I624+I640+I656+I672+I688+I704+I720+I736+I752+I768+I784+I800+I816 -> 0 | J16: =+J32+J48+J64+J80+J96+J112+J128+J144+J160+J176+J192+J208+J224+J240+J256+J272+J288+J304+J320+J336+J352+J368+J384+J400+J416+J432+J448+J464+J480+J496+J512+J528+J544+J560+J576+J592+J608+J624+J640+J656+J672+J688+J704+J720+J736+J752+J768+J784+J800+J816 -> 0 | K16: =+K32+K48+K64+K80+K96+K112+K128+K144+K160+K176+K192+K208+K224+K240+K256+K272+K288+K304+K320+K336+K352+K368+K384+K400+K416+K432+K448+K464+K480+K496+K512+K528+K544+K560+K576+K592+K608+K624+K640+K656+K672+K688+K704+K720+K736+K752+K768+K784+K800+K816 -> 0 | L16: =SUM(G16:K16) -> 0 | M16: =ROUND((L16/$E$1),0) -> 0
A19: 1 | C19: Hawane CLC Church | G19: =+$G$3 -> 2024 | H19: =+G19 -> 2024 | I19: =+H19 -> 2024 | J19: =+I19 -> 2024 | K19: =+J19 -> 2024 | L19: =+K19 -> 2024 | M19: =+L19 -> 2024 | S19: =+C19 -> Hawane CLC Church | T19: =+L23 -> 1046 | U19: =+L24+L25 -> 343 | V19: =+L26+L27 -> 703 | W19: =+L30 -> 27 | X19: =+L28 -> 0
C20: =+$C4 -> September 2024 | G20: =+$G$4 -> Sep | H20: =+G20 -> Sep | I20: =+H20 -> Sep | J20: =+I20 -> Sep | K20: =+J20 -> Sep | L20: =+K20 -> Sep | M20: =+L20 -> Sep
G21: =+$G$5 -> 1 | H21: =+$H$5 -> 8 | I21: =+$I$5 -> 15 | J21: =+$J$5 -> 22 | K21: =+$K$5 -> 29 | L21: Total | M21: Average
C23: Church Attendance: | G23: =SUM(G24:G27) -> 190 | H23: =SUM(H24:H27) -> 235 | I23: =SUM(I24:I27) -> 247 | J23: =SUM(J24:J27) -> 161 | K23: =SUM(K24:K27) -> 213 | L23: =SUM(L24:L27) -> 1046 | M23: =ROUND((L23/$E$1),0) -> 209
D24: Men | G24: 26 | H24: 18 | I24: 21 | J24: 28 | K24: 18 | L24: =SUM(G24:K24) -> 111 | M24: =ROUND((L24/$E$1),0) -> 22
D25: Women | G25: 44 | H25: 47 | I25: 59 | J25: 34 | K25: 48 | L25: =SUM(G25:K25) -> 232 | M25: =ROUND((L25/$E$1),0) -> 46
D26: Youth | G26: 66 | H26: 98 | I26: 86 | J26: 63 | K26: 88 | L26: =SUM(G26:K26) -> 401 | M26: =ROUND((L26/$E$1),0) -> 80
D27: Children | G27: 54 | H27: 72 | I27: 81 | J27: 36 | K27: 59 | L27: =SUM(G27:K27) -> 302 | M27: =ROUND((L27/$E$1),0) -> 60
C28: Salvations | L28: =SUM(G28:K28) -> 0 | M28: =ROUND((L28/$E$1),0) -> 0
C29: Baptisms | L29: =SUM(G29:K29) -> 0 | M29: =ROUND((L29/$E$1),0) -> 0
C30: Home Visits | G30: 5 | H30: 6 | I30: 9 | J30: 1 | K30: 6 | L30: =SUM(G30:K30) -> 27 | M30: =ROUND((L30/$E$1),0) -> 5
C31: Meals / Food Packs | L31: =SUM(G31:K31) -> 0 | M31: =ROUND((L31/$E$1),0) -> 0
C32: Preschool Attendance | L32: =SUM(G32:K32) -> 0 | M32: =ROUND((L32/$E$1),0) -> 0
A35: =+A19+1 -> 2 | C35: Ngwenya | G35: =+$G$3 -> 2024 | H35: =+G35 -> 2024 | I35: =+H35 -> 2024 | J35: =+I35 -> 2024 | K35: =+J35 -> 2024 | L35: =+K35 -> 2024 | M35: =+L35 -> 2024 | S35: =+C35 -> Ngwenya | T35: =+L39 -> 405 | U35: =+L40+L41 -> 99 | V35: =+L42+L43 -> 306 | W35: =+L46 -> 62 | X35: =+L44 -> 7
C36: =+$C20 -> September 2024 | G36: =+$G$4 -> Sep | H36: =+G36 -> Sep | I36: =+H36 -> Sep | J36: =+I36 -> Sep | K36: =+J36 -> Sep | L36: =+K36 -> Sep | M36: =+L36 -> Sep
G37: =+$G$5 -> 1 | H37: =+$H$5 -> 8 | I37: =+$I$5 -> 15 | J37: =+$J$5 -> 22 | K37: =+$K$5 -> 29 | L37: Total | M37: Average
C39: Church Attendance: | G39: =SUM(G40:G43) -> 82 | H39: =SUM(H40:H43) -> 81 | I39: =SUM(I40:I43) -> 86 | J39: =SUM(J40:J43) -> 56 | K39: =SUM(K40:K43) -> 100 | L39: =SUM(L40:L43) -> 405 | M39: =ROUND((L39/$E$1),0) -> 81
D40: Men | G40: 6 | H40: 4 | I40: 6 | J40: 3 | K40: 5 | L40: =SUM(G40:K40) -> 24 | M40: =ROUND((L40/$E$1),0) -> 5
D41: Women | G41: 16 | H41: 15 | I41: 16 | J41: 10 | K41: 18 | L41: =SUM(G41:K41) -> 75 | M41: =ROUND((L41/$E$1),0) -> 15
D42: Youth | G42: 20 | H42: 22 | I42: 20 | J42: 13 | K42: 35 | L42: =SUM(G42:K42) -> 110 | M42: =ROUND((L42/$E$1),0) -> 22
D43: Children | G43: 40 | H43: 40 | I43: 44 | J43: 30 | K43: 42 | L43: =SUM(G43:K43) -> 196 | M43: =ROUND((L43/$E$1),0) -> 39
C44: Salvations | I44: 2 | K44: 5 | L44: =SUM(G44:K44) -> 7 | M44: =ROUND((L44/$E$1),0) -> 1
C45: Baptisms | L45: =SUM(G45:K45) -> 0 | M45: =ROUND((L45/$E$1),0) -> 0
C46: Home Visits | G46: 12 | H46: 11 | I46: 12 | J46: 13 | K46: 14 | L46: =SUM(G46:K46) -> 62 | M46: =ROUND((L46/$E$1),0) -> 12
C47: Meals / Food Packs | G47: 108 | H47: 72 | I47: 144 | J47: 96 | K47: 128 | L47: =SUM(G47:K47) -> 548 | M47: =ROUND((L47/$E$1),0) -> 110
C48: Preschool Attendance | L48: =SUM(G48:K48) -> 0 | M48: =ROUND((L48/$E$1),0) -> 0
...

Sheet Oct-24
D1: Number of Sundays | E1: 4 | S1: ICBC | T1: =+C7 -> Church Attendance: | U1: Adults | V1: Youth & Children | W1: Home Visits | X1: =+C12 -> Salvations
C3: Total ICBC | G3: 2024 | H3: =+G3 -> 2024 | I3: =+H3 -> 2024 | J3: =+I3 -> 2024 | K3: =+J3 -> 2024 | L3: =+K3 -> 2024 | M3: =+L3 -> 2024 | S3: =+C3 -> Total ICBC | T3: =+L7 -> 11252 | U3: =+L8+L9 -> 2634 | V3: =+L10+L11 -> 8618 | W3: =+L14 -> 566 | X3: =+L12 -> 196
C4: October 2024 | G4: Oct | H4: =+G4 -> Oct | I4: =+H4 -> Oct | J4: =+I4 -> Oct | K4: =+J4 -> Oct | L4: =+K4 -> Oct | M4: =+L4 -> Oct
G5: 6 | H5: 13 | I5: 20 | J5: 27 | K5: 0 | L5: Total | M5: Average
C7: Church Attendance: | G7: =SUM(G8:G11) -> 3164 | H7: =SUM(H8:H11) -> 2866 | I7: =SUM(I8:I11) -> 2624 | J7: =SUM(J8:J11) -> 2598 | K7: =SUM(K8:K11) -> 0 | L7: =SUM(L8:L11) -> 11252 | M7: =ROUND((L7/$E$1),0) -> 2813
D8: Men | G8: =+G24+G40+G56+G72+G88+G104+G120+G136+G152+G168+G184+G200+G216+G232+G248+G264+G280+G296+G312+G328+G344+G360+G376+G392+G408+G424+G440+G456+G472+G488+G504+G520+G536+G552+G568+G584+G600+G616+G632+G648+G664+G680+G696+G712+G728+G744+G760+G776+G792+G808 -> 199 | H8: =+H24+H40+H56+H72+H88+H104+H120+H136+H152+H168+H184+H200+H216+H232+H248+H264+H280+H296+H312+H328+H344+H360+H376+H392+H408+H424+H440+H456+H472+H488+H504+H520+H536+H552+H568+H584+H600+H616+H632+H648+H664+H680+H696+H712+H728+H744+H760+H776+H792+H808 -> 211 | I8: =+I24+I40+I56+I72+I88+I104+I120+I136+I152+I168+I184+I200+I216+I232+I248+I264+I280+I296+I312+I328+I344+I360+I376+I392+I408+I424+I440+I456+I472+I488+I504+I520+I536+I552+I568+I584+I600+I616+I632+I648+I664+I680+I696+I712+I728+I744+I760+I776+I792+I808 -> 177 | J8: =+J24+J40+J56+J72+J88+J104+J120+J136+J152+J168+J184+J200+J216+J232+J248+J264+J280+J296+J312+J328+J344+J360+J376+J392+J408+J424+J440+J456+J472+J488+J504+J520+J536+J552+J568+J584+J600+J616+J632+J648+J664+J680+J696+J712+J728+J744+J760+J776+J792+J808 -> 162 | K8: =+K24+K40+K56+K72+K88+K104+K120+K136+K152+K168+K184+K200+K216+K232+K248+K264+K280+K296+K312+K328+K344+K360+K376+K392+K408+K424+K440+K456+K472+K488+K504+K520+K536+K552+K568+K584+K600+K616+K632+K648+K664+K680+K696+K712+K728+K744+K760+K776+K792+K808 -> 0 | L8: =SUM(G8:K8) -> 749 | M8: =ROUND((L8/$E$1),0) -> 187
D9: Women | G9: =+G25+G41+G57+G73+G89+G105+G121+G137+G153+G169+G185+G201+G217+G233+G249+G265+G281+G297+G313+G329+G345+G361+G377+G393+G409+G425+G441+G457+G473+G489+G505+G521+G537+G553+G569+G585+G601+G617+G633+G649+G665+G681+G697+G713+G729+G745+G761+G777+G793+G809 -> 502 | H9: =+H25+H41+H57+H73+H89+H105+H121+H137+H153+H169+H185+H201+H217+H233+H249+H265+H281+H297+H313+H329+H345+H361+H377+H393+H409+H425+H441+H457+H473+H489+H505+H521+H537+H553+H569+H585+H601+H617+H633+H649+H665+H681+H697+H713+H729+H745+H761+H777+H793+H809 -> 491 | I9: =+I25+I41+I57+I73+I89+I105+I121+I137+I153+I169+I185+I201+I217+I233+I249+I265+I281+I297+I313+I329+I345+I361+I377+I393+I409+I425+I441+I457+I473+I489+I505+I521+I537+I553+I569+I585+I601+I617+I633+I649+I665+I681+I697+I713+I729+I745+I761+I777+I793+I809 -> 466 | J9: =+J25+J41+J57+J73+J89+J105+J121+J137+J153+J169+J185+J201+J217+J233+J249+J265+J281+J297+J313+J329+J345+J361+J377+J393+J409+J425+J441+J457+J473+J489+J505+J521+J537+J553+J569+J585+J601+J617+J633+J649+J665+J681+J697+J713+J729+J745+J761+J777+J793+J809 -> 426 | K9: =+K25+K41+K57+K73+K89+K105+K121+K137+K153+K169+K185+K201+K217+K233+K249+K265+K281+K297+K313+K329+K345+K361+K377+K393+K409+K425+K441+K457+K473+K489+K505+K521+K537+K553+K569+K585+K601+K617+K633+K649+K665+K681+K697+K713+K729+K745+K761+K777+K793+K809 -> 0 | L9: =SUM(G9:K9) -> 1885 | M9: =ROUND((L9/$E$1),0) -> 471
D10: Youth | G10: =+G26+G42+G58+G74+G90+G106+G122+G138+G154+G170+G186+G202+G218+G234+G250+G266+G282+G298+G314+G330+G346+G362+G378+G394+G410+G426+G442+G458+G474+G490+G506+G522+G538+G554+G570+G586+G602+G618+G634+G650+G666+G682+G698+G714+G730+G746+G762+G778+G794+G810 -> 953 | H10: =+H26+H42+H58+H74+H90+H106+H122+H138+H154+H170+H186+H202+H218+H234+H250+H266+H282+H298+H314+H330+H346+H362+H378+H394+H410+H426+H442+H458+H474+H490+H506+H522+H538+H554+H570+H586+H602+H618+H634+H650+H666+H682+H698+H714+H730+H746+H762+H778+H794+H810 -> 695 | I10: =+I26+I42+I58+I74+I90+I106+I122+I138+I154+I170+I186+I202+I218+I234+I250+I266+I282+I298+I314+I330+I346+I362+I378+I394+I410+I426+I442+I458+I474+I490+I506+I522+I538+I554+I570+I586+I602+I618+I634+I650+I666+I682+I698+I714+I730+I746+I762+I778+I794+I810 -> 646 | J10: =+J26+J42+J58+J74+J90+J106+J122+J138+J154+J170+J186+J202+J218+J234+J250+J266+J282+J298+J314+J330+J346+J362+J378+J394+J410+J426+J442+J458+J474+J490+J506+J522+J538+J554+J570+J586+J602+J618+J634+J650+J666+J682+J698+J714+J730+J746+J762+J778+J794+J810 -> 617 | K10: =+K26+K42+K58+K74+K90+K106+K122+K138+K154+K170+K186+K202+K218+K234+K250+K266+K282+K298+K314+K330+K346+K362+K378+K394+K410+K426+K442+K458+K474+K490+K506+K522+K538+K554+K570+K586+K602+K618+K634+K650+K666+K682+K698+K714+K730+K746+K762+K778+K794+K810 -> 0 | L10: =SUM(G10:K10) -> 2911 | M10: =ROUND((L10/$E$1),0) -> 728
D11: Children | G11: =+G27+G43+G59+G75+G91+G107+G123+G139+G155+G171+G187+G203+G219+G235+G251+G267+G283+G299+G315+G331+G347+G363+G379+G395+G411+G427+G443+G459+G475+G491+G507+G523+G539+G555+G571+G587+G603+G619+G635+G651+G667+G683+G699+G715+G731+G747+G763+G779+G795+G811 -> 1510 | H11: =+H27+H43+H59+H75+H91+H107+H123+H139+H155+H171+H187+H203+H219+H235+H251+H267+H283+H299+H315+H331+H347+H363+H379+H395+H411+H427+H443+H459+H475+H491+H507+H523+H539+H555+H571+H587+H603+H619+H635+H651+H667+H683+H699+H715+H731+H747+H763+H779+H795+H811 -> 1469 | I11: =+I27+I43+I59+I75+I91+I107+I123+I139+I155+I171+I187+I203+I219+I235+I251+I267+I283+I299+I315+I331+I347+I363+I379+I395+I411+I427+I443+I459+I475+I491+I507+I523+I539+I555+I571+I587+I603+I619+I635+I651+I667+I683+I699+I715+I731+I747+I763+I779+I795+I811 -> 1335 | J11: =+J27+J43+J59+J75+J91+J107+J123+J139+J155+J171+J187+J203+J219+J235+J251+J267+J283+J299+J315+J331+J347+J363+J379+J395+J411+J427+J443+J459+J475+J491+J507+J523+J539+J555+J571+J587+J603+J619+J635+J651+J667+J683+J699+J715+J731+J747+J763+J779+J795+J811 -> 1393 | K11: =+K27+K43+K59+K75+K91+K107+K123+K139+K155+K171+K187+K203+K219+K235+K251+K267+K283+K299+K315+K331+K347+K363+K379+K395+K411+K427+K443+K459+K475+K491+K507+K523+K539+K555+K571+K587+K603+K619+K635+K651+K667+K683+K699+K715+K731+K747+K763+K779+K795+K811 -> 0 | L11: =SUM(G11:K11) -> 5707 | M11: =ROUND((L11/$E$1),0) -> 1427
C12: Salvations | G12: =+G28+G44+G60+G76+G92+G108+G124+G140+G156+G172+G188+G204+G220+G236+G252+G268+G284+G300+G316+G332+G348+G364+G380+G396+G412+G428+G444+G460+G476+G492+G508+G524+G540+G556+G572+G588+G604+G620+G636+G652+G668+G684+G700+G716+G732+G748+G764+G780+G796+G812 -> 112 | H12: =+H28+H44+H60+H76+H92+H108+H124+H140+H156+H172+H188+H204+H220+H236+H252+H268+H284+H300+H316+H332+H348+H364+H380+H396+H412+H428+H444+H460+H476+H492+H508+H524+H540+H556+H572+H588+H604+H620+H636+H652+H668+H684+H700+H716+H732+H748+H764+H780+H796+H812 -> 34 | I12: =+I28+I44+I60+I76+I92+I108+I124+I140+I156+I172+I188+I204+I220+I236+I252+I268+I284+I300+I316+I332+I348+I364+I380+I396+I412+I428+I444+I460+I476+I492+I508+I524+I540+I556+I572+I588+I604+I620+I636+I652+I668+I684+I700+I716+I732+I748+I764+I780+I796+I812 -> 33 | J12: =+J28+J44+J60+J76+J92+J108+J124+J140+J156+J172+J188+J204+J220+J236+J252+J268+J284+J300+J316+J332+J348+J364+J380+J396+J412+J428+J444+J460+J476+J492+J508+J524+J540+J556+J572+J588+J604+J620+J636+J652+J668+J684+J700+J716+J732+J748+J764+J780+J796+J812 -> 17 | K12: =+K28+K44+K60+K76+K92+K108+K124+K140+K156+K172+K188+K204+K220+K236+K252+K268+K284+K300+K316+K332+K348+K364+K380+K396+K412+K428+K444+K460+K476+K492+K508+K524+K540+K556+K572+K588+K604+K620+K636+K652+K668+K684+K700+K716+K732+K748+K764+K780+K796+K812 -> 0 | L12: =SUM(G12:K12) -> 196 | M12: =ROUND((L12/$E$1),0) -> 49
C13: Baptisms | G13: =+G29+G45+G61+G77+G93+G109+G125+G141+G157+G173+G189+G205+G221+G237+G253+G269+G285+G301+G317+G333+G349+G365+G381+G397+G413+G429+G445+G461+G477+G493+G509+G525+G541+G557+G573+G589+G605+G621+G637+G653+G669+G685+G701+G717+G733+G749+G765+G781+G797+G813 -> 0 | H13: =+H29+H45+H61+H77+H93+H109+H125+H141+H157+H173+H189+H205+H221+H237+H253+H269+H285+H301+H317+H333+H349+H365+H381+H397+H413+H429+H445+H461+H477+H493+H509+H525+H541+H557+H573+H589+H605+H621+H637+H653+H669+H685+H701+H717+H733+H749+H765+H781+H797+H813 -> 0 | I13: =+I29+I45+I61+I77+I93+I109+I125+I141+I157+I173+I189+I205+I221+I237+I253+I269+I285+I301+I317+I333+I349+I365+I381+I397+I413+I429+I445+I461+I477+I493+I509+I525+I541+I557+I573+I589+I605+I621+I637+I653+I669+I685+I701+I717+I733+I749+I765+I781+I797+I813 -> 0 | J13: =+J29+J45+J61+J77+J93+J109+J125+J141+J157+J173+J189+J205+J221+J237+J253+J269+J285+J301+J317+J333+J349+J365+J381+J397+J413+J429+J445+J461+J477+J493+J509+J525+J541+J557+J573+J589+J605+J621+J637+J653+J669+J685+J701+J717+J733+J749+J765+J781+J797+J813 -> 0 | K13: =+K29+K45+K61+K77+K93+K109+K125+K141+K157+K173+K189+K205+K221+K237+K253+K269+K285+K301+K317+K333+K349+K365+K381+K397+K413+K429+K445+K461+K477+K493+K509+K525+K541+K557+K573+K589+K605+K621+K637+K653+K669+K685+K701+K717+K733+K749+K765+K781+K797+K813 -> 0 | L13: =SUM(G13:K13) -> 0 | M13: =ROUND((L13/$E$1),0) -> 0
