Workbook

Sheet Nov21
D1: Number of Sundays | E1: 4
C3: Total ICBC | G3: 2021 | H3: =+G3 -> 2021 | I3: =+H3 -> 2021 | J3: =+I3 -> 2021 | K3: =+J3 -> 2021 | L3: =+K3 -> 2021 | M3: =+L3 -> 2021
C4: November 2021 | G4: Nov | H4: =+G4 -> Nov | I4: =+H4 -> Nov | J4: =+I4 -> Nov | K4: =+J4 -> Nov | L4: =+K4 -> Nov | M4: =+L4 -> Nov
G5: 7 | H5: 14 | I5: 21 | J5: 28 | L5: Total | M5: Average
C7: Church Attendance: | G7: =SUM(G8:G11) -> 1179 | H7: =SUM(H8:H11) -> 1517 | I7: =SUM(I8:I11) -> 1263 | J7: =SUM(J8:J11) -> 1482 | K7: =SUM(K8:K11) -> 0 | L7: =SUM(L8:L11) -> 5441 | M7: =ROUND((L7/$E$1),0) -> 1360
D8: Men | G8: =+G24+G40+G56+G72+G88+G104+G120+G136+G152+G168+G184+G200+G216+G232+G248+G264+G280+G296+G312+G328+G344+G360+G376+G392+G408+G424+G440+G456+G472+G488 -> 89 | H8: =+H24+H40+H56+H72+H88+H104+H120+H136+H152+H168+H184+H200+H216+H232+H248+H264+H280+H296+H312+H328+H344+H360+H376+H392+H408+H424+H440+H456+H472+H488 -> 95 | I8: =+I24+I40+I56+I72+I88+I104+I120+I136+I152+I168+I184+I200+I216+I232+I248+I264+I280+I296+I312+I328+I344+I360+I376+I392+I408+I424+I440+I456+I472+I488 -> 94 | J8: =+J24+J40+J56+J72+J88+J104+J120+J136+J152+J168+J184+J200+J216+J232+J248+J264+J280+J296+J312+J328+J344+J360+J376+J392+J408+J424+J440+J456+J472+J488 -> 94 | K8: =+K24+K40+K56+K72+K88+K104+K120+K136+K152+K168+K184+K200+K216+K232+K248+K264+K280+K296+K312+K328+K344+K360+K376+K392+K408+K424+K440+K456+K472+K488 -> 0 | L8: =SUM(G8:K8) -> 372 | M8: =ROUND((L8/$E$1),0) -> 93
D9: Women | G9: =+G25+G41+G57+G73+G89+G105+G121+G137+G153+G169+G185+G201+G217+G233+G249+G265+G281+G297+G313+G329+G345+G361+G377+G393+G409+G425+G441+G457+G473+G489 -> 217 | H9: =+H25+H41+H57+H73+H89+H105+H121+H137+H153+H169+H185+H201+H217+H233+H249+H265+H281+H297+H313+H329+H345+H361+H377+H393+H409+H425+H441+H457+H473+H489 -> 278 | I9: =+I25+I41+I57+I73+I89+I105+I121+I137+I153+I169+I185+I201+I217+I233+I249+I265+I281+I297+I313+I329+I345+I361+I377+I393+I409+I425+I441+I457+I473+I489 -> 247 | J9: =+J25+J41+J57+J73+J89+J105+J121+J137+J153+J169+J185+J201+J217+J233+J249+J265+J281+J297+J313+J329+J345+J361+J377+J393+J409+J425+J441+J457+J473+J489 -> 295 | K9: =+K25+K41+K57+K73+K89+K105+K121+K137+K153+K169+K185+K201+K217+K233+K249+K265+K281+K297+K313+K329+K345+K361+K377+K393+K409+K425+K441+K457+K473+K489 -> 0 | L9: =SUM(G9:K9) -> 1037 | M9: =ROUND((L9/$E$1),0) -> 259
D10: Youth | G10: =+G26+G42+G58+G74+G90+G106+G122+G138+G154+G170+G186+G202+G218+G234+G250+G266+G282+G298+G314+G330+G346+G362+G378+G394+G410+G426+G442+G458+G474+G490 -> 282 | H10: =+H26+H42+H58+H74+H90+H106+H122+H138+H154+H170+H186+H202+H218+H234+H250+H266+H282+H298+H314+H330+H346+H362+H378+H394+H410+H426+H442+H458+H474+H490 -> 456 | I10: =+I26+I42+I58+I74+I90+I106+I122+I138+I154+I170+I186+I202+I218+I234+I250+I266+I282+I298+I314+I330+I346+I362+I378+I394+I410+I426+I442+I458+I474+I490 -> 354 | J10: =+J26+J42+J58+J74+J90+J106+J122+J138+J154+J170+J186+J202+J218+J234+J250+J266+J282+J298+J314+J330+J346+J362+J378+J394+J410+J426+J442+J458+J474+J490 -> 415 | K10: =+K26+K42+K58+K74+K90+K106+K122+K138+K154+K170+K186+K202+K218+K234+K250+K266+K282+K298+K314+K330+K346+K362+K378+K394+K410+K426+K442+K458+K474+K490 -> 0 | L10: =SUM(G10:K10) -> 1507 | M10: =ROUND((L10/$E$1),0) -> 377
D11: Children | G11: =+G27+G43+G59+G75+G91+G107+G123+G139+G155+G171+G187+G203+G219+G235+G251+G267+G283+G299+G315+G331+G347+G363+G379+G395+G411+G427+G443+G459+G475+G491 -> 591 | H11: =+H27+H43+H59+H75+H91+H107+H123+H139+H155+H171+H187+H203+H219+H235+H251+H267+H283+H299+H315+H331+H347+H363+H379+H395+H411+H427+H443+H459+H475+H491 -> 688 | I11: =+I27+I43+I59+I75+I91+I107+I123+I139+I155+I171+I187+I203+I219+I235+I251+I267+I283+I299+I315+I331+I347+I363+I379+I395+I411+I427+I443+I459+I475+I491 -> 568 | J11: =+J27+J43+J59+J75+J91+J107+J123+J139+J155+J171+J187+J203+J219+J235+J251+J267+J283+J299+J315+J331+J347+J363+J379+J395+J411+J427+J443+J459+J475+J491 -> 678 | K11: =+K27+K43+K59+K75+K91+K107+K123+K139+K155+K171+K187+K203+K219+K235+K251+K267+K283+K299+K315+K331+K347+K363+K379+K395+K411+K427+K443+K459+K475+K491 -> 0 | L11: =SUM(G11:K11) -> 2525 | M11: =ROUND((L11/$E$1),0) -> 631
C12: Salvations | G12: =+G28+G44+G60+G76+G92+G108+G124+G140+G156+G172+G188+G204+G220+G236+G252+G268+G284+G300+G316+G332+G348+G364+G380+G396+G412+G428+G444+G460+G476+G492 -> 2 | H12: =+H28+H44+H60+H76+H92+H108+H124+H140+H156+H172+H188+H204+H220+H236+H252+H268+H284+H300+H316+H332+H348+H364+H380+H396+H412+H428+H444+H460+H476+H492 -> 23 | I12: =+I28+I44+I60+I76+I92+I108+I124+I140+I156+I172+I188+I204+I220+I236+I252+I268+I284+I300+I316+I332+I348+I364+I380+I396+I412+I428+I444+I460+I476+I492 -> 12 | J12: =+J28+J44+J60+J76+J92+J108+J124+J140+J156+J172+J188+J204+J220+J236+J252+J268+J284+J300+J316+J332+J348+J364+J380+J396+J412+J428+J444+J460+J476+J492 -> 0 | K12: =+K28+K44+K60+K76+K92+K108+K124+K140+K156+K172+K188+K204+K220+K236+K252+K268+K284+K300+K316+K332+K348+K364+K380+K396+K412+K428+K444+K460+K476+K492 -> 0 | L12: =SUM(G12:K12) -> 37 | M12: =ROUND((L12/$E$1),0) -> 9
C13: Baptisms | G13: =+G29+G45+G61+G77+G93+G109+G125+G141+G157+G173+G189+G205+G221+G237+G253+G269+G285+G301+G317+G333+G349+G365+G381+G397+G413+G429+G445+G461+G477+G493 -> 0 | H13: =+H29+H45+H61+H77+H93+H109+H125+H141+H157+H173+H189+H205+H221+H237+H253+H269+H285+H301+H317+H333+H349+H365+H381+H397+H413+H429+H445+H461+H477+H493 -> 0 | I13: =+I29+I45+I61+I77+I93+I109+I125+I141+I157+I173+I189+I205+I221+I237+I253+I269+I285+I301+I317+I333+I349+I365+I381+I397+I413+I429+I445+I461+I477+I493 -> 0 | J13: =+J29+J45+J61+J77+J93+J109+J125+J141+J157+J173+J189+J205+J221+J237+J253+J269+J285+J301+J317+J333+J349+J365+J381+J397+J413+J429+J445+J461+J477+J493 -> 0 | K13: =+K29+K45+K61+K77+K93+K109+K125+K141+K157+K173+K189+K205+K221+K237+K253+K269+K285+K301+K317+K333+K349+K365+K381+K397+K413+K429+K445+K461+K477+K493 -> 0 | L13: =SUM(G13:K13) -> 0 | M13: =ROUND((L13/$E$1),0) -> 0
C14: Home Visits | G14: =+G30+G46+G62+G78+G94+G110+G126+G142+G158+G174+G190+G206+G222+G238+G254+G270+G286+G302+G318+G334+G350+G366+G382+G398+G414+G430+G446+G462+G478+G494 -> 27 | H14: =+H30+H46+H62+H78+H94+H110+H126+H142+H158+H174+H190+H206+H222+H238+H254+H270+H286+H302+H318+H334+H350+H366+H382+H398+H414+H430+H446+H462+H478 -> 25 | I14: =+I30+I46+I62+I78+I94+I110+I126+I142+I158+I174+I190+I206+I222+I238+I254+I270+I286+I302+I318+I334+I350+I366+I382+I398+I414+I430+I446+I462+I478+I494 -> 32 | J14: =+J30+J46+J62+J78+J94+J110+J126+J142+J158+J174+J190+J206+J222+J238+J254+J270+J286+J302+J318+J334+J350+J366+J382+J398+J414+J430+J446+J462+J478+J494 -> 28 | K14: =+K30+K46+K62+K78+K94+K110+K126+K142+K158+K174+K190+K206+K222+K238+K254+K270+K286+K302+K318+K334+K350+K366+K382+K398+K414+K430+K446+K462+K478+K494 -> 0 | L14: =SUM(G14:K14) -> 112 | M14: =ROUND((L14/$E$1),0) -> 28
C15: Meals / Food Packs | G15: =+G31+G47+G63+G79+G95+G111+G127+G143+G159+G175+G191+G207+G223+G239+G255+G271+G287+G303+G319+G335+G351+G367+G383+G399+G415+G431+G447+G463+G479+G495 -> 0 | H15: =+H31+H47+H63+H79+H95+H111+H127+H143+H159+H175+H191+H207+H223+H239+H255+H271+H287+H303+H319+H335+H351+H367+H383+H399+H415+H431+H447+H463+H479+H495 -> 316 | I15: =+I31+I47+I63+I79+I95+I111+I127+I143+I159+I175+I191+I207+I223+I239+I255+I271+I287+I303+I319+I335+I351+I367+I383+I399+I415+I431+I447+I463+I479+I495 -> 116 | J15: =+J31+J47+J63+J79+J95+J111+J127+J143+J159+J175+J191+J207+J223+J239+J255+J271+J287+J303+J319+J335+J351+J367+J383+J399+J415+J431+J447+J463+J479+J495 -> 39 | K15: =+K31+K47+K63+K79+K95+K111+K127+K143+K159+K175+K191+K207+K223+K239+K255+K271+K287+K303+K319+K335+K351+K367+K383+K399+K415+K431+K447+K463+K479+K495 -> 0 | L15: =SUM(G15:K15) -> 471 | M15: =ROUND((L15/$E$1),0) -> 118
C16: Preschool Attendance | G16: =+G32+G48+G64+G80+G96+G112+G128+G144+G160+G176+G192+G208+G224+G240+G256+G272+G288+G304+G320+G336+G352+G368+G384+G400+G416+G432+G448+G464+G480+G496 -> 34 | H16: =+H32+H48+H64+H80+H96+H112+H128+H144+H160+H176+H192+H208+H224+H240+H256+H272+H288+H304+H320+H336+H352+H368+H384+H400+H416+H432+H448+H464+H480+H496 -> 0 | I16: =+I32+I48+I64+I80+I96+I112+I128+I144+I160+I176+I192+I208+I224+I240+I256+I272+I288+I304+I320+I336+I352+I368+I384+I400+I416+I432+I448+I464+I480+I496 -> 43 | J16: =+J32+J48+J64+J80+J96+J112+J128+J144+J160+J176+J192+J208+J224+J240+J256+J272+J288+J304+J320+J336+J352+J368+J384+J400+J416+J432+J448+J464+J480+J496 -> 60 | K16: =+K32+K48+K64+K80+K96+K112+K128+K144+K160+K176+K192+K208+K224+K240+K256+K272+K288+K304+K320+K336+K352+K368+K384+K400+K416+K432+K448+K464+K480+K496 -> 0 | L16: =SUM(G16:K16) -> 137 | M16: =ROUND((L16/$E$1),0) -> 34
A19: 1 | C19: Hawane CLC Church | G19: =+$G$3 -> 2021 | H19: =+G19 -> 2021 | I19: =+H19 -> 2021 | J19: =+I19 -> 2021 | K19: =+J19 -> 2021 | L19: =+K19 -> 2021 | M19: =+L19 -> 2021
C20: November 2021 | G20: =+$G$4 -> Nov | H20: =+G20 -> Nov | I20: =+H20 -> Nov | J20: =+I20 -> Nov | K20: =+J20 -> Nov | L20: =+K20 -> Nov | M20: =+L20 -> Nov
G21: =+$G$5 -> 7 | H21: =+$H$5 -> 14 | I21: =+$I$5 -> 21 | J21: =+$J$5 -> 28 | K21: =+$K$5 -> 0 | L21: Total | M21: Average
C23: Church Attendance: | G23: =SUM(G24:G27) -> 0 | H23: =SUM(H24:H27) -> 172 | I23: =SUM(I24:I27) -> 130 | J23: =SUM(J24:J27) -> 183 | K23: =SUM(K24:K27) -> 0 | L23: =SUM(L24:L27) -> 485 | M23: =ROUND((L23/$E$1),0) -> 121
D24: Men | H24: 6 | I24: 14 | J24: 7 | L24: =SUM(G24:K24) -> 27 | M24: =ROUND((L24/$E$1),0) -> 7
D25: Women | H25: 27 | I25: 24 | J25: 38 | L25: =SUM(G25:K25) -> 89 | M25: =ROUND((L25/$E$1),0) -> 22
D26: Youth | H26: 62 | I26: 39 | J26: 46 | L26: =SUM(G26:K26) -> 147 | M26: =ROUND((L26/$E$1),0) -> 37
D27: Children | H27: 77 | I27: 53 | J27: 92 | L27: =SUM(G27:K27) -> 222 | M27: =ROUND((L27/$E$1),0) -> 56
C28: Salvations | L28: =SUM(G28:K28) -> 0 | M28: =ROUND((L28/$E$1),0) -> 0
C29: Baptisms | L29: =SUM(G29:K29) -> 0 | M29: =ROUND((L29/$E$1),0) -> 0
C30: Home Visits | L30: =SUM(G30:K30) -> 0 | M30: =ROUND((L30/$E$1),0) -> 0
C31: Meals / Food Packs | L31: =SUM(G31:K31) -> 0 | M31: =ROUND((L31/$E$1),0) -> 0
C32: Preschool Attendance | L32: =SUM(G32:K32) -> 0 | M32: =ROUND((L32/$E$1),0) -> 0
A35: =+A19+1 -> 2 | C35: Ngwenya | G35: 2021 | H35: =+G35 -> 2021 | I35: =+H35 -> 2021 | J35: =+I35 -> 2021 | K35: =+J35 -> 2021 | L35: =+K35 -> 2021 | M35: =+L35 -> 2021
C36: November 2021 | G36: Nov | H36: =+G36 -> Nov | I36: =+H36 -> Nov | J36: =+I36 -> Nov | K36: =+J36 -> Nov | L36: =+K36 -> Nov | M36: =+L36 -> Nov
G37: 7 | H37: 14 | I37: 21 | J37: 28 | L37: Total | M37: Average
C39: Church Attendance: | G39: =SUM(G40:G43) -> 33 | H39: =SUM(H40:H43) -> 45 | I39: =SUM(I40:I43) -> 48 | J39: =SUM(J40:J43) -> 53 | K39: =SUM(K40:K43) -> 0 | L39: =SUM(L40:L43) -> 179 | M39: =ROUND((L39/$E$1),0) -> 45
D40: Men | G40: 10 | H40: 4 | I40: 4 | J40: 5 | L40: =SUM(G40:K40) -> 23 | M40: =ROUND((L40/$E$1),0) -> 6
D41: Women | G41: 2 | H41: 10 | I41: 11 | J41: 12 | L41: =SUM(G41:K41) -> 35 | M41: =ROUND((L41/$E$1),0) -> 9
D42: Youth | G42: 13 | H42: 13 | I42: 15 | J42: 16 | L42: =SUM(G42:K42) -> 57 | M42: =ROUND((L42/$E$1),0) -> 14
D43: Children | G43: 8 | H43: 18 | I43: 18 | J43: 20 | L43: =SUM(G43:K43) -> 64 | M43: =ROUND((L43/$E$1),0) -> 16
C44: Salvations | G44: 2 | J44: 0 | L44: =SUM(G44:K44) -> 2 | M44: =ROUND((L44/$E$1),0) -> 1
C45: Baptisms | J45: 0 | L45: =SUM(G45:K45) -> 0 | M45: =ROUND((L45/$E$1),0) -> 0
C46: Home Visits | G46: 5 | H46: 3 | I46: 2 | J46: 2 | L46: =SUM(G46:K46) -> 12 | M46: =ROUND((L46/$E$1),0) -> 3
C47: Meals / Food Packs | I47: 30 | J47: 0 | L47: =SUM(G47:K47) -> 30 | M47: =ROUND((L47/$E$1),0) -> 8
C48: Preschool Attendance | G48: 8 | J48: 0 | L48: =SUM(G48:K48) -> 8 | M48: =ROUND((L48/$E$1),0) -> 2
...

Sheet Dec21
D1: Number of Sundays | E1: 4 | P1: No services at some
C3: Total ICBC | G3: 2021 | H3: =+G3 -> 2021 | I3: =+H3 -> 2021 | J3: =+I3 -> 2021 | K3: =+J3 -> 2021 | L3: =+K3 -> 2021 | M3: =+L3 -> 2021
C4: December 2021 | G4: Dec | H4: =+G4 -> Dec | I4: =+H4 -> Dec | J4: =+I4 -> Dec | K4: =+J4 -> Dec | L4: =+K4 -> Dec | M4: =+L4 -> Dec
G5: 5 | H5: 12 | I5: 19 | J5: 26 | L5: Total | M5: Average
C7: Church Attendance: | G7: =SUM(G8:G11) -> 1353 | H7: =SUM(H8:H11) -> 1584 | I7: =SUM(I8:I11) -> 1594 | J7: =SUM(J8:J11) -> 1143 | K7: =SUM(K8:K11) -> 0 | L7: =SUM(L8:L11) -> 5674 | M7: =ROUND((L7/$E$1),0) -> 1419
D8: Men | G8: =+G24+G40+G56+G72+G88+G104+G120+G136+G152+G168+G184+G200+G216+G232+G248+G264+G280+G296+G312+G328+G344+G360+G376+G392+G408+G424+G440+G456+G472+G488 -> 99 | H8: =+H24+H40+H56+H72+H88+H104+H120+H136+H152+H168+H184+H200+H216+H232+H248+H264+H280+H296+H312+H328+H344+H360+H376+H392+H408+H424+H440+H456+H472+H488 -> 110 | I8: =+I24+I40+I56+I72+I88+I104+I120+I136+I152+I168+I184+I200+I216+I232+I248+I264+I280+I296+I312+I328+I344+I360+I376+I392+I408+I424+I440+I456+I472+I488 -> 116 | J8: =+J24+J40+J56+J72+J88+J104+J120+J136+J152+J168+J184+J200+J216+J232+J248+J264+J280+J296+J312+J328+J344+J360+J376+J392+J408+J424+J440+J456+J472+J488 -> 87 | K8: =+K24+K40+K56+K72+K88+K104+K120+K136+K152+K168+K184+K200+K216+K232+K248+K264+K280+K296+K312+K328+K344+K360+K376+K392+K408+K424+K440+K456+K472+K488 -> 0 | L8: =SUM(G8:K8) -> 412 | M8: =ROUND((L8/$E$1),0) -> 103
D9: Women | G9: =+G25+G41+G57+G73+G89+G105+G121+G137+G153+G169+G185+G201+G217+G233+G249+G265+G281+G297+G313+G329+G345+G361+G377+G393+G409+G425+G441+G457+G473+G489 -> 256 | H9: =+H25+H41+H57+H73+H89+H105+H121+H137+H153+H169+H185+H201+H217+H233+H249+H265+H281+H297+H313+H329+H345+H361+H377+H393+H409+H425+H441+H457+H473+H489 -> 277 | I9: =+I25+I41+I57+I73+I89+I105+I121+I137+I153+I169+I185+I201+I217+I233+I249+I265+I281+I297+I313+I329+I345+I361+I377+I393+I409+I425+I441+I457+I473+I489 -> 287 | J9: =+J25+J41+J57+J73+J89+J105+J121+J137+J153+J169+J185+J201+J217+J233+J249+J265+J281+J297+J313+J329+J345+J361+J377+J393+J409+J425+J441+J457+J473+J489 -> 230 | K9: =+K25+K41+K57+K73+K89+K105+K121+K137+K153+K169+K185+K201+K217+K233+K249+K265+K281+K297+K313+K329+K345+K361+K377+K393+K409+K425+K441+K457+K473+K489 -> 0 | L9: =SUM(G9:K9) -> 1050 | M9: =ROUND((L9/$E$1),0) -> 263
D10: Youth | G10: =+G26+G42+G58+G74+G90+G106+G122+G138+G154+G170+G186+G202+G218+G234+G250+G266+G282+G298+G314+G330+G346+G362+G378+G394+G410+G426+G442+G458+G474+G490 -> 370 | H10: =+H26+H42+H58+H74+H90+H106+H122+H138+H154+H170+H186+H202+H218+H234+H250+H266+H282+H298+H314+H330+H346+H362+H378+H394+H410+H426+H442+H458+H474+H490 -> 431 | I10: =+I26+I42+I58+I74+I90+I106+I122+I138+I154+I170+I186+I202+I218+I234+I250+I266+I282+I298+I314+I330+I346+I362+I378+I394+I410+I426+I442+I458+I474+I490 -> 436 | J10: =+J26+J42+J58+J74+J90+J106+J122+J138+J154+J170+J186+J202+J218+J234+J250+J266+J282+J298+J314+J330+J346+J362+J378+J394+J410+J426+J442+J458+J474+J490 -> 286 | K10: =+K26+K42+K58+K74+K90+K106+K122+K138+K154+K170+K186+K202+K218+K234+K250+K266+K282+K298+K314+K330+K346+K362+K378+K394+K410+K426+K442+K458+K474+K490 -> 0 | L10: =SUM(G10:K10) -> 1523 | M10: =ROUND((L10/$E$1),0) -> 381
D11: Children | G11: =+G27+G43+G59+G75+G91+G107+G123+G139+G155+G171+G187+G203+G219+G235+G251+G267+G283+G299+G315+G331+G347+G363+G379+G395+G411+G427+G443+G459+G475+G491 -> 628 | H11: =+H27+H43+H59+H75+H91+H107+H123+H139+H155+H171+H187+H203+H219+H235+H251+H267+H283+H299+H315+H331+H347+H363+H379+H395+H411+H427+H443+H459+H475+H491 -> 766 | I11: =+I27+I43+I59+I75+I91+I107+I123+I139+I155+I171+I187+I203+I219+I235+I251+I267+I283+I299+I315+I331+I347+I363+I379+I395+I411+I427+I443+I459+I475+I491 -> 755 | J11: =+J27+J43+J59+J75+J91+J107+J123+J139+J155+J171+J187+J203+J219+J235+J251+J267+J283+J299+J315+J331+J347+J363+J379+J395+J411+J427+J443+J459+J475+J491 -> 540 | K11: =+K27+K43+K59+K75+K91+K107+K123+K139+K155+K171+K187+K203+K219+K235+K251+K267+K283+K299+K315+K331+K347+K363+K379+K395+K411+K427+K443+K459+K475+K491 -> 0 | L11: =SUM(G11:K11) -> 2689 | M11: =ROUND((L11/$E$1),0) -> 672
C12: Salvations | G12: =+G28+G44+G60+G76+G92+G108+G124+G140+G156+G172+G188+G204+G220+G236+G252+G268+G284+G300+G316+G332+G348+G364+G380+G396+G412+G428+G444+G460+G476+G492 -> 31 | H12: =+H28+H44+H60+H76+H92+H108+H124+H140+H156+H172+H188+H204+H220+H236+H252+H268+H284+H300+H316+H332+H348+H364+H380+H396+H412+H428+H444+H460+H476+H492 -> 28 | I12: =+I28+I44+I60+I76+I92+I108+I124+I140+I156+I172+I188+I204+I220+I236+I252+I268+I284+I300+I316+I332+I348+I364+I380+I396+I412+I428+I444+I460+I476+I492 -> 52 | J12: =+J28+J44+J60+J76+J92+J108+J124+J140+J156+J172+J188+J204+J220+J236+J252+J268+J284+J300+J316+J332+J348+J364+J380+J396+J412+J428+J444+J460+J476+J492 -> 35 | K12: =+K28+K44+K60+K76+K92+K108+K124+K140+K156+K172+K188+K204+K220+K236+K252+K268+K284+K300+K316+K332+K348+K364+K380+K396+K412+K428+K444+K460+K476+K492 -> 0 | L12: =SUM(G12:K12) -> 146 | M12: =ROUND((L12/$E$1),0) -> 37
C13: Baptisms | G13: =+G29+G45+G61+G77+G93+G109+G125+G141+G157+G173+G189+G205+G221+G237+G253+G269+G285+G301+G317+G333+G349+G365+G381+G397+G413+G429+G445+G461+G477+G493 -> 0 | H13: =+H29+H45+H61+H77+H93+H109+H125+H141+H157+H173+H189+H205+H221+H237+H253+H269+H285+H301+H317+H333+H349+H365+H381+H397+H413+H429+H445+H461+H477+H493 -> 0 | I13: =+I29+I45+I61+I77+I93+I109+I125+I141+I157+I173+I189+I205+I221+I237+I253+I269+I285+I301+I317+I333+I349+I365+I381+I397+I413+I429+I445+I461+I477+I493 -> 0 | J13: =+J29+J45+J61+J77+J93+J109+J125+J141+J157+J173+J189+J205+J221+J237+J253+J269+J285+J301+J317+J333+J349+J365+J381+J397+J413+J429+J445+J461+J477+J493 -> 5 | K13: =+K29+K45+K61+K77+K93+K109+K125+K141+K157+K173+K189+K205+K221+K237+K253+K269+K285+K301+K317+K333+K349+K365+K381+K397+K413+K429+K445+K461+K477+K493 -> 0 | L13: =SUM(G13:K13) -> 5 | M13: =ROUND((L13/$E$1),0) -> 1
C14: Home Visits | G14: =+G30+G46+G62+G78+G94+G110+G126+G142+G158+G174+G190+G206+G222+G238+G254+G270+G286+G302+G318+G334+G350+G366+G382+G398+G414+G430+G446+G462+G478+G494 -> 76 | H14: =+H30+H46+H62+H78+H94+H110+H126+H142+H158+H174+H190+H206+H222+H238+H254+H270+H286+H302+H318+H334+H350+H366+H382+H398+H414+H430+H446+H462+H478+H494 -> 28 | I14: =+I30+I46+I62+I78+I94+I110+I126+I142+I158+I174+I190+I206+I222+I238+I254+I270+I286+I302+I318+I334+I350+I366+I382+I398+I414+I430+I446+I462+I478+I494 -> 30 | J14: =+J30+J46+J62+J78+J94+J110+J126+J142+J158+J174+J190+J206+J222+J238+J254+J270+J286+J302+J318+J334+J350+J366+J382+J398+J414+J430+J446+J462+J478+J494 -> 19 | K14: =+K30+K46+K62+K78+K94+K110+K126+K142+K158+K174+K190+K206+K222+K238+K254+K270+K286+K302+K318+K334+K350+K366+K382+K398+K414+K430+K446+K462+K478+K494 -> 0 | L14: =SUM(G14:K14) -> 153 | M14: =ROUND((L14/$E$1),0) -> 38
C15: Meals / Food Packs | G15: =+G31+G47+G63+G79+G95+G111+G127+G143+G159+G175+G191+G207+G223+G239+G255+G271+G287+G303+G319+G335+G351+G367+G383+G399+G415+G431+G447+G463+G479+G495 -> 116 | H15: =+H31+H47+H63+H79+H95+H111+H127+H143+H159+H175+H191+H207+H223+H239+H255+H271+H287+H303+H319+H335+H351+H367+H383+H399+H415+H431+H447+H463+H479+H495 -> 105 | I15: =+I31+I47+I63+I79+I95+I111+I127+I143+I159+I175+I191+I207+I223+I239+I255+I271+I287+I303+I319+I335+I351+I367+I383+I399+I415+I431+I447+I463+I479+I495 -> 799 | J15: =+J31+J47+J63+J79+J95+J111+J127+J143+J159+J175+J191+J207+J223+J239+J255+J271+J287+J303+J319+J335+J351+J367+J383+J399+J415+J431+J447+J463+J479+J495 -> 354 | K15: =+K31+K47+K63+K79+K95+K111+K127+K143+K159+K175+K191+K207+K223+K239+K255+K271+K287+K303+K319+K335+K351+K367+K383+K399+K415+K431+K447+K463+K479+K495 -> 0 | L15: =SUM(G15:K15) -> 1374 | M15: =ROUND((L15/$E$1),0) -> 344
C16: Preschool Attendance | G16: =+G32+G48+G64+G80+G96+G112+G128+G144+G160+G176+G192+G208+G224+G240+G256+G272+G288+G304+G320+G336+G352+G368+G384+G400+G416+G432+G448+G464+G480+G496 -> 44 | H16: =+H32+H48+H64+H80+H96+H112+H128+H144+H160+H176+H192+H208+H224+H240+H256+H272+H288+H304+H320+H336+H352+H368+H384+H400+H416+H432+H448+H464+H480+H496 -> 60 | I16: =+I32+I48+I64+I80+I96+I112+I128+I144+I160+I176+I192+I208+I224+I240+I256+I272+I288+I304+I320+I336+I352+I368+I384+I400+I416+I432+I448+I464+I480+I496 -> 43 | J16: =+J32+J48+J64+J80+J96+J112+J128+J144+J160+J176+J192+J208+J224+J240+J256+J272+J288+J304+J320+J336+J352+J368+J384+J400+J416+J432+J448+J464+J480+J496 -> 0 | K16: =+K32+K48+K64+K80+K96+K112+K128+K144+K160+K176+K192+K208+K224+K240+K256+K272+K288+K304+K320+K336+K352+K368+K384+K400+K416+K432+K448+K464+K480+K496 -> 0 | L16: =SUM(G16:K16) -> 147 | M16: =ROUND((L16/$E$1),0) -> 37
A19: 1 | C19: Hawane CLC Church | G19: =+$G$3 -> 2021 | H19: =+G19 -> 2021 | I19: =+H19 -> 2021 | J19: =+I19 -> 2021 | K19: =+J19 -> 2021 | L19: =+K19 -> 2021 | M19: =+L19 -> 2021
C20: =+$C4 -> December 2021 | G20: =+$G$4 -> Dec | H20: =+G20 -> Dec | I20: =+H20 -> Dec | J20: =+I20 -> Dec | K20: =+J20 -> Dec | L20: =+K20 -> Dec | M20: =+L20 -> Dec
G21: =+$G$5 -> 5 | H21: =+$H$5 -> 12 | I21: =+$I$5 -> 19 | J21: =+$J$5 -> 26 | K21: =+$K$5 -> 0 | L21: Total | M21: Average
C23: Church Attendance: | G23: =SUM(G24:G27) -> 105 | H23: =SUM(H24:H27) -> 145 | I23: =SUM(I24:I27) -> 124 | J23: =SUM(J24:J27) -> 111 | K23: =SUM(K24:K27) -> 0 | L23: =SUM(L24:L27) -> 485 | M23: =ROUND((L23/$E$1),0) -> 121
D24: Men | G24: 6 | H24: 8 | I24: 7 | J24: 7 | L24: =SUM(G24:K24) -> 28 | M24: =ROUND((L24/$E$1),0) -> 7
D25: Women | G25: 19 | H25: 22 | I25: 21 | J25: 16 | L25: =SUM(G25:K25) -> 78 | M25: =ROUND((L25/$E$1),0) -> 20
D26: Youth | G26: 36 | H26: 47 | I26: 39 | J26: 37 | L26: =SUM(G26:K26) -> 159 | M26: =ROUND((L26/$E$1),0) -> 40
D27: Children | G27: 44 | H27: 68 | I27: 57 | J27: 51 | L27: =SUM(G27:K27) -> 220 | M27: =ROUND((L27/$E$1),0) -> 55
C28: Salvations | L28: =SUM(G28:K28) -> 0 | M28: =ROUND((L28/$E$1),0) -> 0
C29: Baptisms | L29: =SUM(G29:K29) -> 0 | M29: =ROUND((L29/$E$1),0) -> 0
C30: Home Visits | L30: =SUM(G30:K30) -> 0 | M30: =ROUND((L30/$E$1),0) -> 0
C31: Meals / Food Packs | L31: =SUM(G31:K31) -> 0 | M31: =ROUND((L31/$E$1),0) -> 0
C32: Preschool Attendance | L32: =SUM(G32:K32) -> 0 | M32: =ROUND((L32/$E$1),0) -> 0
A35: =+A19+1 -> 2 | C35: Ngwenya | G35: 2021 | H35: =+G35 -> 2021 | I35: =+H35 -> 2021 | J35: =+I35 -> 2021 | K35: =+J35 -> 2021 | L35: =+K35 -> 2021 | M35: =+L35 -> 2021
C36: =+$C20 -> December 2021 | G36: Dec | H36: =+G36 -> Dec | I36: =+H36 -> Dec | J36: =+I36 -> Dec | K36: =+J36 -> Dec | L36: =+K36 -> Dec | M36: =+L36 -> Dec
G37: 5 | H37: 12 | I37: 19 | J37: 26 | L37: Total | M37: Average
C39: Church Attendance: | G39: =SUM(G40:G43) -> 48 | H39: =SUM(H40:H43) -> 54 | I39: =SUM(I40:I43) -> 56 | J39: =SUM(J40:J43) -> 49 | K39: =SUM(K40:K43) -> 0 | L39: =SUM(L40:L43) -> 207 | M39: =ROUND((L39/$E$1),0) -> 52
D40: Men | G40: 5 | H40: 4 | I40: 6 | J40: 4 | L40: =SUM(G40:K40) -> 19 | M40: =ROUND((L40/$E$1),0) -> 5
D41: Women | G41: 10 | H41: 10 | I41: 12 | J41: 12 | L41: =SUM(G41:K41) -> 44 | M41: =ROUND((L41/$E$1),0) -> 11
D42: Youth | G42: 15 | H42: 20 | I42: 20 | J42: 15 | L42: =SUM(G42:K42) -> 70 | M42: =ROUND((L42/$E$1),0) -> 18
D43: Children | G43: 18 | H43: 20 | I43: 18 | J43: 18 | L43: =SUM(G43:K43) -> 74 | M43: =ROUND((L43/$E$1),0) -> 19
C44: Salvations | H44: 2 | L44: =SUM(G44:K44) -> 2 | M44: =ROUND((L44/$E$1),0) -> 1
C45: Baptisms | J45: 5 | L45: =SUM(G45:K45) -> 5 | M45: =ROUND((L45/$E$1),0) -> 1
C46: Home Visits | G46: 3 | H46: 3 | J46: 5 | L46: =SUM(G46:K46) -> 11 | M46: =ROUND((L46/$E$1),0) -> 3
C47: Meals / Food Packs | H47: 1 | I47: 2 | J47: 2 | L47: =SUM(G47:K47) -> 5 | M47: =ROUND((L47/$E$1),0) -> 1
C48: Preschool Attendance | L48: =SUM(G48:K48) -> 0 | M48: =ROUND((L48/$E$1),0) -> 0
...

Sheet Jan22
D1: Number of Sundays | E1: 5
C3: Total ICBC | G3: 2022 | H3: =+G3 -> 2022 | I3: =+H3 -> 2022 | J3: =+I3 -> 2022 | K3: =+J3 -> 2022 | L3: =+K3 -> 2022 | M3: =+L3 -> 2022
C4: January 2022 | G4: Jan | H4: =+G4 -> Jan | I4: =+H4 -> Jan | J4: =+I4 -> Jan | K4: =+J4 -> Jan | L4: =+K4 -> Jan | M4: =+L4 -> Jan
G5: 2 | H5: 9 | I5: 16 | J5: 23 | K5: 30 | L5: Total | M5: Average
C7: Church Attendance: | G7: =SUM(G8:G11) -> 1363 | H7: =SUM(H8:H11) -> 1579 | I7: =SUM(I8:I11) -> 1560 | J7: =SUM(J8:J11) -> 1404 | K7: =SUM(K8:K11) -> 1353 | L7: =SUM(L8:L11) -> 7259 | M7: =ROUND((L7/$E$1),0) -> 1452
D8: Men | G8: =+G24+G40+G56+G72+G88+G104+G120+G136+G152+G168+G184+G200+G216+G232+G248+G264+G280+G296+G312+G328+G344+G360+G376+G392+G408+G424+G440+G456+G472+G488 -> 117 | H8: =+H24+H40+H56+H72+H88+H104+H120+H136+H152+H168+H184+H200+H216+H232+H248+H264+H280+H296+H312+H328+H344+H360+H376+H392+H408+H424+H440+H456+H472+H488 -> 128 | I8: =+I24+I40+I56+I72+I88+I104+I120+I136+I152+I168+I184+I200+I216+I232+I248+I264+I280+I296+I312+I328+I344+I360+I376+I392+I408+I424+I440+I456+I472+I488 -> 106 | J8: =+J24+J40+J56+J72+J88+J104+J120+J136+J152+J168+J184+J200+J216+J232+J248+J264+J280+J296+J312+J328+J344+J360+J376+J392+J408+J424+J440+J456+J472+J488 -> 104 | K8: =+K24+K40+K56+K72+K88+K104+K120+K136+K152+K168+K184+K200+K216+K232+K248+K264+K280+K296+K312+K328+K344+K360+K376+K392+K408+K424+K440+K456+K472+K488 -> 112 | L8: =SUM(G8:K8) -> 567 | M8: =ROUND((L8/$E$1),0) -> 113
D9: Women | G9: =+G25+G41+G57+G73+G89+G105+G121+G137+G153+G169+G185+G201+G217+G233+G249+G265+G281+G297+G313+G329+G345+G361+G377+G393+G409+G425+G441+G457+G473+G489 -> 277 | H9: =+H25+H41+H57+H73+H89+H105+H121+H137+H153+H169+H185+H201+H217+H233+H249+H265+H281+H297+H313+H329+H345+H361+H377+H393+H409+H425+H441+H457+H473+H489 -> 295 | I9: =+I25+I41+I57+I73+I89+I105+I121+I137+I153+I169+I185+I201+I217+I233+I249+I265+I281+I297+I313+I329+I345+I361+I377+I393+I409+I425+I441+I457+I473+I489 -> 284 | J9: =+J25+J41+J57+J73+J89+J105+J121+J137+J153+J169+J185+J201+J217+J233+J249+J265+J281+J297+J313+J329+J345+J361+J377+J393+J409+J425+J441+J457+J473+J489 -> 276 | K9: =+K25+K41+K57+K73+K89+K105+K121+K137+K153+K169+K185+K201+K217+K233+K249+K265+K281+K297+K313+K329+K345+K361+K377+K393+K409+K425+K441+K457+K473+K489 -> 276 | L9: =SUM(G9:K9) -> 1408 | M9: =ROUND((L9/$E$1),0) -> 282
D10: Youth | G10: =+G26+G42+G58+G74+G90+G106+G122+G138+G154+G170+G186+G202+G218+G234+G250+G266+G282+G298+G314+G330+G346+G362+G378+G394+G410+G426+G442+G458+G474+G490 -> 387 | H10: =+H26+H42+H58+H74+H90+H106+H122+H138+H154+H170+H186+H202+H218+H234+H250+H266+H282+H298+H314+H330+H346+H362+H378+H394+H410+H426+H442+H458+H474+H490 -> 439 | I10: =+I26+I42+I58+I74+I90+I106+I122+I138+I154+I170+I186+I202+I218+I234+I250+I266+I282+I298+I314+I330+I346+I362+I378+I394+I410+I426+I442+I458+I474+I490 -> 427 | J10: =+J26+J42+J58+J74+J90+J106+J122+J138+J154+J170+J186+J202+J218+J234+J250+J266+J282+J298+J314+J330+J346+J362+J378+J394+J410+J426+J442+J458+J474+J490 -> 384 | K10: =+K26+K42+K58+K74+K90+K106+K122+K138+K154+K170+K186+K202+K218+K234+K250+K266+K282+K298+K314+K330+K346+K362+K378+K394+K410+K426+K442+K458+K474+K490 -> 345 | L10: =SUM(G10:K10) -> 1982 | M10: =ROUND((L10/$E$1),0) -> 396
D11: Children | G11: =+G27+G43+G59+G75+G91+G107+G123+G139+G155+G171+G187+G203+G219+G235+G251+G267+G283+G299+G315+G331+G347+G363+G379+G395+G411+G427+G443+G459+G475+G491 -> 582 | H11: =+H27+H43+H59+H75+H91+H107+H123+H139+H155+H171+H187+H203+H219+H235+H251+H267+H283+H299+H315+H331+H347+H363+H379+H395+H411+H427+H443+H459+H475+H491 -> 717 | I11: =+I27+I43+I59+I75+I91+I107+I123+I139+I155+I171+I187+I203+I219+I235+I251+I267+I283+I299+I315+I331+I347+I363+I379+I395+I411+I427+I443+I459+I475+I491 -> 743 | J11: =+J27+J43+J59+J75+J91+J107+J123+J139+J155+J171+J187+J203+J219+J235+J251+J267+J283+J299+J315+J331+J347+J363+J379+J395+J411+J427+J443+J459+J475+J491 -> 640 | K11: =+K27+K43+K59+K75+K91+K107+K123+K139+K155+K171+K187+K203+K219+K235+K251+K267+K283+K299+K315+K331+K347+K363+K379+K395+K411+K427+K443+K459+K475+K491 -> 620 | L11: =SUM(G11:K11) -> 3302 | M11: =ROUND((L11/$E$1),0) -> 660
C12: Salvations | G12: =+G28+G44+G60+G76+G92+G108+G124+G140+G156+G172+G188+G204+G220+G236+G252+G268+G284+G300+G316+G332+G348+G364+G380+G396+G412+G428+G444+G460+G476+G492 -> 15 | H12: =+H28+H44+H60+H76+H92+H108+H124+H140+H156+H172+H188+H204+H220+H236+H252+H268+H284+H300+H316+H332+H348+H364+H380+H396+H412+H428+H444+H460+H476+H492 -> 27 | I12: =+I28+I44+I60+I76+I92+I108+I124+I140+I156+I172+I188+I204+I220+I236+I252+I268+I284+I300+I316+I332+I348+I364+I380+I396+I412+I428+I444+I460+I476+I492 -> 34 | J12: =+J28+J44+J60+J76+J92+J108+J124+J140+J156+J172+J188+J204+J220+J236+J252+J268+J284+J300+J316+J332+J348+J364+J380+J396+J412+J428+J444+J460+J476+J492 -> 33 | K12: =+K28+K44+K60+K76+K92+K108+K124+K140+K156+K172+K188+K204+K220+K236+K252+K268+K284+K300+K316+K332+K348+K364+K380+K396+K412+K428+K444+K460+K476+K492 -> 20 | L12: =SUM(G12:K12) -> 129 | M12: =ROUND((L12/$E$1),0) -> 26
C13: Baptisms | G13: =+G29+G45+G61+G77+G93+G109+G125+G141+G157+G173+G189+G205+G221+G237+G253+G269+G285+G301+G317+G333+G349+G365+G381+G397+G413+G429+G445+G461+G477+G493 -> 0 | H13: =+H29+H45+H61+H77+H93+H109+H125+H141+H157+H173+H189+H205+H221+H237+H253+H269+H285+H301+H317+H333+H349+H365+H381+H397+H413+H429+H445+H461+H477+H493 -> 0 | I13: =+I29+I45+I61+I77+I93+I109+I125+I141+I157+I173+I189+I205+I221+I237+I253+I269+I285+I301+I317+I333+I349+I365+I381+I397+I413+I429+I445+I461+I477+I493 -> 0 | J13: =+J29+J45+J61+J77+J93+J109+J125+J141+J157+J173+J189+J205+J221+J237+J253+J269+J285+J301+J317+J333+J349+J365+J381+J397+J413+J429+J445+J461+J477+J493 -> 0 | K13: =+K29+K45+K61+K77+K93+K109+K125+K141+K157+K173+K189+K205+K221+K237+K253+K269+K285+K301+K317+K333+K349+K365+K381+K397+K413+K429+K445+K461+K477+K493 -> 0 | L13: =SUM(G13:K13) -> 0 | M13: =ROUND((L13/$E$1),0) -> 0
C14: Home Visits | G14: =+G30+G46+G62+G78+G94+G110+G126+G142+G158+G174+G190+G206+G222+G238+G254+G270+G286+G302+G318+G334+G350+G366+G382+G398+G414+G430+G446+G462+G478+G494 -> 36 | H14: =+H30+H46+H62+H78+H94+H110+H126+H142+H158+H174+H190+H206+H222+H238+H254+H270+H286+H302+H318+H334+H350+H366+H382+H398+H414+H430+H446+H462+H478+H494 -> 26 | I14: =+I30+I46+I62+I78+I94+I110+I126+I142+I158+I174+I190+I206+I222+I238+I254+I270+I286+I302+I318+I334+I350+I366+I382+I398+I414+I430+I446+I462+I478+I494 -> 74 | J14: =+J30+J46+J62+J78+J94+J110+J126+J142+J158+J174+J190+J206+J222+J238+J254+J270+J286+J302+J318+J334+J350+J366+J382+J398+J414+J430+J446+J462+J478+J494 -> 112 | K14: =+K30+K46+K62+K78+K94+K110+K126+K142+K158+K174+K190+K206+K222+K238+K254+K270+K286+K302+K318+K334+K350+K366+K382+K398+K414+K430+K446+K462+K478+K494 -> 30 | L14: =SUM(G14:K14) -> 278 | M14: =ROUND((L14/$E$1),0) -> 56
C15: Meals / Food Packs | G15: =+G31+G47+G63+G79+G95+G111+G127+G143+G159+G175+G191+G207+G223+G239+G255+G271+G287+G303+G319+G335+G351+G367+G383+G399+G415+G431+G447+G463+G479+G495 -> 284 | H15: =+H31+H47+H63+H79+H95+H111+H127+H143+H159+H175+H191+H207+H223+H239+H255+H271+H287+H303+H319+H335+H351+H367+H383+H399+H415+H431+H447+H463+H479+H495 -> 387 | I15: =+I31+I47+I63+I79+I95+I111+I127+I143+I159+I175+I191+I207+I223+I239+I255+I271+I287+I303+I319+I335+I351+I367+I383+I399+I415+I431+I447+I463+I479+I495 -> 415 | J15: =+J31+J47+J63+J79+J95+J111+J127+J143+J159+J175+J191+J207+J223+J239+J255+J271+J287+J303+J319+J335+J351+J367+J383+J399+J415+J431+J447+J463+J479+J495 -> 555 | K15: =+K31+K47+K63+K79+K95+K111+K127+K143+K159+K175+K191+K207+K223+K239+K255+K271+K287+K303+K319+K335+K351+K367+K383+K399+K415+K431+K447+K463+K479+K495 -> 427 | L15: =SUM(G15:K15) -> 2068 | M15: =ROUND((L15/$E$1),0) -> 414
C16: Preschool Attendance | G16: =+G32+G48+G64+G80+G96+G112+G128+G144+G160+G176+G192+G208+G224+G240+G256+G272+G288+G304+G320+G336+G352+G368+G384+G400+G416+G432+G448+G464+G480+G496 -> 43 | H16: =+H32+H48+H64+H80+H96+H112+H128+H144+H160+H176+H192+H208+H224+H240+H256+H272+H288+H304+H320+H336+H352+H368+H384+H400+H416+H432+H448+H464+H480+H496 -> 41 | I16: =+I32+I48+I64+I80+I96+I112+I128+I144+I160+I176+I192+I208+I224+I240+I256+I272+I288+I304+I320+I336+I352+I368+I384+I400+I416+I432+I448+I464+I480+I496 -> 0 | J16: =+J32+J48+J64+J80+J96+J112+J128+J144+J160+J176+J192+J208+J224+J240+J256+J272+J288+J304+J320+J336+J352+J368+J384+J400+J416+J432+J448+J464+J480+J496 -> 0 | K16: =+K32+K48+K64+K80+K96+K112+K128+K144+K160+K176+K192+K208+K224+K240+K256+K272+K288+K304+K320+K336+K352+K368+K384+K400+K416+K432+K448+K464+K480+K496 -> 133 | L16: =SUM(G16:K16) -> 217 | M16: =ROUND((L16/$E$1),0) -> 43
A19: 1 | C19: Hawane CLC Church | G19: =+$G$3 -> 2022 | H19: =+G19 -> 2022 | I19: =+H19 -> 2022 | J19: =+I19 -> 2022 | K19: =+J19 -> 2022 | L19: =+K19 -> 2022 | M19: =+L19 -> 2022
C20: =+$C4 -> January 2022 | G20: =+$G$4 -> Jan | H20: =+G20 -> Jan | I20: =+H20 -> Jan | J20: =+I20 -> Jan | K20: =+J20 -> Jan | L20: =+K20 -> Jan | M20: =+L20 -> Jan
G21: =+$G$5 -> 2 | H21: =+$H$5 -> 9 | I21: =+$I$5 -> 16 | J21: =+$J$5 -> 23 | K21: =+$K$5 -> 30 | L21: Total | M21: Average
C23: Church Attendance: | G23: =SUM(G24:G27) -> 141 | H23: =SUM(H24:H27) -> 175 | I23: =SUM(I24:I27) -> 167 | J23: =SUM(J24:J27) -> 164 | K23: =SUM(K24:K27) -> 121 | L23: =SUM(L24:L27) -> 768 | M23: =ROUND((L23/$E$1),0) -> 154
D24: Men | G24: 12 | H24: 10 | I24: 13 | J24: 13 | K24: 13 | L24: =SUM(G24:K24) -> 61 | M24: =ROUND((L24/$E$1),0) -> 12
D25: Women | G25: 21 | H25: 31 | I25: 23 | J25: 33 | K25: 29 | L25: =SUM(G25:K25) -> 137 | M25: =ROUND((L25/$E$1),0) -> 27
D26: Youth | G26: 49 | H26: 57 | I26: 49 | J26: 50 | K26: 50 | L26: =SUM(G26:K26) -> 255 | M26: =ROUND((L26/$E$1),0) -> 51
D27: Children | G27: 59 | H27: 77 | I27: 82 | J27: 68 | K27: 29 | L27: =SUM(G27:K27) -> 315 | M27: =ROUND((L27/$E$1),0) -> 63
C28: Salvations | L28: =SUM(G28:K28) -> 0 | M28: =ROUND((L28/$E$1),0) -> 0
C29: Baptisms | L29: =SUM(G29:K29) -> 0 | M29: =ROUND((L29/$E$1),0) -> 0
C30: Home Visits | L30: =SUM(G30:K30) -> 0 | M30: =ROUND((L30/$E$1),0) -> 0
C31: Meals / Food Packs | L31: =SUM(G31:K31) -> 0 | M31: =ROUND((L31/$E$1),0) -> 0
C32: Preschool Attendance | L32: =SUM(G32:K32) -> 0 | M32: =ROUND((L32/$E$1),0) -> 0
A35: =+A19+1 -> 2 | C35: Ngwenya | G35: 2021 | H35: =+G35 -> 2021 | I35: =+H35 -> 2021 | J35: =+I35 -> 2021 | K35: =+J35 -> 2021 | L35: =+K35 -> 2021 | M35: =+L35 -> 2021
C36: =+$C20 -> January 2022 | G36: Nov | H36: =+G36 -> Nov | I36: =+H36 -> Nov | J36: =+I36 -> Nov | K36: =+J36 -> Nov | L36: =+K36 -> Nov | M36: =+L36 -> Nov
G37: 7 | H37: 14 | I37: 21 | J37: 28 | L37: Total | M37: Average
C39: Church Attendance: | G39: =SUM(G40:G43) -> 40 | H39: =SUM(H40:H43) -> 47 | I39: =SUM(I40:I43) -> 44 | J39: =SUM(J40:J43) -> 43 | K39: =SUM(K40:K43) -> 52 | L39: =SUM(L40:L43) -> 226 | M39: =ROUND((L39/$E$1),0) -> 45
D40: Men | G40: 4 | H40: 5 | I40: 1 | J40: 4 | K40: 5 | L40: =SUM(G40:K40) -> 19 | M40: =ROUND((L40/$E$1),0) -> 4
D41: Women | G41: 6 | H41: 10 | I41: 6 | J41: 8 | K41: 12 | L41: =SUM(G41:K41) -> 42 | M41: =ROUND((L41/$E$1),0) -> 8
D42: Youth | G42: 11 | H42: 13 | I42: 12 | J42: 11 | K42: 15 | L42: =SUM(G42:K42) -> 62 | M42: =ROUND((L42/$E$1),0) -> 12
D43: Children | G43: 19 | H43: 19 | I43: 25 | J43: 20 | K43: 20 | L43: =SUM(G43:K43) -> 103 | M43: =ROUND((L43/$E$1),0) -> 21
C44: Salvations | K44: 3 | L44: =SUM(G44:K44) -> 3 | M44: =ROUND((L44/$E$1),0) -> 1
C45: Baptisms | L45: =SUM(G45:K45) -> 0 | M45: =ROUND((L45/$E$1),0) -> 0
C46: Home Visits | G46: 3 | H46: 2 | I46: 2 | J46: 3 | K46: 3 | L46: =SUM(G46:K46) -> 13 | M46: =ROUND((L46/$E$1),0) -> 3
C47: Meals / Food Packs | G47: 1 | H47: 3 | I47: 3 | J47: 2 | K47: 2 | L47: =SUM(G47:K47) -> 11 | M47: =ROUND((L47/$E$1),0) -> 2
C48: Preschool Attendance | L48: =SUM(G48:K48) -> 0 | M48: =ROUND((L48/$E$1),0) -> 0
...

Sheet Feb22
D1: Number of Sundays | E1: 4
C3: Total ICBC | G3: 2022 | H3: =+G3 -> 2022 | I3: =+H3 -> 2022 | J3: =+I3 -> 2022 | K3: =+J3 -> 2022 | L3: =+K3 -> 2022 | M3: =+L3 -> 2022
C4: February 2022 | G4: Feb | H4: =+G4 -> Feb | I4: =+H4 -> Feb | J4: =+I4 -> Feb | K4: =+J4 -> Feb | L4: =+K4 -> Feb | M4: =+L4 -> Feb
G5: 6 | H5: 13 | I5: 20 | J5: 27 | L5: Total | M5: Average
C7: Church Attendance: | G7: =SUM(G8:G11) -> 1358 | H7: =SUM(H8:H11) -> 1639 | I7: =SUM(I8:I11) -> 1657 | J7: =SUM(J8:J11) -> 1619 | K7: =SUM(K8:K11) -> 0 | L7: =SUM(L8:L11) -> 6273 | M7: =ROUND((L7/$E$1),0) -> 1568
D8: Men | G8: =+G24+G40+G56+G72+G88+G104+G120+G136+G152+G168+G184+G200+G216+G232+G248+G264+G280+G296+G312+G328+G344+G360+G376+G392+G408+G424+G440+G456+G472+G488 -> 106 | H8: =+H24+H40+H56+H72+H88+H104+H120+H136+H152+H168+H184+H200+H216+H232+H248+H264+H280+H296+H312+H328+H344+H360+H376+H392+H408+H424+H440+H456+H472+H488 -> 111 | I8: =+I24+I40+I56+I72+I88+I104+I120+I136+I152+I168+I184+I200+I216+I232+I248+I264+I280+I296+I312+I328+I344+I360+I376+I392+I408+I424+I440+I456+I472+I488 -> 131 | J8: =+J24+J40+J56+J72+J88+J104+J120+J136+J152+J168+J184+J200+J216+J232+J248+J264+J280+J296+J312+J328+J344+J360+J376+J392+J408+J424+J440+J456+J472+J488 -> 116 | K8: =+K24+K40+K56+K72+K88+K104+K120+K136+K152+K168+K184+K200+K216+K232+K248+K264+K280+K296+K312+K328+K344+K360+K376+K392+K408+K424+K440+K456+K472+K488 -> 0 | L8: =SUM(G8:K8) -> 464 | M8: =ROUND((L8/$E$1),0) -> 116
D9: Women | G9: =+G25+G41+G57+G73+G89+G105+G121+G137+G153+G169+G185+G201+G217+G233+G249+G265+G281+G297+G313+G329+G345+G361+G377+G393+G409+G425+G441+G457+G473+G489 -> 283 | H9: =+H25+H41+H57+H73+H89+H105+H121+H137+H153+H169+H185+H201+H217+H233+H249+H265+H281+H297+H313+H329+H345+H361+H377+H393+H409+H425+H441+H457+H473+H489 -> 326 | I9: =+I25+I41+I57+I73+I89+I105+I121+I137+I153+I169+I185+I201+I217+I233+I249+I265+I281+I297+I313+I329+I345+I361+I377+I393+I409+I425+I441+I457+I473+I489 -> 292 | J9: =+J25+J41+J57+J73+J89+J105+J121+J137+J153+J169+J185+J201+J217+J233+J249+J265+J281+J297+J313+J329+J345+J361+J377+J393+J409+J425+J441+J457+J473+J489 -> 284 | K9: =+K25+K41+K57+K73+K89+K105+K121+K137+K153+K169+K185+K201+K217+K233+K249+K265+K281+K297+K313+K329+K345+K361+K377+K393+K409+K425+K441+K457+K473+K489 -> 0 | L9: =SUM(G9:K9) -> 1185 | M9: =ROUND((L9/$E$1),0) -> 296
D10: Youth | G10: =+G26+G42+G58+G74+G90+G106+G122+G138+G154+G170+G186+G202+G218+G234+G250+G266+G282+G298+G314+G330+G346+G362+G378+G394+G410+G426+G442+G458+G474+G490 -> 343 | H10: =+H26+H42+H58+H74+H90+H106+H122+H138+H154+H170+H186+H202+H218+H234+H250+H266+H282+H298+H314+H330+H346+H362+H378+H394+H410+H426+H442+H458+H474+H490 -> 462 | I10: =+I26+I42+I58+I74+I90+I106+I122+I138+I154+I170+I186+I202+I218+I234+I250+I266+I282+I298+I314+I330+I346+I362+I378+I394+I410+I426+I442+I458+I474+I490 -> 503 | J10: =+J26+J42+J58+J74+J90+J106+J122+J138+J154+J170+J186+J202+J218+J234+J250+J266+J282+J298+J314+J330+J346+J362+J378+J394+J410+J426+J442+J458+J474+J490 -> 430 | K10: =+K26+K42+K58+K74+K90+K106+K122+K138+K154+K170+K186+K202+K218+K234+K250+K266+K282+K298+K314+K330+K346+K362+K378+K394+K410+K426+K442+K458+K474+K490 -> 0 | L10: =SUM(G10:K10) -> 1738 | M10: =ROUND((L10/$E$1),0) -> 435
D11: Children | G11: =+G27+G43+G59+G75+G91+G107+G123+G139+G155+G171+G187+G203+G219+G235+G251+G267+G283+G299+G315+G331+G347+G363+G379+G395+G411+G427+G443+G459+G475+G491 -> 626 | H11: =+H27+H43+H59+H75+H91+H107+H123+H139+H155+H171+H187+H203+H219+H235+H251+H267+H283+H299+H315+H331+H347+H363+H379+H395+H411+H427+H443+H459+H475+H491 -> 740 | I11: =+I27+I43+I59+I75+I91+I107+I123+I139+I155+I171+I187+I203+I219+I235+I251+I267+I283+I299+I315+I331+I347+I363+I379+I395+I411+I427+I443+I459+I475+I491 -> 731 | J11: =+J27+J43+J59+J75+J91+J107+J123+J139+J155+J171+J187+J203+J219+J235+J251+J267+J283+J299+J315+J331+J347+J363+J379+J395+J411+J427+J443+J459+J475+J491 -> 789 | K11: =+K27+K43+K59+K75+K91+K107+K123+K139+K155+K171+K187+K203+K219+K235+K251+K267+K283+K299+K315+K331+K347+K363+K379+K395+K411+K427+K443+K459+K475+K491 -> 0 | L11: =SUM(G11:K11) -> 2886 | M11: =ROUND((L11/$E$1),0) -> 722
C12: Salvations | G12: =+G28+G44+G60+G76+G92+G108+G124+G140+G156+G172+G188+G204+G220+G236+G252+G268+G284+G300+G316+G332+G348+G364+G380+G396+G412+G428+G444+G460+G476+G492 -> 18 | H12: =+H28+H44+H60+H76+H92+H108+H124+H140+H156+H172+H188+H204+H220+H236+H252+H268+H284+H300+H316+H332+H348+H364+H380+H396+H412+H428+H444+H460+H476+H492 -> 55 | I12: =+I28+I44+I60+I76+I92+I108+I124+I140+I156+I172+I188+I204+I220+I236+I252+I268+I284+I300+I316+I332+I348+I364+I380+I396+I412+I428+I444+I460+I476+I492 -> 26 | J12: =+J28+J44+J60+J76+J92+J108+J124+J140+J156+J172+J188+J204+J220+J236+J252+J268+J284+J300+J316+J332+J348+J364+J380+J396+J412+J428+J444+J460+J476+J492 -> 16 | K12: =+K28+K44+K60+K76+K92+K108+K124+K140+K156+K172+K188+K204+K220+K236+K252+K268+K284+K300+K316+K332+K348+K364+K380+K396+K412+K428+K444+K460+K476+K492 -> 0 | L12: =SUM(G12:K12) -> 115 | M12: =ROUND((L12/$E$1),0) -> 29
C13: Baptisms | G13: =+G29+G45+G61+G77+G93+G109+G125+G141+G157+G173+G189+G205+G221+G237+G253+G269+G285+G301+G317+G333+G349+G365+G381+G397+G413+G429+G445+G461+G477+G493 -> 0 | H13: =+H29+H45+H61+H77+H93+H109+H125+H141+H157+H173+H189+H205+H221+H237+H253+H269+H285+H301+H317+H333+H349+H365+H381+H397+H413+H429+H445+H461+H477+H493 -> 0 | I13: =+I29+I45+I61+I77+I93+I109+I125+I141+I157+I173+I189+I205+I221+I237+I253+I269+I285+I301+I317+I333+I349+I365+I381+I397+I413+I429+I445+I461+I477+I493 -> 0 | J13: =+J29+J45+J61+J77+J93+J109+J125+J141+J157+J173+J189+J205+J221+J237+J253+J269+J285+J301+J317+J333+J349+J365+J381+J397+J413+J429+J445+J461+J477+J493 -> 2 | K13: =+K29+K45+K61+K77+K93+K109+K125+K141+K157+K173+K189+K205+K221+K237+K253+K269+K285+K301+K317+K333+K349+K365+K381+K397+K413+K429+K445+K461+K477+K493 -> 0 | L13: =SUM(G13:K13) -> 2 | M13: =ROUND((L13/$E$1),0) -> 1
C14: Home Visits | G14: =+G30+G46+G62+G78+G94+G110+G126+G142+G158+G174+G190+G206+G222+G238+G254+G270+G286+G302+G318+G334+G350+G366+G382+G398+G414+G430+G446+G462+G478+G494 -> 46 | H14: =+H30+H46+H62+H78+H94+H110+H126+H142+H158+H174+H190+H206+H222+H238+H254+H270+H286+H302+H318+H334+H350+H366+H382+H398+H414+H430+H446+H462+H478+H494 -> 40 | I14: =+I30+I46+I62+I78+I94+I110+I126+I142+I158+I174+I190+I206+I222+I238+I254+I270+I286+I302+I318+I334+I350+I366+I382+I398+I414+I430+I446+I462+I478+I494 -> 26 | J14: =+J30+J46+J62+J78+J94+J110+J126+J142+J158+J174+J190+J206+J222+J238+J254+J270+J286+J302+J318+J334+J350+J366+J382+J398+J414+J430+J446+J462+J478+J494 -> 34 | K14: =+K30+K46+K62+K78+K94+K110+K126+K142+K158+K174+K190+K206+K222+K238+K254+K270+K286+K302+K318+K334+K350+K366+K382+K398+K414+K430+K446+K462+K478+K494 -> 0 | L14: =SUM(G14:K14) -> 146 | M14: =ROUND((L14/$E$1),0) -> 37
C15: Meals / Food Packs | G15: =+G31+G47+G63+G79+G95+G111+G127+G143+G159+G175+G191+G207+G223+G239+G255+G271+G287+G303+G319+G335+G351+G367+G383+G399+G415+G431+G447+G463+G479+G495 -> 670 | H15: =+H31+H47+H63+H79+H95+H111+H127+H143+H159+H175+H191+H207+H223+H239+H255+H271+H287+H303+H319+H335+H351+H367+H383+H399+H415+H431+H447+H463+H479+H495 -> 392 | I15: =+I31+I47+I63+I79+I95+I111+I127+I143+I159+I175+I191+I207+I223+I239+I255+I271+I287+I303+I319+I335+I351+I367+I383+I399+I415+I431+I447+I463+I479+I495 -> 316 | J15: =+J31+J47+J63+J79+J95+J111+J127+J143+J159+J175+J191+J207+J223+J239+J255+J271+J287+J303+J319+J335+J351+J367+J383+J399+J415+J431+J447+J463+J479+J495 -> 440 | K15: =+K31+K47+K63+K79+K95+K111+K127+K143+K159+K175+K191+K207+K223+K239+K255+K271+K287+K303+K319+K335+K351+K367+K383+K399+K415+K431+K447+K463+K479+K495 -> 0 | L15: =SUM(G15:K15) -> 1818 | M15: =ROUND((L15/$E$1),0) -> 455
C16: Preschool Attendance | G16: =+G32+G48+G64+G80+G96+G112+G128+G144+G160+G176+G192+G208+G224+G240+G256+G272+G288+G304+G320+G336+G352+G368+G384+G400+G416+G432+G448+G464+G480+G496 -> 0 | H16: =+H32+H48+H64+H80+H96+H112+H128+H144+H160+H176+H192+H208+H224+H240+H256+H272+H288+H304+H320+H336+H352+H368+H384+H400+H416+H432+H448+H464+H480+H496 -> 313 | I16: =+I32+I48+I64+I80+I96+I112+I128+I144+I160+I176+I192+I208+I224+I240+I256+I272+I288+I304+I320+I336+I352+I368+I384+I400+I416+I432+I448+I464+I480+I496 -> 282 | J16: =+J32+J48+J64+J80+J96+J112+J128+J144+J160+J176+J192+J208+J224+J240+J256+J272+J288+J304+J320+J336+J352+J368+J384+J400+J416+J432+J448+J464+J480+J496 -> 199 | K16: =+K32+K48+K64+K80+K96+K112+K128+K144+K160+K176+K192+K208+K224+K240+K256+K272+K288+K304+K320+K336+K352+K368+K384+K400+K416+K432+K448+K464+K480+K496 -> 0 | L16: =SUM(G16:K16) -> 794 | M16: =ROUND((L16/$E$1),0) -> 199
A19: 1 | C19: Hawane CLC Church | G19: =+$G$3 -> 2022 | H19: =+G19 -> 2022 | I19: =+H19 -> 2022 | J19: =+I19 -> 2022 | K19: =+J19 -> 2022 | L19: =+K19 -> 2022 | M19: =+L19 -> 2022
C20: =+$C4 -> February 2022 | G20: =+$G$4 -> Feb | H20: =+G20 -> Feb | I20: =+H20 -> Feb | J20: =+I20 -> Feb | K20: =+J20 -> Feb | L20: =+K20 -> Feb | M20: =+L20 -> Feb
G21: =+$G$5 -> 6 | H21: =+$H$5 -> 13 | I21: =+$I$5 -> 20 | J21: =+$J$5 -> 27 | K21: =+$K$5 -> 0 | L21: Total | M21: Average
C23: Church Attendance: | G23: =SUM(G24:G27) -> 132 | H23: =SUM(H24:H27) -> 142 | I23: =SUM(I24:I27) -> 136 | J23: =SUM(J24:J27) -> 140 | K23: =SUM(K24:K27) -> 0 | L23: =SUM(L24:L27) -> 550 | M23: =ROUND((L23/$E$1),0) -> 138
D24: Men | G24: 12 | H24: 11 | I24: 12 | J24: 11 | L24: =SUM(G24:K24) -> 46 | M24: =ROUND((L24/$E$1),0) -> 12
D25: Women | G25: 26 | H25: 32 | I25: 32 | J25: 22 | L25: =SUM(G25:K25) -> 112 | M25: =ROUND((L25/$E$1),0) -> 28
D26: Youth | G26: 50 | H26: 60 | I26: 52 | J26: 33 | L26: =SUM(G26:K26) -> 195 | M26: =ROUND((L26/$E$1),0) -> 49
D27: Children | G27: 44 | H27: 39 | I27: 40 | J27: 74 | L27: =SUM(G27:K27) -> 197 | M27: =ROUND((L27/$E$1),0) -> 49
C28: Salvations | L28: =SUM(G28:K28) -> 0 | M28: =ROUND((L28/$E$1),0) -> 0
C29: Baptisms | L29: =SUM(G29:K29) -> 0 | M29: =ROUND((L29/$E$1),0) -> 0
C30: Home Visits | L30: =SUM(G30:K30) -> 0 | M30: =ROUND((L30/$E$1),0) -> 0
C31: Meals / Food Packs | L31: =SUM(G31:K31) -> 0 | M31: =ROUND((L31/$E$1),0) -> 0
C32: Preschool Attendance | L32: =SUM(G32:K32) -> 0 | M32: =ROUND((L32/$E$1),0) -> 0
A35: =+A19+1 -> 2 | C35: Ngwenya | G35: =+$G$3 -> 2022 | H35: =+G35 -> 2022 | I35: =+H35 -> 2022 | J35: =+I35 -> 2022 | K35: =+J35 -> 2022 | L35: =+K35 -> 2022 | M35: =+L35 -> 2022
C36: =+$C20 -> February 2022 | G36: =+$G$4 -> Feb | H36: =+G36 -> Feb | I36: =+H36 -> Feb | J36: =+I36 -> Feb | K36: =+J36 -> Feb | L36: =+K36 -> Feb | M36: =+L36 -> Feb
G37: =+$G$5 -> 6 | H37: =+$H$5 -> 13 | I37: =+$I$5 -> 20 | J37: =+$J$5 -> 27 | K37: =+$K$5 -> 0 | L37: Total | M37: Average
C39: Church Attendance: | G39: =SUM(G40:G43) -> 55 | H39: =SUM(H40:H43) -> 56 | I39: =SUM(I40:I43) -> 52 | J39: =SUM(J40:J43) -> 49 | K39: =SUM(K40:K43) -> 0 | L39: =SUM(L40:L43) -> 212 | M39: =ROUND((L39/$E$1),0) -> 53
D40: Men | G40: 6 | H40: 5 | I40: 5 | J40: 4 | L40: =SUM(G40:K40) -> 20 | M40: =ROUND((L40/$E$1),0) -> 5
D41: Women | G41: 14 | H41: 11 | I41: 13 | J41: 8 | L41: =SUM(G41:K41) -> 46 | M41: =ROUND((L41/$E$1),0) -> 12
D42: Youth | G42: 15 | H42: 13 | I42: 13 | J42: 13 | L42: =SUM(G42:K42) -> 54 | M42: =ROUND((L42/$E$1),0) -> 14
D43: Children | G43: 20 | H43: 27 | I43: 21 | J43: 24 | L43: =SUM(G43:K43) -> 92 | M43: =ROUND((L43/$E$1),0) -> 23
C44: Salvations | G44: 2 | H44: 3 | I44: 2 | L44: =SUM(G44:K44) -> 7 | M44: =ROUND((L44/$E$1),0) -> 2
C45: Baptisms | L45: =SUM(G45:K45) -> 0 | M45: =ROUND((L45/$E$1),0) -> 0
C46: Home Visits | G46: 2 | H46: 3 | I46: 5 | J46: 4 | L46: =SUM(G46:K46) -> 14 | M46: =ROUND((L46/$E$1),0) -> 4
C47: Meals / Food Packs | G47: 2 | H47: 4 | I47: 6 | J47: 3 | L47: =SUM(G47:K47) -> 15 | M47: =ROUND((L47/$E$1),0) -> 4
C48: Preschool Attendance | L48: =SUM(G48:K48) -> 0 | M48: =ROUND((L48/$E$1),0) -> 0
...

Sheet Mar22
D1: Number of Sundays | E1: 4
C3: Total ICBC | G3: 2022 | H3: =+G3 -> 2022 | I3: =+H3 -> 2022 | J3: =+I3 -> 2022 | K3: =+J3 -> 2022 | L3: =+K3 -> 2022 | M3: =+L3 -> 2022
C4: March 2022 | G4: Mar | H4: =+G4 -> Mar | I4: =+H4 -> Mar | J4: =+I4 -> Mar | K4: =+J4 -> Mar | L4: =+K4 -> Mar | M4: =+L4 -> Mar
G5: 6 | H5: 13 | I5: 20 | J5: 27 | L5: Total | M5: Average
C7: Church Attendance: | G7: =SUM(G8:G11) -> 1672 | H7: =SUM(H8:H11) -> 1905 | I7: =SUM(I8:I11) -> 1764 | J7: =SUM(J8:J11) -> 1851 | K7: =SUM(K8:K11) -> 0 | L7: =SUM(L8:L11) -> 7192 | M7: =ROUND((L7/$E$1),0) -> 1798
D8: Men | G8: =+G24+G40+G56+G72+G88+G104+G120+G136+G152+G168+G184+G200+G216+G232+G248+G264+G280+G296+G312+G328+G344+G360+G376+G392+G408+G424+G440+G456+G472+G488 -> 113 | H8: =+H24+H40+H56+H72+H88+H104+H120+H136+H152+H168+H184+H200+H216+H232+H248+H264+H280+H296+H312+H328+H344+H360+H376+H392+H408+H424+H440+H456+H472+H488 -> 136 | I8: =+I24+I40+I56+I72+I88+I104+I120+I136+I152+I168+I184+I200+I216+I232+I248+I264+I280+I296+I312+I328+I344+I360+I376+I392+I408+I424+I440+I456+I472+I488 -> 133 | J8: =+J24+J40+J56+J72+J88+J104+J120+J136+J152+J168+J184+J200+J216+J232+J248+J264+J280+J296+J312+J328+J344+J360+J376+J392+J408+J424+J440+J456+J472+J488 -> 127 | K8: =+K24+K40+K56+K72+K88+K104+K120+K136+K152+K168+K184+K200+K216+K232+K248+K264+K280+K296+K312+K328+K344+K360+K376+K392+K408+K424+K440+K456+K472+K488 -> 0 | L8: =SUM(G8:K8) -> 509 | M8: =ROUND((L8/$E$1),0) -> 127
D9: Women | G9: =+G25+G41+G57+G73+G89+G105+G121+G137+G153+G169+G185+G201+G217+G233+G249+G265+G281+G297+G313+G329+G345+G361+G377+G393+G409+G425+G441+G457+G473+G489 -> 307 | H9: =+H25+H41+H57+H73+H89+H105+H121+H137+H153+H169+H185+H201+H217+H233+H249+H265+H281+H297+H313+H329+H345+H361+H377+H393+H409+H425+H441+H457+H473+H489 -> 346 | I9: =+I25+I41+I57+I73+I89+I105+I121+I137+I153+I169+I185+I201+I217+I233+I249+I265+I281+I297+I313+I329+I345+I361+I377+I393+I409+I425+I441+I457+I473+I489 -> 303 | J9: =+J25+J41+J57+J73+J89+J105+J121+J137+J153+J169+J185+J201+J217+J233+J249+J265+J281+J297+J313+J329+J345+J361+J377+J393+J409+J425+J441+J457+J473+J489 -> 379 | K9: =+K25+K41+K57+K73+K89+K105+K121+K137+K153+K169+K185+K201+K217+K233+K249+K265+K281+K297+K313+K329+K345+K361+K377+K393+K409+K425+K441+K457+K473+K489 -> 0 | L9: =SUM(G9:K9) -> 1335 | M9: =ROUND((L9/$E$1),0) -> 334
D10: Youth | G10: =+G26+G42+G58+G74+G90+G106+G122+G138+G154+G170+G186+G202+G218+G234+G250+G266+G282+G298+G314+G330+G346+G362+G378+G394+G410+G426+G442+G458+G474+G490 -> 460 | H10: =+H26+H42+H58+H74+H90+H106+H122+H138+H154+H170+H186+H202+H218+H234+H250+H266+H282+H298+H314+H330+H346+H362+H378+H394+H410+H426+H442+H458+H474+H490 -> 507 | I10: =+I26+I42+I58+I74+I90+I106+I122+I138+I154+I170+I186+I202+I218+I234+I250+I266+I282+I298+I314+I330+I346+I362+I378+I394+I410+I426+I442+I458+I474+I490 -> 450 | J10: =+J26+J42+J58+J74+J90+J106+J122+J138+J154+J170+J186+J202+J218+J234+J250+J266+J282+J298+J314+J330+J346+J362+J378+J394+J410+J426+J442+J458+J474+J490 -> 476 | K10: =+K26+K42+K58+K74+K90+K106+K122+K138+K154+K170+K186+K202+K218+K234+K250+K266+K282+K298+K314+K330+K346+K362+K378+K394+K410+K426+K442+K458+K474+K490 -> 0 | L10: =SUM(G10:K10) -> 1893 | M10: =ROUND((L10/$E$1),0) -> 473
D11: Children | G11: =+G27+G43+G59+G75+G91+G107+G123+G139+G155+G171+G187+G203+G219+G235+G251+G267+G283+G299+G315+G331+G347+G363+G379+G395+G411+G427+G443+G459+G475+G491 -> 792 | H11: =+H27+H43+H59+H75+H91+H107+H123+H139+H155+H171+H187+H203+H219+H235+H251+H267+H283+H299+H315+H331+H347+H363+H379+H395+H411+H427+H443+H459+H475+H491 -> 916 | I11: =+I27+I43+I59+I75+I91+I107+I123+I139+I155+I171+I187+I203+I219+I235+I251+I267+I283+I299+I315+I331+I347+I363+I379+I395+I411+I427+I443+I459+I475+I491 -> 878 | J11: =+J27+J43+J59+J75+J91+J107+J123+J139+J155+J171+J187+J203+J219+J235+J251+J267+J283+J299+J315+J331+J347+J363+J379+J395+J411+J427+J443+J459+J475+J491 -> 869 | K11: =+K27+K43+K59+K75+K91+K107+K123+K139+K155+K171+K187+K203+K219+K235+K251+K267+K283+K299+K315+K331+K347+K363+K379+K395+K411+K427+K443+K459+K475+K491 -> 0 | L11: =SUM(G11:K11) -> 3455 | M11: =ROUND((L11/$E$1),0) -> 864
C12: Salvations | G12: =+G28+G44+G60+G76+G92+G108+G124+G140+G156+G172+G188+G204+G220+G236+G252+G268+G284+G300+G316+G332+G348+G364+G380+G396+G412+G428+G444+G460+G476+G492 -> 39 | H12: =+H28+H44+H60+H76+H92+H108+H124+H140+H156+H172+H188+H204+H220+H236+H252+H268+H284+H300+H316+H332+H348+H364+H380+H396+H412+H428+H444+H460+H476+H492 -> 52 | I12: =+I28+I44+I60+I76+I92+I108+I124+I140+I156+I172+I188+I204+I220+I236+I252+I268+I284+I300+I316+I332+I348+I364+I380+I396+I412+I428+I444+I460+I476+I492 -> 32 | J12: =+J28+J44+J60+J76+J92+J108+J124+J140+J156+J172+J188+J204+J220+J236+J252+J268+J284+J300+J316+J332+J348+J364+J380+J396+J412+J428+J444+J460+J476+J492 -> 25 | K12: =+K28+K44+K60+K76+K92+K108+K124+K140+K156+K172+K188+K204+K220+K236+K252+K268+K284+K300+K316+K332+K348+K364+K380+K396+K412+K428+K444+K460+K476+K492 -> 0 | L12: =SUM(G12:K12) -> 148 | M12: =ROUND((L12/$E$1),0) -> 37
C13: Baptisms | G13: =+G29+G45+G61+G77+G93+G109+G125+G141+G157+G173+G189+G205+G221+G237+G253+G269+G285+G301+G317+G333+G349+G365+G381+G397+G413+G429+G445+G461+G477+G493 -> 0 | H13: =+H29+H45+H61+H77+H93+H109+H125+H141+H157+H173+H189+H205+H221+H237+H253+H269+H285+H301+H317+H333+H349+H365+H381+H397+H413+H429+H445+H461+H477+H493 -> 0 | I13: =+I29+I45+I61+I77+I93+I109+I125+I141+I157+I173+I189+I205+I221+I237+I253+I269+I285+I301+I317+I333+I349+I365+I381+I397+I413+I429+I445+I461+I477+I493 -> 0 | J13: =+J29+J45+J61+J77+J93+J109+J125+J141+J157+J173+J189+J205+J221+J237+J253+J269+J285+J301+J317+J333+J349+J365+J381+J397+J413+J429+J445+J461+J477+J493 -> 0 | K13: =+K29+K45+K61+K77+K93+K109+K125+K141+K157+K173+K189+K205+K221+K237+K253+K269+K285+K301+K317+K333+K349+K365+K381+K397+K413+K429+K445+K461+K477+K493 -> 0 | L13: =SUM(G13:K13) -> 0 | M13: =ROUND((L13/$E$1),0) -> 0
C14: Home Visits | G14: =+G30+G46+G62+G78+G94+G110+G126+G142+G158+G174+G190+G206+G222+G238+G254+G270+G286+G302+G318+G334+G350+G366+G382+G398+G414+G430+G446+G462+G478+G494 -> 44 | H14: =+H30+H46+H62+H78+H94+H110+H126+H142+H158+H174+H190+H206+H222+H238+H254+H270+H286+H302+H318+H334+H350+H366+H382+H398+H414+H430+H446+H462+H478+H494 -> 61 | I14: =+I30+I46+I62+I78+I94+I110+I126+I142+I158+I174+I190+I206+I222+I238+I254+I270+I286+I302+I318+I334+I350+I366+I382+I398+I414+I430+I446+I462+I478+I494 -> 45 | J14: =+J30+J46+J62+J78+J94+J110+J126+J142+J158+J174+J190+J206+J222+J238+J254+J270+J286+J302+J318+J334+J350+J366+J382+J398+J414+J430+J446+J462+J478+J494 -> 61 | K14: =+K30+K46+K62+K78+K94+K110+K126+K142+K158+K174+K190+K206+K222+K238+K254+K270+K286+K302+K318+K334+K350+K366+K382+K398+K414+K430+K446+K462+K478+K494 -> 0 | L14: =SUM(G14:K14) -> 211 | M14: =ROUND((L14/$E$1),0) -> 53
C15: Meals / Food Packs | G15: =+G31+G47+G63+G79+G95+G111+G127+G143+G159+G175+G191+G207+G223+G239+G255+G271+G287+G303+G319+G335+G351+G367+G383+G399+G415+G431+G447+G463+G479+G495 -> 629 | H15: =+H31+H47+H63+H79+H95+H111+H127+H143+H159+H175+H191+H207+H223+H239+H255+H271+H287+H303+H319+H335+H351+H367+H383+H399+H415+H431+H447+H463+H479+H495 -> 561 | I15: =+I31+I47+I63+I79+I95+I111+I127+I143+I159+I175+I191+I207+I223+I239+I255+I271+I287+I303+I319+I335+I351+I367+I383+I399+I415+I431+I447+I463+I479+I495 -> 545 | J15: =+J31+J47+J63+J79+J95+J111+J127+J143+J159+J175+J191+J207+J223+J239+J255+J271+J287+J303+J319+J335+J351+J367+J383+J399+J415+J431+J447+J463+J479+J495 -> 699 | K15: =+K31+K47+K63+K79+K95+K111+K127+K143+K159+K175+K191+K207+K223+K239+K255+K271+K287+K303+K319+K335+K351+K367+K383+K399+K415+K431+K447+K463+K479+K495 -> 0 | L15: =SUM(G15:K15) -> 2434 | M15: =ROUND((L15/$E$1),0) -> 609
C16: Preschool Attendance | G16: =+G32+G48+G64+G80+G96+G112+G128+G144+G160+G176+G192+G208+G224+G240+G256+G272+G288+G304+G320+G336+G352+G368+G384+G400+G416+G432+G448+G464+G480+G496 -> 704 | H16: =+H32+H48+H64+H80+H96+H112+H128+H144+H160+H176+H192+H208+H224+H240+H256+H272+H288+H304+H320+H336+H352+H368+H384+H400+H416+H432+H448+H464+H480+H496 -> 719 | I16: =+I32+I48+I64+I80+I96+I112+I128+I144+I160+I176+I192+I208+I224+I240+I256+I272+I288+I304+I320+I336+I352+I368+I384+I400+I416+I432+I448+I464+I480+I496 -> 729 | J16: =+J32+J48+J64+J80+J96+J112+J128+J144+J160+J176+J192+J208+J224+J240+J256+J272+J288+J304+J320+J336+J352+J368+J384+J400+J416+J432+J448+J464+J480+J496 -> 736 | K16: =+K32+K48+K64+K80+K96+K112+K128+K144+K160+K176+K192+K208+K224+K240+K256+K272+K288+K304+K320+K336+K352+K368+K384+K400+K416+K432+K448+K464+K480+K496 -> 0 | L16: =SUM(G16:K16) -> 2888 | M16: =ROUND((L16/$E$1),0) -> 722
A19: 1 | C19: Hawane CLC Church | G19: =+$G$3 -> 2022 | H19: =+G19 -> 2022 | I19: =+H19 -> 2022 | J19: =+I19 -> 2022 | K19: =+J19 -> 2022 | L19: =+K19 -> 2022 | M19: =+L19 -> 2022
C20: =+$C4 -> March 2022 | G20: =+$G$4 -> Mar | H20: =+G20 -> Mar | I20: =+H20 -> Mar | J20: =+I20 -> Mar | K20: =+J20 -> Mar | L20: =+K20 -> Mar | M20: =+L20 -> Mar
G21: =+$G$5 -> 6 | H21: =+$H$5 -> 13 | I21: =+$I$5 -> 20 | J21: =+$J$5 -> 27 | K21: =+$K$5 -> 0 | L21: Total | M21: Average
C23: Church Attendance: | G23: =SUM(G24:G27) -> 136 | H23: =SUM(H24:H27) -> 192 | I23: =SUM(I24:I27) -> 189 | J23: =SUM(J24:J27) -> 179 | K23: =SUM(K24:K27) -> 0 | L23: =SUM(L24:L27) -> 696 | M23: =ROUND((L23/$E$1),0) -> 174
D24: Men | G24: 12 | H24: 33 | I24: 32 | J24: 11 | L24: =SUM(G24:K24) -> 88 | M24: =ROUND((L24/$E$1),0) -> 22
D25: Women | G25: 23 | H25: 16 | I25: 16 | J25: 29 | L25: =SUM(G25:K25) -> 84 | M25: =ROUND((L25/$E$1),0) -> 21
D26: Youth | G26: 51 | H26: 49 | I26: 47 | J26: 60 | L26: =SUM(G26:K26) -> 207 | M26: =ROUND((L26/$E$1),0) -> 52
D27: Children | G27: 50 | H27: 94 | I27: 94 | J27: 79 | L27: =SUM(G27:K27) -> 317 | M27: =ROUND((L27/$E$1),0) -> 79
C28: Salvations | L28: =SUM(G28:K28) -> 0 | M28: =ROUND((L28/$E$1),0) -> 0
C29: Baptisms | L29: =SUM(G29:K29) -> 0 | M29: =ROUND((L29/$E$1),0) -> 0
C30: Home Visits | L30: =SUM(G30:K30) -> 0 | M30: =ROUND((L30/$E$1),0) -> 0
C31: Meals / Food Packs | L31: =SUM(G31:K31) -> 0 | M31: =ROUND((L31/$E$1),0) -> 0
C32: Preschool Attendance | G32: 44 | H32: 44 | I32: 44 | J32: 44 | L32: =SUM(G32:K32) -> 176 | M32: =ROUND((L32/$E$1),0) -> 44
A35: =+A19+1 -> 2 | C35: Ngwenya | G35: =+$G$3 -> 2022 | H35: =+G35 -> 2022 | I35: =+H35 -> 2022 | J35: =+I35 -> 2022 | K35: =+J35 -> 2022 | L35: =+K35 -> 2022 | M35: =+L35 -> 2022
C36: =+$C20 -> March 2022 | G36: =+$G$4 -> Mar | H36: =+G36 -> Mar | I36: =+H36 -> Mar | J36: =+I36 -> Mar | K36: =+J36 -> Mar | L36: =+K36 -> Mar | M36: =+L36 -> Mar
G37: =+$G$5 -> 6 | H37: =+$H$5 -> 13 | I37: =+$I$5 -> 20 | J37: =+$J$5 -> 27 | K37: =+$K$5 -> 0 | L37: Total | M37: Average | Q37: 27 March 2022 - Ngwenya had the service at the Uphakatsi
C39: Church Attendance: | G39: =SUM(G40:G43) -> 59 | H39: =SUM(H40:H43) -> 63 | I39: =SUM(I40:I43) -> 55 | J39: =SUM(J40:J43) -> 0 | K39: =SUM(K40:K43) -> 0 | L39: =SUM(L40:L43) -> 177 | M39: =ROUND((L39/$E$1),0) -> 44
D40: Men | G40: 5 | H40: 6 | I40: 4 | L40: =SUM(G40:K40) -> 15 | M40: =ROUND((L40/$E$1),0) -> 4
D41: Women | G41: 11 | H41: 14 | I41: 10 | L41: =SUM(G41:K41) -> 35 | M41: =ROUND((L41/$E$1),0) -> 9
D42: Youth | G42: 15 | H42: 15 | I42: 15 | L42: =SUM(G42:K42) -> 45 | M42: =ROUND((L42/$E$1),0) -> 11
D43: Children | G43: 28 | H43: 28 | I43: 26 | L43: =SUM(G43:K43) -> 82 | M43: =ROUND((L43/$E$1),0) -> 21
C44: Salvations | H44: 3 | I44: 4 | L44: =SUM(G44:K44) -> 7 | M44: =ROUND((L44/$E$1),0) -> 2
C45: Baptisms | L45: =SUM(G45:K45) -> 0 | M45: =ROUND((L45/$E$1),0) -> 0
C46: Home Visits | G46: 5 | H46: 5 | I46: 2 | J46: 4 | L46: =SUM(G46:K46) -> 16 | M46: =ROUND((L46/$E$1),0) -> 4
C47: Meals / Food Packs | G47: 4 | H47: 4 | I47: 3 | J47: 4 | L47: =SUM(G47:K47) -> 15 | M47: =ROUND((L47/$E$1),0) -> 4
C48: Preschool Attendance | L48: =SUM(G48:K48) -> 0 | M48: =ROUND((L48/$E$1),0) -> 0
...

Sheet Apr22
D1: Number of Sundays | E1: 4
C3: Total ICBC | G3: 2022 | H3: =+G3 -> 2022 | I3: =+H3 -> 2022 | J3: =+I3 -> 2022 | K3: =+J3 -> 2022 | L3: =+K3 -> 2022 | M3: =+L3 -> 2022
C4: April 2022 | G4: Apr | H4: =+G4 -> Apr | I4: =+H4 -> Apr | J4: =+I4 -> Apr | K4: =+J4 -> Apr | L4: =+K4 -> Apr | M4: =+L4 -> Apr
G5: 3 | H5: 10 | I5: 17 | J5: 24 | L5: Total | M5: Average
C7: Church Attendance: | G7: =SUM(G8:G11) -> 1672 | H7: =SUM(H8:H11) -> 1153 | I7: =SUM(I8:I11) -> 1610 | J7: =SUM(J8:J11) -> 1823 | K7: =SUM(K8:K11) -> 0 | L7: =SUM(L8:L11) -> 6258 | M7: =ROUND((L7/$E$1),0) -> 1565
D8: Men | G8: =+G24+G40+G56+G72+G88+G104+G120+G136+G152+G168+G184+G200+G216+G232+G248+G264+G280+G296+G312+G328+G344+G360+G376+G392+G408+G424+G440+G456+G472+G488 -> 116 | H8: =+H24+H40+H56+H72+H88+H104+H120+H136+H152+H168+H184+H200+H216+H232+H248+H264+H280+H296+H312+H328+H344+H360+H376+H392+H408+H424+H440+H456+H472+H488 -> 98 | I8: =+I24+I40+I56+I72+I88+I104+I120+I136+I152+I168+I184+I200+I216+I232+I248+I264+I280+I296+I312+I328+I344+I360+I376+I392+I408+I424+I440+I456+I472+I488 -> 194 | J8: =+J24+J40+J56+J72+J88+J104+J120+J136+J152+J168+J184+J200+J216+J232+J248+J264+J280+J296+J312+J328+J344+J360+J376+J392+J408+J424+J440+J456+J472+J488 -> 128 | K8: =+K24+K40+K56+K72+K88+K104+K120+K136+K152+K168+K184+K200+K216+K232+K248+K264+K280+K296+K312+K328+K344+K360+K376+K392+K408+K424+K440+K456+K472+K488 -> 0 | L8: =SUM(G8:K8) -> 536 | M8: =ROUND((L8/$E$1),0) -> 134
